Workbook
Name Diff_: [1]set_validations_!$A$2:$A$401
Name gang_: [1]set_validations_!$D$2:$D$201
Name Loop_back: [1]set_validations_!$E$2:$E$201
Name Match_: [1]set_validations_!$B$2:$B$201
Name Share_: [1]set_validations_!$C$2:$C$201
Name Time_Domain: [1]set_validations_!$F$2:$F$201

Sheet TITLE
F6: INTEL
F7: X74B SRAM/COLL CMT TIU
F8: R&D-ALTANOVA JOB # 4651
F13: FILE NAME | G13: Revision History | H13: COMMENTS | I13: Date
F14: INTEL-4651-X74B SRAM_COLL CMT_TIU--NETLIST-01.xlsx | G14: FIRST RELEASE | H14: released from design end. | I14: 41867
F15: INTEL-4651-X74B SRAM_COLL CMT_TIU-NETLIST-02.xlsx | G15: SECOND RELEASE | H15: UPDATE THE TCI CONNECTIONS | I15: 41914
F16: INTEL-4651-X74B SRAM_COLL CMT_TIU-NETLIST-05 | G16: THIRD RELEASE | H16: CHECK AND RELEASED WITH QA. | I16: 41961
F17: INTEL-4651-X74B SRAM_COLL CMT_TIU-NETLIST-06 | G17: FOURTH RELEASE | H17: CHECK AND RELEASED WITH QA. AFTER ASSIGMENT CHANGES DUE TO LEGNTH MATCHING | I17: 41962
F18: INTEL-4651-X74B SRAM_COLL CMT_TIU-NETLIST-07 | G18: FIFTH RELEASE | H18: 1) Ground Connection Remove from the DUT Pins T5, C5, AM13, N7 and P3 on sheet "GROUND". 2) Added NO Conect DUT pins T5, C5, AM13, N7 and P3 on sheet "NO CONNECT PINS". | I18: 41963
F19: INTEL-4651-X74B SRAM_COLL CMT_TIU-NETLIST-08 | G19: SIXTH RELEASE | H19: SWAP TESTER CHANNEL "J1506_PIN29" AND "J1506_PIN30" ON SHEET "DIRECT TESTER" | I19: 41964

Sheet DIRECT TESTER
E2: SITE-1 | G2: SITE-3 | I2: SITE-5 | K2: SITE-7
C3: CUSTOMER PINLIST | E3: R&D-ALTANOVA ASSIGNMENT | G3: R&D-ALTANOVA ASSIGNMENT | I3: R&D-ALTANOVA ASSIGNMENT | K3: R&D-ALTANOVA ASSIGNMENT
C5: Ball Location | D5: Ball Name | E5: 800 MDM | F5: 800 MDM THROUGH RESISTOR | G5: 800 MDM | H5: 800 MDM THROUGH RESISTOR | I5: 800 MDM | J5: 800 MDM THROUGH RESISTOR | K5: 800 MDM | L5: 800 MDM THROUGH RESISTOR
C6: T38 | D6: VCCADCREF | E6: =VLOOKUP("U1."&C6,'PIN REPORT'!$A:$G,7,0) -> J1601_PIN26 | G6: =VLOOKUP("U3."&C6,'PIN REPORT'!$A:$G,7,0) -> J1801_PIN37 | I6: =VLOOKUP("U5."&C6,'PIN REPORT'!$A:$G,7,0) -> J1707_PIN100 | K6: =VLOOKUP("U7."&C6,'PIN REPORT'!$A:$G,7,0) -> J1507_PIN96
C7: A37 | D7: XACTVCCGMON | E7: =VLOOKUP("U1."&C7,'PIN REPORT'!$A:$G,7,0) -> J1601_PIN09 | G7: =VLOOKUP("U3."&C7,'PIN REPORT'!$A:$G,7,0) -> J1802_PIN62 | I7: =VLOOKUP("U5."&C7,'PIN REPORT'!$A:$G,7,0) -> J1707_PIN91 | K7: =VLOOKUP("U7."&C7,'PIN REPORT'!$A:$G,7,0) -> J1508_PIN81
C8: U36 | D8: XACTVSSMON | E8: =VLOOKUP("U1."&C8,'PIN REPORT'!$A:$G,7,0) -> J1601_PIN24 | G8: =VLOOKUP("U3."&C8,'PIN REPORT'!$A:$G,7,0) -> J1801_PIN14 | I8: =VLOOKUP("U5."&C8,'PIN REPORT'!$A:$G,7,0) -> J1706_PIN21 | K8: =VLOOKUP("U7."&C8,'PIN REPORT'!$A:$G,7,0) -> J1506_PIN35
C9: C37 | D9: XADCANA[0] | E9: =VLOOKUP("U1."&C9,'PIN REPORT'!$A:$G,7,0) -> J1601_PIN16 | G9: =VLOOKUP("U3."&C9,'PIN REPORT'!$A:$G,7,0) -> J1801_PIN25 | I9: =VLOOKUP("U5."&C9,'PIN REPORT'!$A:$G,7,0) -> J1708_PIN46 | K9: =VLOOKUP("U7."&C9,'PIN REPORT'!$A:$G,7,0) -> J1508_PIN77
C10: V40 | D10: XADCANA[1] | E10: =VLOOKUP("U1."&C10,'PIN REPORT'!$A:$G,7,0) -> J1602_PIN73 | G10: =VLOOKUP("U3."&C10,'PIN REPORT'!$A:$G,7,0) -> J1801_PIN39 | I10: =VLOOKUP("U5."&C10,'PIN REPORT'!$A:$G,7,0) -> J1705_PIN51 | K10: =VLOOKUP("U7."&C10,'PIN REPORT'!$A:$G,7,0) -> J1504_PIN124
C11: V39 | D11: XADCANA[2] | E11: =VLOOKUP("U1."&C11,'PIN REPORT'!$A:$G,7,0) -> J1601_PIN36 | G11: =VLOOKUP("U3."&C11,'PIN REPORT'!$A:$G,7,0) -> J1801_PIN01 | I11: =VLOOKUP("U5."&C11,'PIN REPORT'!$A:$G,7,0) -> J1705_PIN81 | K11: =VLOOKUP("U7."&C11,'PIN REPORT'!$A:$G,7,0) -> J1504_PIN112
C12: J38 | D12: XADCANA[3] | E12: =VLOOKUP("U1."&C12,'PIN REPORT'!$A:$G,7,0) -> J1601_PIN05 | G12: =VLOOKUP("U3."&C12,'PIN REPORT'!$A:$G,7,0) -> J1802_PIN84 | I12: =VLOOKUP("U5."&C12,'PIN REPORT'!$A:$G,7,0) -> J1705_PIN50 | K12: =VLOOKUP("U7."&C12,'PIN REPORT'!$A:$G,7,0) -> J1504_PIN116
C13: AA33 | D13: XADCDIG[0] | E13: =VLOOKUP("U1."&C13,'PIN REPORT'!$A:$G,7,0) -> J1602_PIN74 | G13: =VLOOKUP("U3."&C13,'PIN REPORT'!$A:$G,7,0) -> J1801_PIN05 | I13: =VLOOKUP("U5."&C13,'PIN REPORT'!$A:$G,7,0) -> J1704_PIN91 | K13: =VLOOKUP("U7."&C13,'PIN REPORT'!$A:$G,7,0) -> J1503_PIN27
C14: Y33 | D14: XADCDIG[1] | E14: =VLOOKUP("U1."&C14,'PIN REPORT'!$A:$G,7,0) -> J1601_PIN18 | G14: =VLOOKUP("U3."&C14,'PIN REPORT'!$A:$G,7,0) -> J1801_PIN15 | I14: =VLOOKUP("U5."&C14,'PIN REPORT'!$A:$G,7,0) -> J1704_PIN124 | K14: =VLOOKUP("U7."&C14,'PIN REPORT'!$A:$G,7,0) -> J1504_PIN115
C15: T34 | D15: XADCDIG[10] | E15: =VLOOKUP("U1."&C15,'PIN REPORT'!$A:$G,7,0) -> J1601_PIN37 | G15: =VLOOKUP("U3."&C15,'PIN REPORT'!$A:$G,7,0) -> J1801_PIN03 | I15: =VLOOKUP("U5."&C15,'PIN REPORT'!$A:$G,7,0) -> J1705_PIN49 | K15: =VLOOKUP("U7."&C15,'PIN REPORT'!$A:$G,7,0) -> J1504_PIN114
C16: T33 | D16: XADCDIG[11] | E16: =VLOOKUP("U1."&C16,'PIN REPORT'!$A:$G,7,0) -> J1603_PIN87 | G16: =VLOOKUP("U3."&C16,'PIN REPORT'!$A:$G,7,0) -> J1803_PIN90 | I16: =VLOOKUP("U5."&C16,'PIN REPORT'!$A:$G,7,0) -> J1706_PIN08 | K16: =VLOOKUP("U7."&C16,'PIN REPORT'!$A:$G,7,0) -> J1506_PIN37
C17: Y34 | D17: XADCDIG[2] | E17: =VLOOKUP("U1."&C17,'PIN REPORT'!$A:$G,7,0) -> J1601_PIN17 | G17: =VLOOKUP("U3."&C17,'PIN REPORT'!$A:$G,7,0) -> J1801_PIN27 | I17: =VLOOKUP("U5."&C17,'PIN REPORT'!$A:$G,7,0) -> J1704_PIN92 | K17: =VLOOKUP("U7."&C17,'PIN REPORT'!$A:$G,7,0) -> J1504_PIN113
... C88: AR28 | D88: XDDR_PRBSRST | E88: =VLOOKUP("U1."&C88,'PIN REPORT'!$A:$G,7,0) -> J1608_PIN70 | G88: =VLOOKUP("U3."&C88,'PIN REPORT'!$A:$G,7,0) -> J1805_PIN67 | I88: =VLOOKUP("U5."&C88,'PIN REPORT'!$A:$G,7,0) -> J1704_PIN98 | K88: =VLOOKUP("U7."&C88,'PIN REPORT'!$A:$G,7,0) -> J1503_PIN08
C89: AV7 | D89: XDDR_RCOMP[0] | E89: =VLOOKUP("U1."&C89,'PIN REPORT'!$A:$G,7,0) -> U1_XDDR_RCOMP[0] | F89: =VLOOKUP(E89,WORKING!$D:$H,5,0) -> J1609_PIN114 | G89: =VLOOKUP("U3."&C89,'PIN REPORT'!$A:$G,7,0) -> U3_XDDR_RCOMP[0] | H89: =VLOOKUP(G89,WORKING!$D:$H,5,0) -> J1807_PIN20 | I89: =VLOOKUP("U5."&C89,'PIN REPORT'!$A:$G,7,0) -> U5_XDDR_RCOMP[0] | J89: =VLOOKUP(I89,WORKING!$D:$H,5,0) -> J1704_PIN88 | K89: =VLOOKUP("U7."&C89,'PIN REPORT'!$A:$G,7,0) -> U7_XDDR_RCOMP[0] | L89: =VLOOKUP(K89,WORKING!$D:$H,5,0) -> J1502_PIN84
C90: AU7 | D90: XDDR_RCOMP[1] | E90: =VLOOKUP("U1."&C90,'PIN REPORT'!$A:$G,7,0) -> U1_XDDR_RCOMP[1] | F90: =VLOOKUP(E90,WORKING!$D:$H,5,0) -> J1609_PIN103 | G90: =VLOOKUP("U3."&C90,'PIN REPORT'!$A:$G,7,0) -> U3_XDDR_RCOMP[1] | H90: =VLOOKUP(G90,WORKING!$D:$H,5,0) -> J1808_PIN60 | I90: =VLOOKUP("U5."&C90,'PIN REPORT'!$A:$G,7,0) -> U5_XDDR_RCOMP[1] | J90: =VLOOKUP(I90,WORKING!$D:$H,5,0) -> J1705_PIN46 | K90: =VLOOKUP("U7."&C90,'PIN REPORT'!$A:$G,7,0) -> U7_XDDR_RCOMP[1] | L90: =VLOOKUP(K90,WORKING!$D:$H,5,0) -> J1503_PIN02
C91: Y4 | D91: XDDR_RX_N | E91: =VLOOKUP("U1."&C91,'PIN REPORT'!$A:$G,7,0) -> J1608_PIN51 | G91: =VLOOKUP("U3."&C91,'PIN REPORT'!$A:$G,7,0) -> J1808_PIN71 | I91: =VLOOKUP("U5."&C91,'PIN REPORT'!$A:$G,7,0) -> J1708_PIN80 | K91: =VLOOKUP("U7."&C91,'PIN REPORT'!$A:$G,7,0) -> J1507_PIN95
C92: Y5 | D92: XDDR_RX_P | E92: =VLOOKUP("U1."&C92,'PIN REPORT'!$A:$G,7,0) -> J1609_PIN93 | G92: =VLOOKUP("U3."&C92,'PIN REPORT'!$A:$G,7,0) -> J1808_PIN84 | I92: =VLOOKUP("U5."&C92,'PIN REPORT'!$A:$G,7,0) -> J1709_PIN19 | K92: =VLOOKUP("U7."&C92,'PIN REPORT'!$A:$G,7,0) -> J1507_PIN97
C93: AL30 | D93: XDDR_SCANMODE | E93: =VLOOKUP("U1."&C93,'PIN REPORT'!$A:$G,7,0) -> J1606_PIN119 | G93: =VLOOKUP("U3."&C93,'PIN REPORT'!$A:$G,7,0) -> J1805_PIN72 | I93: =VLOOKUP("U5."&C93,'PIN REPORT'!$A:$G,7,0) -> J1704_PIN89 | K93: =VLOOKUP("U7."&C93,'PIN REPORT'!$A:$G,7,0) -> J1503_PIN26
C94: AM28 | D94: XDDR_SCLKA | E94: =VLOOKUP("U1."&C94,'PIN REPORT'!$A:$G,7,0) -> J1603_PIN120 | G94: =VLOOKUP("U3."&C94,'PIN REPORT'!$A:$G,7,0) -> J1803_PIN103 | I94: =VLOOKUP("U5."&C94,'PIN REPORT'!$A:$G,7,0) -> J1704_PIN101 | K94: =VLOOKUP("U7."&C94,'PIN REPORT'!$A:$G,7,0) -> J1504_PIN121
C95: AN28 | D95: XDDR_SCLKB | E95: =VLOOKUP("U1."&C95,'PIN REPORT'!$A:$G,7,0) -> J1603_PIN109 | G95: =VLOOKUP("U3."&C95,'PIN REPORT'!$A:$G,7,0) -> J1804_PIN14 | I95: =VLOOKUP("U5."&C95,'PIN REPORT'!$A:$G,7,0) -> J1705_PIN65 | K95: =VLOOKUP("U7."&C95,'PIN REPORT'!$A:$G,7,0) -> J1504_PIN118
C96: AN30 | D96: XDDR_SRAMEN | E96: =VLOOKUP("U1."&C96,'PIN REPORT'!$A:$G,7,0) -> J1609_PIN113 | G96: =VLOOKUP("U3."&C96,'PIN REPORT'!$A:$G,7,0) -> J1802_PIN74 | I96: =VLOOKUP("U5."&C96,'PIN REPORT'!$A:$G,7,0) -> J1704_PIN90 | K96: =VLOOKUP("U7."&C96,'PIN REPORT'!$A:$G,7,0) -> J1502_PIN43
C97: AV33 | D97: XDDR_SUPDATE | E97: =VLOOKUP("U1."&C97,'PIN REPORT'!$A:$G,7,0) -> J1604_PIN17 | G97: =VLOOKUP("U3."&C97,'PIN REPORT'!$A:$G,7,0) -> J1802_PIN67 | I97: =VLOOKUP("U5."&C97,'PIN REPORT'!$A:$G,7,0) -> J1705_PIN56 | K97: =VLOOKUP("U7."&C97,'PIN REPORT'!$A:$G,7,0) -> J1505_PIN62
C98: AN31 | D98: XDDR_TDI | E98: =VLOOKUP("U1."&C98,'PIN REPORT'!$A:$G,7,0) -> J1609_PIN112 | G98: =VLOOKUP("U3."&C98,'PIN REPORT'!$A:$G,7,0) -> J1806_PIN104 | I98: =VLOOKUP("U5."&C98,'PIN REPORT'!$A:$G,7,0) -> J1703_PIN04 | K98: =VLOOKUP("U7."&C98,'PIN REPORT'!$A:$G,7,0) -> J1501_PIN109
C99: AM11 | D99: XDDR_TDO | E99: =VLOOKUP("U1."&C99,'PIN REPORT'!$A:$G,7,0) -> J1605_PIN59 | G99: =VLOOKUP("U3."&C99,'PIN REPORT'!$A:$G,7,0) -> J1807_PIN30 | I99: =VLOOKUP("U5."&C99,'PIN REPORT'!$A:$G,7,0) -> J1707_PIN104 | K99: =VLOOKUP("U7."&C99,'PIN REPORT'!$A:$G,7,0) -> J1507_PIN105
C100: W4 | D100: XDDR_TX_N | E100: =VLOOKUP("U1."&C100,'PIN REPORT'!$A:$G,7,0) -> J1609_PIN91 | G100: =VLOOKUP("U3."&C100,'PIN REPORT'!$A:$G,7,0) -> J1808_PIN80 | I100: =VLOOKUP("U5."&C100,'PIN REPORT'!$A:$G,7,0) -> J1709_PIN20 | K100: =VLOOKUP("U7."&C100,'PIN REPORT'!$A:$G,7,0) -> J1507_PIN123
C101: W5 | D101: XDDR_TX_P | E101: =VLOOKUP("U1."&C101,'PIN REPORT'!$A:$G,7,0) -> J1608_PIN49 | G101: =VLOOKUP("U3."&C101,'PIN REPORT'!$A:$G,7,0) -> J1808_PIN76 | I101: =VLOOKUP("U5."&C101,'PIN REPORT'!$A:$G,7,0) -> J1708_PIN53 | K101: =VLOOKUP("U7."&C101,'PIN REPORT'!$A:$G,7,0) -> J1507_PIN99
C102: AK28 | D102: XDDR_UPDATE | E102: =VLOOKUP("U1."&C102,'PIN REPORT'!$A:$G,7,0) -> J1603_PIN112 | G102: =VLOOKUP("U3."&C102,'PIN REPORT'!$A:$G,7,0) -> J1803_PIN117 | I102: =VLOOKUP("U5."&C102,'PIN REPORT'!$A:$G,7,0) -> J1704_PIN103 | K102: =VLOOKUP("U7."&C102,'PIN REPORT'!$A:$G,7,0) -> J1504_PIN97
... C261: AL36 | D261: XPCIPLLIN6 | E261: =VLOOKUP("U1."&C261,'PIN REPORT'!$A:$G,7,0) -> J1604_PIN25 | G261: =VLOOKUP("U3."&C261,'PIN REPORT'!$A:$G,7,0) -> J1801_PIN11 | I261: =VLOOKUP("U5."&C261,'PIN REPORT'!$A:$G,7,0) -> J1705_PIN70 | K261: =VLOOKUP("U7."&C261,'PIN REPORT'!$A:$G,7,0) -> J1505_PIN81
C262: AM36 | D262: XPCIRCOMP | E262: =VLOOKUP("U1."&C262,'PIN REPORT'!$A:$G,7,0) -> U1_XPCIRCOMP | F262: =VLOOKUP(E262,WORKING!$D:$H,5,0) -> J1606_PIN94 | G262: =VLOOKUP("U3."&C262,'PIN REPORT'!$A:$G,7,0) -> U3_XPCIRCOMP | H262: =VLOOKUP(G262,WORKING!$D:$H,5,0) -> J1807_PIN34 | I262: =VLOOKUP("U5."&C262,'PIN REPORT'!$A:$G,7,0) -> U5_XPCIRCOMP | J262: =VLOOKUP(I262,WORKING!$D:$H,5,0) -> J1702_PIN50 | K262: =VLOOKUP("U7."&C262,'PIN REPORT'!$A:$G,7,0) -> U7_XPCIRCOMP | L262: =VLOOKUP(K262,WORKING!$D:$H,5,0) -> J1503_PIN21
C263: AL38 | D263: XPCIRESERVED[0] | E263: =VLOOKUP("U1."&C263,'PIN REPORT'!$A:$G,7,0) -> J1604_PIN21 | G263: =VLOOKUP("U3."&C263,'PIN REPORT'!$A:$G,7,0) -> J1803_PIN108 | I263: =VLOOKUP("U5."&C263,'PIN REPORT'!$A:$G,7,0) -> J1705_PIN68 | K263: =VLOOKUP("U7."&C263,'PIN REPORT'!$A:$G,7,0) -> J1505_PIN61
C264: AK36 | D264: XPCIRESERVED[1] | E264: =VLOOKUP("U1."&C264,'PIN REPORT'!$A:$G,7,0) -> J1604_PIN33 | G264: =VLOOKUP("U3."&C264,'PIN REPORT'!$A:$G,7,0) -> J1803_PIN124 | I264: =VLOOKUP("U5."&C264,'PIN REPORT'!$A:$G,7,0) -> J1705_PIN60 | K264: =VLOOKUP("U7."&C264,'PIN REPORT'!$A:$G,7,0) -> J1505_PIN75
C265: AJ34 | D265: XPCIRESET | E265: =VLOOKUP("U1."&C265,'PIN REPORT'!$A:$G,7,0) -> J1604_PIN24 | G265: =VLOOKUP("U3."&C265,'PIN REPORT'!$A:$G,7,0) -> J1801_PIN12 | I265: =VLOOKUP("U5."&C265,'PIN REPORT'!$A:$G,7,0) -> J1705_PIN55 | K265: =VLOOKUP("U7."&C265,'PIN REPORT'!$A:$G,7,0) -> J1505_PIN49
C266: D32 | D266: XPDFIN[0] | E266: =VLOOKUP("U1."&C266,'PIN REPORT'!$A:$G,7,0) -> J1602_PIN81 | G266: =VLOOKUP("U3."&C266,'PIN REPORT'!$A:$G,7,0) -> J1803_PIN123 | I266: =VLOOKUP("U5."&C266,'PIN REPORT'!$A:$G,7,0) -> J1706_PIN32 | K266: =VLOOKUP("U7."&C266,'PIN REPORT'!$A:$G,7,0) -> J1505_PIN76
C267: B32 | D267: XPDFIN[1] | E267: =VLOOKUP("U1."&C267,'PIN REPORT'!$A:$G,7,0) -> J1601_PIN27 | G267: =VLOOKUP("U3."&C267,'PIN REPORT'!$A:$G,7,0) -> J1801_PIN31 | I267: =VLOOKUP("U5."&C267,'PIN REPORT'!$A:$G,7,0) -> J1708_PIN45 | K267: =VLOOKUP("U7."&C267,'PIN REPORT'!$A:$G,7,0) -> J1508_PIN46
C268: D33 | D268: XPDFIN[2] | E268: =VLOOKUP("U1."&C268,'PIN REPORT'!$A:$G,7,0) -> J1601_PIN13 | G268: =VLOOKUP("U3."&C268,'PIN REPORT'!$A:$G,7,0) -> J1801_PIN30 | I268: =VLOOKUP("U5."&C268,'PIN REPORT'!$A:$G,7,0) -> J1708_PIN41 | K268: =VLOOKUP("U7."&C268,'PIN REPORT'!$A:$G,7,0) -> J1508_PIN49
C269: B33 | D269: XPDFIN[3] | E269: =VLOOKUP("U1."&C269,'PIN REPORT'!$A:$G,7,0) -> J1601_PIN15 | G269: =VLOOKUP("U3."&C269,'PIN REPORT'!$A:$G,7,0) -> J1801_PIN29 | I269: =VLOOKUP("U5."&C269,'PIN REPORT'!$A:$G,7,0) -> J1708_PIN63 | K269: =VLOOKUP("U7."&C269,'PIN REPORT'!$A:$G,7,0) -> J1508_PIN47
C270: C33 | D270: XPDFIN[4] | E270: =VLOOKUP("U1."&C270,'PIN REPORT'!$A:$G,7,0) -> J1601_PIN29 | G270: =VLOOKUP("U3."&C270,'PIN REPORT'!$A:$G,7,0) -> J1801_PIN32 | I270: =VLOOKUP("U5."&C270,'PIN REPORT'!$A:$G,7,0) -> J1708_PIN49 | K270: =VLOOKUP("U7."&C270,'PIN REPORT'!$A:$G,7,0) -> J1508_PIN48
...

Sheet CIRCUIT1
F3: SITE-1 | I3: SITE-3 | L3: SITE-5 | O3: SITE-7
D5: CUSTOMER PINLIST | F5: R&D-ALTANOVA ASSIGNMENT | I5: R&D-ALTANOVA ASSIGNMENT | L5: R&D-ALTANOVA ASSIGNMENT | O5: R&D-ALTANOVA ASSIGNMENT
D7: Ball Location | E7: Ball Name | F7: DUT TO INDUCTOR/RELAY | G7: INDUCTOR/RELAY TO RELAY | H7: RELAY TO TESTER | I7: DUT TO INDUCTOR/RELAY | J7: INDUCTOR/RELAY TO RELAY | K7: RELAY TO TESTER | L7: DUT TO INDUCTOR/RELAY | M7: INDUCTOR/RELAY TO RELAY | N7: RELAY TO TESTER | O7: DUT TO INDUCTOR/RELAY | P7: INDUCTOR/RELAY TO RELAY | Q7: RELAY TO TESTER
D8: AJ36 | E8: XPCIRXN[0] | F8: =VLOOKUP("U1."&D8,'PIN REPORT'!$A:$G,7,0) -> U1_XPCIRXN[0] | G8: =VLOOKUP(F8,WORKING!$L:$P,5,0) -> N19907848 | H8: =VLOOKUP(F8,WORKING!$L:$T,9,0) -> J1609_PIN92 | I8: =VLOOKUP("U3."&D8,'PIN REPORT'!$A:$G,7,0) -> U3_XPCIRXN[0] | J8: =VLOOKUP(I8,WORKING!$L:$P,5,0) -> N21318804 | K8: =VLOOKUP(I8,WORKING!$L:$T,9,0) -> J1809_PIN88 | L8: =VLOOKUP("U5."&D8,'PIN REPORT'!$A:$G,7,0) -> U5_XPCIRXN[0] | M8: =VLOOKUP(L8,WORKING!$L:$P,5,0) -> N21324161 | N8: =VLOOKUP(L8,WORKING!$L:$T,9,0) -> J1706_PIN02 | O8: =VLOOKUP("U7."&D8,'PIN REPORT'!$A:$G,7,0) -> U7_XPCIRXN[0] | P8: =VLOOKUP(O8,WORKING!$L:$P,5,0) -> N21327256 | Q8: =VLOOKUP(O8,WORKING!$L:$T,9,0) -> J1504_PIN85
D9: AJ37 | E9: XPCIRXP[0] | F9: =VLOOKUP("U1."&D9,'PIN REPORT'!$A:$G,7,0) -> U1_XPCIRXP[0] | G9: =VLOOKUP(F9,WORKING!$L:$P,5,0) -> N19907828 | H9: =VLOOKUP(F9,WORKING!$L:$T,9,0) -> J1609_PIN89 | I9: =VLOOKUP("U3."&D9,'PIN REPORT'!$A:$G,7,0) -> U3_XPCIRXP[0] | J9: =VLOOKUP(I9,WORKING!$L:$P,5,0) -> N21318198 | K9: =VLOOKUP(I9,WORKING!$L:$T,9,0) -> J1809_PIN90 | L9: =VLOOKUP("U5."&D9,'PIN REPORT'!$A:$G,7,0) -> U5_XPCIRXP[0] | M9: =VLOOKUP(L9,WORKING!$L:$P,5,0) -> N21324144 | N9: =VLOOKUP(L9,WORKING!$L:$T,9,0) -> J1706_PIN01 | O9: =VLOOKUP("U7."&D9,'PIN REPORT'!$A:$G,7,0) -> U7_XPCIRXP[0] | P9: =VLOOKUP(O9,WORKING!$L:$P,5,0) -> N21327239 | Q9: =VLOOKUP(O9,WORKING!$L:$T,9,0) -> J1504_PIN87
D10: AM38 | E10: XPCITXN[0] | F10: =VLOOKUP("U1."&D10,'PIN REPORT'!$A:$G,7,0) -> U1_XPCITXN[0] | G10: =VLOOKUP(F10,WORKING!$L:$P,5,0) -> N19907894 | H10: =VLOOKUP(F10,WORKING!$L:$T,9,0) -> J1609_PIN92 | I10: =VLOOKUP("U3."&D10,'PIN REPORT'!$A:$G,7,0) -> U3_XPCITXN[0] | J10: =VLOOKUP(I10,WORKING!$L:$P,5,0) -> N21317510 | K10: =VLOOKUP(I10,WORKING!$L:$T,9,0) -> J1809_PIN88 | L10: =VLOOKUP("U5."&D10,'PIN REPORT'!$A:$G,7,0) -> U5_XPCITXN[0] | M10: =VLOOKUP(L10,WORKING!$L:$P,5,0) -> N21324210 | N10: =VLOOKUP(L10,WORKING!$L:$T,9,0) -> J1706_PIN02 | O10: =VLOOKUP("U7."&D10,'PIN REPORT'!$A:$G,7,0) -> U7_XPCITXN[0] | P10: =VLOOKUP(O10,WORKING!$L:$P,5,0) -> N21327305 | Q10: =VLOOKUP(O10,WORKING!$L:$T,9,0) -> J1504_PIN85
D11: AM39 | E11: XPCITXP[0] | F11: =VLOOKUP("U1."&D11,'PIN REPORT'!$A:$G,7,0) -> U1_XPCITXP[0] | G11: =VLOOKUP(F11,WORKING!$L:$P,5,0) -> N19908247 | H11: =VLOOKUP(F11,WORKING!$L:$T,9,0) -> J1609_PIN89 | I11: =VLOOKUP("U3."&D11,'PIN REPORT'!$A:$G,7,0) -> U3_XPCITXP[0] | J11: =VLOOKUP(I11,WORKING!$L:$P,5,0) -> N21317673 | K11: =VLOOKUP(I11,WORKING!$L:$T,9,0) -> J1809_PIN90 | L11: =VLOOKUP("U5."&D11,'PIN REPORT'!$A:$G,7,0) -> U5_XPCITXP[0] | M11: =VLOOKUP(L11,WORKING!$L:$P,5,0) -> N21324357 | N11: =VLOOKUP(L11,WORKING!$L:$T,9,0) -> J1706_PIN01 | O11: =VLOOKUP("U7."&D11,'PIN REPORT'!$A:$G,7,0) -> U7_XPCITXP[0] | P11: =VLOOKUP(O11,WORKING!$L:$P,5,0) -> N21327452 | Q11: =VLOOKUP(O11,WORKING!$L:$T,9,0) -> J1504_PIN87
D12: AH38 | E12: XPCIRXN[1] | F12: =VLOOKUP("U1."&D12,'PIN REPORT'!$A:$G,7,0) -> U1_XPCIRXN[1] | G12: =VLOOKUP(F12,WORKING!$L:$P,5,0) -> N19952660 | H12: =VLOOKUP(F12,WORKING!$L:$T,9,0) -> J1609_PIN90 | I12: =VLOOKUP("U3."&D12,'PIN REPORT'!$A:$G,7,0) -> U3_XPCIRXN[1] | J12: =VLOOKUP(I12,WORKING!$L:$P,5,0) -> N21318162 | K12: =VLOOKUP(I12,WORKING!$L:$T,9,0) -> J1809_PIN92 | L12: =VLOOKUP("U5."&D12,'PIN REPORT'!$A:$G,7,0) -> U5_XPCIRXN[1] | M12: =VLOOKUP(L12,WORKING!$L:$P,5,0) -> N21324856 | N12: =VLOOKUP(L12,WORKING!$L:$T,9,0) -> J1704_PIN99 | O12: =VLOOKUP("U7."&D12,'PIN REPORT'!$A:$G,7,0) -> U7_XPCIRXN[1] | P12: =VLOOKUP(O12,WORKING!$L:$P,5,0) -> N21327951 | Q12: =VLOOKUP(O12,WORKING!$L:$T,9,0) -> J1507_PIN92
D13: AH37 | E13: XPCIRXP[1] | F13: =VLOOKUP("U1."&D13,'PIN REPORT'!$A:$G,7,0) -> U1_XPCIRXP[1] | G13: =VLOOKUP(F13,WORKING!$L:$P,5,0) -> N19952650 | H13: =VLOOKUP(F13,WORKING!$L:$T,9,0) -> J1609_PIN87 | I13: =VLOOKUP("U3."&D13,'PIN REPORT'!$A:$G,7,0) -> U3_XPCIRXP[1] | J13: =VLOOKUP(I13,WORKING!$L:$P,5,0) -> N21317840 | K13: =VLOOKUP(I13,WORKING!$L:$T,9,0) -> J1809_PIN94 | L13: =VLOOKUP("U5."&D13,'PIN REPORT'!$A:$G,7,0) -> U5_XPCIRXP[1] | M13: =VLOOKUP(L13,WORKING!$L:$P,5,0) -> N21324536 | N13: =VLOOKUP(L13,WORKING!$L:$T,9,0) -> J1704_PIN100 | O13: =VLOOKUP("U7."&D13,'PIN REPORT'!$A:$G,7,0) -> U7_XPCIRXP[1] | P13: =VLOOKUP(O13,WORKING!$L:$P,5,0) -> N21327631 | Q13: =VLOOKUP(O13,WORKING!$L:$T,9,0) -> J1507_PIN90
D14: AM40 | E14: XPCITXN[1] | F14: =VLOOKUP("U1."&D14,'PIN REPORT'!$A:$G,7,0) -> U1_XPCITXN[1] | G14: =VLOOKUP(F14,WORKING!$L:$P,5,0) -> N19952402 | H14: =VLOOKUP(F14,WORKING!$L:$T,9,0) -> J1609_PIN90 | I14: =VLOOKUP("U3."&D14,'PIN REPORT'!$A:$G,7,0) -> U3_XPCITXN[1] | J14: =VLOOKUP(I14,WORKING!$L:$P,5,0) -> N21317844 | K14: =VLOOKUP(I14,WORKING!$L:$T,9,0) -> J1809_PIN92 | L14: =VLOOKUP("U5."&D14,'PIN REPORT'!$A:$G,7,0) -> U5_XPCITXN[1] | M14: =VLOOKUP(L14,WORKING!$L:$P,5,0) -> N21324532 | N14: =VLOOKUP(L14,WORKING!$L:$T,9,0) -> J1704_PIN99 | O14: =VLOOKUP("U7."&D14,'PIN REPORT'!$A:$G,7,0) -> U7_XPCITXN[1] | P14: =VLOOKUP(O14,WORKING!$L:$P,5,0) -> N21327627 | Q14: =VLOOKUP(O14,WORKING!$L:$T,9,0) -> J1507_PIN92
D15: AL40 | E15: XPCITXP[1] | F15: =VLOOKUP("U1."&D15,'PIN REPORT'!$A:$G,7,0) -> U1_XPCITXP[1] | G15: =VLOOKUP(F15,WORKING!$L:$P,5,0) -> N19952435 | H15: =VLOOKUP(F15,WORKING!$L:$T,9,0) -> J1609_PIN87 | I15: =VLOOKUP("U3."&D15,'PIN REPORT'!$A:$G,7,0) -> U3_XPCITXP[1] | J15: =VLOOKUP(I15,WORKING!$L:$P,5,0) -> N21317842 | K15: =VLOOKUP(I15,WORKING!$L:$T,9,0) -> J1809_PIN94 | L15: =VLOOKUP("U5."&D15,'PIN REPORT'!$A:$G,7,0) -> U5_XPCITXP[1] | M15: =VLOOKUP(L15,WORKING!$L:$P,5,0) -> N21324534 | N15: =VLOOKUP(L15,WORKING!$L:$T,9,0) -> J1704_PIN100 | O15: =VLOOKUP("U7."&D15,'PIN REPORT'!$A:$G,7,0) -> U7_XPCITXP[1] | P15: =VLOOKUP(O15,WORKING!$L:$P,5,0) -> N21327629 | Q15: =VLOOKUP(O15,WORKING!$L:$T,9,0) -> J1507_PIN90
D16: AG37 | E16: XPCIRXN[2] | F16: =VLOOKUP("U1."&D16,'PIN REPORT'!$A:$G,7,0) -> U1_XPCIRXN[2] | G16: =VLOOKUP(F16,WORKING!$L:$P,5,0) -> N19954453 | H16: =VLOOKUP(F16,WORKING!$L:$T,9,0) -> J1608_PIN48 | I16: =VLOOKUP("U3."&D16,'PIN REPORT'!$A:$G,7,0) -> U3_XPCIRXN[2] | J16: =VLOOKUP(I16,WORKING!$L:$P,5,0) -> N21317933 | K16: =VLOOKUP(I16,WORKING!$L:$T,9,0) -> J1809_PIN98 | L16: =VLOOKUP("U5."&D16,'PIN REPORT'!$A:$G,7,0) -> U5_XPCIRXN[2] | M16: =VLOOKUP(L16,WORKING!$L:$P,5,0) -> N21324607 | N16: =VLOOKUP(L16,WORKING!$L:$T,9,0) -> J1705_PIN58 | O16: =VLOOKUP("U7."&D16,'PIN REPORT'!$A:$G,7,0) -> U7_XPCIRXN[2] | P16: =VLOOKUP(O16,WORKING!$L:$P,5,0) -> N21327702 | Q16: =VLOOKUP(O16,WORKING!$L:$T,9,0) -> J1507_PIN106
D17: AG36 | E17: XPCIRXP[2] | F17: =VLOOKUP("U1."&D17,'PIN REPORT'!$A:$G,7,0) -> U1_XPCIRXP[2] | G17: =VLOOKUP(F17,WORKING!$L:$P,5,0) -> N19954463 | H17: =VLOOKUP(F17,WORKING!$L:$T,9,0) -> J1608_PIN47 | I17: =VLOOKUP("U3."&D17,'PIN REPORT'!$A:$G,7,0) -> U3_XPCIRXP[2] | J17: =VLOOKUP(I17,WORKING!$L:$P,5,0) -> N21318510 | K17: =VLOOKUP(I17,WORKING!$L:$T,9,0) -> J1809_PIN95 | L17: =VLOOKUP("U5."&D17,'PIN REPORT'!$A:$G,7,0) -> U5_XPCIRXP[2] | M17: =VLOOKUP(L17,WORKING!$L:$P,5,0) -> N21325184 | N17: =VLOOKUP(L17,WORKING!$L:$T,9,0) -> J1705_PIN57 | O17: =VLOOKUP("U7."&D17,'PIN REPORT'!$A:$G,7,0) -> U7_XPCIRXP[2] | P17: =VLOOKUP(O17,WORKING!$L:$P,5,0) -> N21328279 | Q17: =VLOOKUP(O17,WORKING!$L:$T,9,0) -> J1507_PIN104
D18: AK40 | E18: XPCITXN[2] | F18: =VLOOKUP("U1."&D18,'PIN REPORT'!$A:$G,7,0) -> U1_XPCITXN[2] | G18: =VLOOKUP(F18,WORKING!$L:$P,5,0) -> N19953974 | H18: =VLOOKUP(F18,WORKING!$L:$T,9,0) -> J1608_PIN48 | I18: =VLOOKUP("U3."&D18,'PIN REPORT'!$A:$G,7,0) -> U3_XPCITXN[2] | J18: =VLOOKUP(I18,WORKING!$L:$P,5,0) -> N21317824 | K18: =VLOOKUP(I18,WORKING!$L:$T,9,0) -> J1809_PIN98 | L18: =VLOOKUP("U5."&D18,'PIN REPORT'!$A:$G,7,0) -> U5_XPCITXN[2] | M18: =VLOOKUP(L18,WORKING!$L:$P,5,0) -> N21324520 | N18: =VLOOKUP(L18,WORKING!$L:$T,9,0) -> J1705_PIN58 | O18: =VLOOKUP("U7."&D18,'PIN REPORT'!$A:$G,7,0) -> U7_XPCITXN[2] | P18: =VLOOKUP(O18,WORKING!$L:$P,5,0) -> N21327615 | Q18: =VLOOKUP(O18,WORKING!$L:$T,9,0) -> J1507_PIN106
D19: AK39 | E19: XPCITXP[2] | F19: =VLOOKUP("U1."&D19,'PIN REPORT'!$A:$G,7,0) -> U1_XPCITXP[2] | G19: =VLOOKUP(F19,WORKING!$L:$P,5,0) -> N19953941 | H19: =VLOOKUP(F19,WORKING!$L:$T,9,0) -> J1608_PIN47 | I19: =VLOOKUP("U3."&D19,'PIN REPORT'!$A:$G,7,0) -> U3_XPCITXP[2] | J19: =VLOOKUP(I19,WORKING!$L:$P,5,0) -> N21317822 | K19: =VLOOKUP(I19,WORKING!$L:$T,9,0) -> J1809_PIN95 | L19: =VLOOKUP("U5."&D19,'PIN REPORT'!$A:$G,7,0) -> U5_XPCITXP[2] | M19: =VLOOKUP(L19,WORKING!$L:$P,5,0) -> N21324504 | N19: =VLOOKUP(L19,WORKING!$L:$T,9,0) -> J1705_PIN57 | O19: =VLOOKUP("U7."&D19,'PIN REPORT'!$A:$G,7,0) -> U7_XPCITXP[2] | P19: =VLOOKUP(O19,WORKING!$L:$P,5,0) -> N21327599 | Q19: =VLOOKUP(O19,WORKING!$L:$T,9,0) -> J1507_PIN104
... D39: AE37 | E39: XPCITXP[7] | F39: =VLOOKUP("U1."&D39,'PIN REPORT'!$A:$G,7,0) -> U1_XPCITXP[7] | G39: =VLOOKUP(F39,WORKING!$L:$P,5,0) -> N19956335 | H39: =VLOOKUP(F39,WORKING!$L:$T,9,0) -> J1602_PIN50 | I39: =VLOOKUP("U3."&D39,'PIN REPORT'!$A:$G,7,0) -> U3_XPCITXP[7] | J39: =VLOOKUP(I39,WORKING!$L:$P,5,0) -> N21321224 | K39: =VLOOKUP(I39,WORKING!$L:$T,9,0) -> J1802_PIN50 | L39: =VLOOKUP("U5."&D39,'PIN REPORT'!$A:$G,7,0) -> U5_XPCITXP[7] | M39: =VLOOKUP(L39,WORKING!$L:$P,5,0) -> N21330847 | N39: =VLOOKUP(L39,WORKING!$L:$T,9,0) -> J1706_PIN19 | O39: =VLOOKUP("U7."&D39,'PIN REPORT'!$A:$G,7,0) -> U7_XPCITXP[7] | P39: =VLOOKUP(O39,WORKING!$L:$P,5,0) -> N21334640 | Q39: =VLOOKUP(O39,WORKING!$L:$T,9,0) -> J1509_PIN12

Sheet CIRCUIT2
D7: SITE-1 | F7: SITE-3 | H7: SITE-5 | J7: SITE-7
B9: CUSTOMER PINLIST | D9: R&D-ALTANOVA ASSIGNMENT | F9: R&D-ALTANOVA ASSIGNMENT | H9: R&D-ALTANOVA ASSIGNMENT | J9: R&D-ALTANOVA ASSIGNMENT
B11: Ball Location | C11: Ball Name | D11: DUT TO INDUCTOR | E11: INDUCTOR TO TESTER | F11: DUT TO INDUCTOR | G11: INDUCTOR TO TESTER | H11: DUT TO INDUCTOR | I11: INDUCTOR TO TESTER | J11: DUT TO INDUCTOR | K11: INDUCTOR TO TESTER
B12: AW36 | C12: XSERDESRXN[1] | D12: =VLOOKUP("U1."&B12,'PIN REPORT'!$A:$G,7,0) -> U1_XSERDESRXN[1] | E12: =VLOOKUP(D12,WORKING!$V:$Z,5,0) -> J1609_PIN100 | F12: =VLOOKUP("U3."&B12,'PIN REPORT'!$A:$G,7,0) -> U3_XSERDESRXN[1] | G12: =VLOOKUP(F12,WORKING!$V:$Z,5,0) -> J1809_PIN113 | H12: =VLOOKUP("U5."&B12,'PIN REPORT'!$A:$G,7,0) -> U5_XSERDESRXN[1] | I12: =VLOOKUP(H12,WORKING!$V:$Z,5,0) -> J1701_PIN100 | J12: =VLOOKUP("U7."&B12,'PIN REPORT'!$A:$G,7,0) -> U7_XSERDESRXN[1] | K12: =VLOOKUP(J12,WORKING!$V:$Z,5,0) -> J1501_PIN104
B13: AY36 | C13: XSERDESRXP[1] | D13: =VLOOKUP("U1."&B13,'PIN REPORT'!$A:$G,7,0) -> U1_XSERDESRXP[1] | E13: =VLOOKUP(D13,WORKING!$V:$Z,5,0) -> J1609_PIN102 | F13: =VLOOKUP("U3."&B13,'PIN REPORT'!$A:$G,7,0) -> U3_XSERDESRXP[1] | G13: =VLOOKUP(F13,WORKING!$V:$Z,5,0) -> J1809_PIN111 | H13: =VLOOKUP("U5."&B13,'PIN REPORT'!$A:$G,7,0) -> U5_XSERDESRXP[1] | I13: =VLOOKUP(H13,WORKING!$V:$Z,5,0) -> J1701_PIN99 | J13: =VLOOKUP("U7."&B13,'PIN REPORT'!$A:$G,7,0) -> U7_XSERDESRXP[1] | K13: =VLOOKUP(J13,WORKING!$V:$Z,5,0) -> J1501_PIN103
B14: AR40 | C14: XSERDESTXN[1] | D14: =VLOOKUP("U1."&B14,'PIN REPORT'!$A:$G,7,0) -> U1_XSERDESTXN[1] | E14: =VLOOKUP(D14,WORKING!$V:$Z,5,0) -> J1609_PIN95 | F14: =VLOOKUP("U3."&B14,'PIN REPORT'!$A:$G,7,0) -> U3_XSERDESTXN[1] | G14: =VLOOKUP(F14,WORKING!$V:$Z,5,0) -> J1809_PIN106 | H14: =VLOOKUP("U5."&B14,'PIN REPORT'!$A:$G,7,0) -> U5_XSERDESTXN[1] | I14: =VLOOKUP(H14,WORKING!$V:$Z,5,0) -> J1701_PIN93 | J14: =VLOOKUP("U7."&B14,'PIN REPORT'!$A:$G,7,0) -> U7_XSERDESTXN[1] | K14: =VLOOKUP(J14,WORKING!$V:$Z,5,0) -> J1501_PIN97
B15: AP40 | C15: XSERDESTXP[1] | D15: =VLOOKUP("U1."&B15,'PIN REPORT'!$A:$G,7,0) -> U1_XSERDESTXP[1] | E15: =VLOOKUP(D15,WORKING!$V:$Z,5,0) -> J1609_PIN125 | F15: =VLOOKUP("U3."&B15,'PIN REPORT'!$A:$G,7,0) -> U3_XSERDESTXP[1] | G15: =VLOOKUP(F15,WORKING!$V:$Z,5,0) -> J1809_PIN105 | H15: =VLOOKUP("U5."&B15,'PIN REPORT'!$A:$G,7,0) -> U5_XSERDESTXP[1] | I15: =VLOOKUP(H15,WORKING!$V:$Z,5,0) -> J1701_PIN94 | J15: =VLOOKUP("U7."&B15,'PIN REPORT'!$A:$G,7,0) -> U7_XSERDESTXP[1] | K15: =VLOOKUP(J15,WORKING!$V:$Z,5,0) -> J1501_PIN95

Sheet CIRCUIT3
D2: SITE-1 | F2: SITE-3 | H2: SITE-5 | J2: SITE-7
B4: CUSTOMER PINLIST | D4: R&D-ALTANOVA ASSIGNMENT | F4: R&D-ALTANOVA ASSIGNMENT | H4: R&D-ALTANOVA ASSIGNMENT | J4: R&D-ALTANOVA ASSIGNMENT
B6: Ball Location | C6: Ball Name | D6: DUT TO CAPACITOR | E6: CAPCITOR TO DUT (LOOPBACK) | F6: DUT TO CAPACITOR | G6: CAPCITOR TO DUT (LOOPBACK) | H6: DUT TO CAPACITOR | I6: CAPCITOR TO DUT (LOOPBACK) | J6: DUT TO CAPACITOR | K6: CAPCITOR TO DUT (LOOPBACK)
B7: AW34 | C7: XSERDESRXN[0] | D7: =VLOOKUP("U1."&B7,'PIN REPORT'!$A:$G,7,0) -> U1_XSERDESRXN[0] | E7: =VLOOKUP(D7,WORKING!$AC:$AG,5,0) -> U1_XSERDESTXN[0] | F7: =VLOOKUP("U3."&B7,'PIN REPORT'!$A:$G,7,0) -> U3_XSERDESRXN[0] | G7: =VLOOKUP(F7,WORKING!$AC:$AG,5,0) -> U3_XSERDESTXN[0] | H7: =VLOOKUP("U5."&B7,'PIN REPORT'!$A:$G,7,0) -> U5_XSERDESRXN[0] | I7: =VLOOKUP(H7,WORKING!$AC:$AG,5,0) -> U5_XSERDESTXN[0] | J7: =VLOOKUP("U7."&B7,'PIN REPORT'!$A:$G,7,0) -> U7_XSERDESRXN[0] | K7: =VLOOKUP(J7,WORKING!$AC:$AG,5,0) -> U7_XSERDESTXN[0]
B8: AY35 | C8: XSERDESRXP[0] | D8: =VLOOKUP("U1."&B8,'PIN REPORT'!$A:$G,7,0) -> U1_XSERDESRXP[0] | E8: =VLOOKUP(D8,WORKING!$AC:$AG,5,0) -> U1_XSERDESTXP[0] | F8: =VLOOKUP("U3."&B8,'PIN REPORT'!$A:$G,7,0) -> U3_XSERDESRXP[0] | G8: =VLOOKUP(F8,WORKING!$AC:$AG,5,0) -> U3_XSERDESTXP[0] | H8: =VLOOKUP("U5."&B8,'PIN REPORT'!$A:$G,7,0) -> U5_XSERDESRXP[0] | I8: =VLOOKUP(H8,WORKING!$AC:$AG,5,0) -> U5_XSERDESTXP[0] | J8: =VLOOKUP("U7."&B8,'PIN REPORT'!$A:$G,7,0) -> U7_XSERDESRXP[0] | K8: =VLOOKUP(J8,WORKING!$AC:$AG,5,0) -> U7_XSERDESTXP[0]
B9: AT39 | C9: XSERDESTXN[0] | D9: =VLOOKUP("U1."&B9,'PIN REPORT'!$A:$G,7,0) -> U1_XSERDESTXN[0] | E9: =VLOOKUP(D9,WORKING!$AC:$AG,5,0) -> U1_XSERDESRXN[0] | F9: =VLOOKUP("U3."&B9,'PIN REPORT'!$A:$G,7,0) -> U3_XSERDESTXN[0] | G9: =VLOOKUP(F9,WORKING!$AC:$AG,5,0) -> U3_XSERDESRXN[0] | H9: =VLOOKUP("U5."&B9,'PIN REPORT'!$A:$G,7,0) -> U5_XSERDESTXN[0] | I9: =VLOOKUP(H9,WORKING!$AC:$AG,5,0) -> U5_XSERDESRXN[0] | J9: =VLOOKUP("U7."&B9,'PIN REPORT'!$A:$G,7,0) -> U7_XSERDESTXN[0] | K9: =VLOOKUP(J9,WORKING!$AC:$AG,5,0) -> U7_XSERDESRXN[0]
B10: AT40 | C10: XSERDESTXP[0] | D10: =VLOOKUP("U1."&B10,'PIN REPORT'!$A:$G,7,0) -> U1_XSERDESTXP[0] | E10: =VLOOKUP(D10,WORKING!$AC:$AG,5,0) -> U1_XSERDESRXP[0] | F10: =VLOOKUP("U3."&B10,'PIN REPORT'!$A:$G,7,0) -> U3_XSERDESTXP[0] | G10: =VLOOKUP(F10,WORKING!$AC:$AG,5,0) -> U3_XSERDESRXP[0] | H10: =VLOOKUP("U5."&B10,'PIN REPORT'!$A:$G,7,0) -> U5_XSERDESTXP[0] | I10: =VLOOKUP(H10,WORKING!$AC:$AG,5,0) -> U5_XSERDESRXP[0] | J10: =VLOOKUP("U7."&B10,'PIN REPORT'!$A:$G,7,0) -> U7_XSERDESTXP[0] | K10: =VLOOKUP(J10,WORKING!$AC:$AG,5,0) -> U7_XSERDESRXP[0]

Sheet NO CONNECT PINS
D2: SITE-1 | E2: SITE-3 | F2: SITE-5 | G2: SITE-7
B4: CUSTOMER PINLIST | D4: R&D-ALTANOVA ASSIGNMENT | E4: R&D-ALTANOVA ASSIGNMENT | F4: R&D-ALTANOVA ASSIGNMENT | G4: R&D-ALTANOVA ASSIGNMENT
B6: Ball Location | C6: Ball Name
B7: L36 | C7: VCCSBOX0 | D7: =IF(VLOOKUP("U1."&B7,'PIN REPORT'!$A:$G,7,0)=0,"NC",VLOOKUP("U1."&B7,'PIN REPORT'!$A:$G,7,0)) -> NC | E7: =IF(VLOOKUP("U3."&B7,'PIN REPORT'!$A:$G,7,0)=0,"NC",VLOOKUP("U3."&B7,'PIN REPORT'!$A:$G,7,0)) -> NC | F7: =IF(VLOOKUP("U5."&B7,'PIN REPORT'!$A:$G,7,0)=0,"NC",VLOOKUP("U5."&B7,'PIN REPORT'!$A:$G,7,0)) -> NC | G7: =IF(VLOOKUP("U7."&B7,'PIN REPORT'!$A:$G,7,0)=0,"NC",VLOOKUP("U7."&B7,'PIN REPORT'!$A:$G,7,0)) -> NC
B8: M34 | C8: VCCSBOX1 | D8: =IF(VLOOKUP("U1."&B8,'PIN REPORT'!$A:$G,7,0)=0,"NC",VLOOKUP("U1."&B8,'PIN REPORT'!$A:$G,7,0)) -> NC | E8: =IF(VLOOKUP("U3."&B8,'PIN REPORT'!$A:$G,7,0)=0,"NC",VLOOKUP("U3."&B8,'PIN REPORT'!$A:$G,7,0)) -> NC | F8: =IF(VLOOKUP("U5."&B8,'PIN REPORT'!$A:$G,7,0)=0,"NC",VLOOKUP("U5."&B8,'PIN REPORT'!$A:$G,7,0)) -> NC | G8: =IF(VLOOKUP("U7."&B8,'PIN REPORT'!$A:$G,7,0)=0,"NC",VLOOKUP("U7."&B8,'PIN REPORT'!$A:$G,7,0)) -> NC
B9: F29 | C9: VCCSBOX2 | D9: =IF(VLOOKUP("U1."&B9,'PIN REPORT'!$A:$G,7,0)=0,"NC",VLOOKUP("U1."&B9,'PIN REPORT'!$A:$G,7,0)) -> NC | E9: =IF(VLOOKUP("U3."&B9,'PIN REPORT'!$A:$G,7,0)=0,"NC",VLOOKUP("U3."&B9,'PIN REPORT'!$A:$G,7,0)) -> NC | F9: =IF(VLOOKUP("U5."&B9,'PIN REPORT'!$A:$G,7,0)=0,"NC",VLOOKUP("U5."&B9,'PIN REPORT'!$A:$G,7,0)) -> NC | G9: =IF(VLOOKUP("U7."&B9,'PIN REPORT'!$A:$G,7,0)=0,"NC",VLOOKUP("U7."&B9,'PIN REPORT'!$A:$G,7,0)) -> NC
B10: H29 | C10: VCCSBOX3 | D10: =IF(VLOOKUP("U1."&B10,'PIN REPORT'!$A:$G,7,0)=0,"NC",VLOOKUP("U1."&B10,'PIN REPORT'!$A:$G,7,0)) -> NC | E10: =IF(VLOOKUP("U3."&B10,'PIN REPORT'!$A:$G,7,0)=0,"NC",VLOOKUP("U3."&B10,'PIN REPORT'!$A:$G,7,0)) -> NC | F10: =IF(VLOOKUP("U5."&B10,'PIN REPORT'!$A:$G,7,0)=0,"NC",VLOOKUP("U5."&B10,'PIN REPORT'!$A:$G,7,0)) -> NC | G10: =IF(VLOOKUP("U7."&B10,'PIN REPORT'!$A:$G,7,0)=0,"NC",VLOOKUP("U7."&B10,'PIN REPORT'!$A:$G,7,0)) -> NC
B11: C32 | C11: XACTHSIO[0] | D11: =IF(VLOOKUP("U1."&B11,'PIN REPORT'!$A:$G,7,0)=0,"NC",VLOOKUP("U1."&B11,'PIN REPORT'!$A:$G,7,0)) -> NC | E11: =IF(VLOOKUP("U3."&B11,'PIN REPORT'!$A:$G,7,0)=0,"NC",VLOOKUP("U3."&B11,'PIN REPORT'!$A:$G,7,0)) -> NC | F11: =IF(VLOOKUP("U5."&B11,'PIN REPORT'!$A:$G,7,0)=0,"NC",VLOOKUP("U5."&B11,'PIN REPORT'!$A:$G,7,0)) -> NC | G11: =IF(VLOOKUP("U7."&B11,'PIN REPORT'!$A:$G,7,0)=0,"NC",VLOOKUP("U7."&B11,'PIN REPORT'!$A:$G,7,0)) -> NC
B12: F33 | C12: XACTHSIO[1] | D12: =IF(VLOOKUP("U1."&B12,'PIN REPORT'!$A:$G,7,0)=0,"NC",VLOOKUP("U1."&B12,'PIN REPORT'!$A:$G,7,0)) -> NC | E12: =IF(VLOOKUP("U3."&B12,'PIN REPORT'!$A:$G,7,0)=0,"NC",VLOOKUP("U3."&B12,'PIN REPORT'!$A:$G,7,0)) -> NC | F12: =IF(VLOOKUP("U5."&B12,'PIN REPORT'!$A:$G,7,0)=0,"NC",VLOOKUP("U5."&B12,'PIN REPORT'!$A:$G,7,0)) -> NC | G12: =IF(VLOOKUP("U7."&B12,'PIN REPORT'!$A:$G,7,0)=0,"NC",VLOOKUP("U7."&B12,'PIN REPORT'!$A:$G,7,0)) -> NC
B13: E32 | C13: XACTHSIO[2] | D13: =IF(VLOOKUP("U1."&B13,'PIN REPORT'!$A:$G,7,0)=0,"NC",VLOOKUP("U1."&B13,'PIN REPORT'!$A:$G,7,0)) -> NC | E13: =IF(VLOOKUP("U3."&B13,'PIN REPORT'!$A:$G,7,0)=0,"NC",VLOOKUP("U3."&B13,'PIN REPORT'!$A:$G,7,0)) -> NC | F13: =IF(VLOOKUP("U5."&B13,'PIN REPORT'!$A:$G,7,0)=0,"NC",VLOOKUP("U5."&B13,'PIN REPORT'!$A:$G,7,0)) -> NC | G13: =IF(VLOOKUP("U7."&B13,'PIN REPORT'!$A:$G,7,0)=0,"NC",VLOOKUP("U7."&B13,'PIN REPORT'!$A:$G,7,0)) -> NC
B14: G40 | C14: XACTHSIO[3] | D14: =IF(VLOOKUP("U1."&B14,'PIN REPORT'!$A:$G,7,0)=0,"NC",VLOOKUP("U1."&B14,'PIN REPORT'!$A:$G,7,0)) -> NC | E14: =IF(VLOOKUP("U3."&B14,'PIN REPORT'!$A:$G,7,0)=0,"NC",VLOOKUP("U3."&B14,'PIN REPORT'!$A:$G,7,0)) -> NC | F14: =IF(VLOOKUP("U5."&B14,'PIN REPORT'!$A:$G,7,0)=0,"NC",VLOOKUP("U5."&B14,'PIN REPORT'!$A:$G,7,0)) -> NC | G14: =IF(VLOOKUP("U7."&B14,'PIN REPORT'!$A:$G,7,0)=0,"NC",VLOOKUP("U7."&B14,'PIN REPORT'!$A:$G,7,0)) -> NC
B15: AD8 | C15: XDDR_DIGOUT[6] | D15: =IF(VLOOKUP("U1."&B15,'PIN REPORT'!$A:$G,7,0)=0,"NC",VLOOKUP("U1."&B15,'PIN REPORT'!$A:$G,7,0)) -> NC | E15: =IF(VLOOKUP("U3."&B15,'PIN REPORT'!$A:$G,7,0)=0,"NC",VLOOKUP("U3."&B15,'PIN REPORT'!$A:$G,7,0)) -> NC | F15: =IF(VLOOKUP("U5."&B15,'PIN REPORT'!$A:$G,7,0)=0,"NC",VLOOKUP("U5."&B15,'PIN REPORT'!$A:$G,7,0)) -> NC | G15: =IF(VLOOKUP("U7."&B15,'PIN REPORT'!$A:$G,7,0)=0,"NC",VLOOKUP("U7."&B15,'PIN REPORT'!$A:$G,7,0)) -> NC
B16: AC8 | C16: XDDR_DIGOUT[7] | D16: =IF(VLOOKUP("U1."&B16,'PIN REPORT'!$A:$G,7,0)=0,"NC",VLOOKUP("U1."&B16,'PIN REPORT'!$A:$G,7,0)) -> NC | E16: =IF(VLOOKUP("U3."&B16,'PIN REPORT'!$A:$G,7,0)=0,"NC",VLOOKUP("U3."&B16,'PIN REPORT'!$A:$G,7,0)) -> NC | F16: =IF(VLOOKUP("U5."&B16,'PIN REPORT'!$A:$G,7,0)=0,"NC",VLOOKUP("U5."&B16,'PIN REPORT'!$A:$G,7,0)) -> NC | G16: =IF(VLOOKUP("U7."&B16,'PIN REPORT'!$A:$G,7,0)=0,"NC",VLOOKUP("U7."&B16,'PIN REPORT'!$A:$G,7,0)) -> NC
B17: AD1 | C17: XDDR_DIGOUT[8] | D17: =IF(VLOOKUP("U1."&B17,'PIN REPORT'!$A:$G,7,0)=0,"NC",VLOOKUP("U1."&B17,'PIN REPORT'!$A:$G,7,0)) -> NC | E17: =IF(VLOOKUP("U3."&B17,'PIN REPORT'!$A:$G,7,0)=0,"NC",VLOOKUP("U3."&B17,'PIN REPORT'!$A:$G,7,0)) -> NC | F17: =IF(VLOOKUP("U5."&B17,'PIN REPORT'!$A:$G,7,0)=0,"NC",VLOOKUP("U5."&B17,'PIN REPORT'!$A:$G,7,0)) -> NC | G17: =IF(VLOOKUP("U7."&B17,'PIN REPORT'!$A:$G,7,0)=0,"NC",VLOOKUP("U7."&B17,'PIN REPORT'!$A:$G,7,0)) -> NC
B18: AD2 | C18: XDDR_DIGOUT[9] | D18: =IF(VLOOKUP("U1."&B18,'PIN REPORT'!$A:$G,7,0)=0,"NC",VLOOKUP("U1."&B18,'PIN REPORT'!$A:$G,7,0)) -> NC | E18: =IF(VLOOKUP("U3."&B18,'PIN REPORT'!$A:$G,7,0)=0,"NC",VLOOKUP("U3."&B18,'PIN REPORT'!$A:$G,7,0)) -> NC | F18: =IF(VLOOKUP("U5."&B18,'PIN REPORT'!$A:$G,7,0)=0,"NC",VLOOKUP("U5."&B18,'PIN REPORT'!$A:$G,7,0)) -> NC | G18: =IF(VLOOKUP("U7."&B18,'PIN REPORT'!$A:$G,7,0)=0,"NC",VLOOKUP("U7."&B18,'PIN REPORT'!$A:$G,7,0)) -> NC
... B81: P3 | C81: XSTKVMIDLFT[3] | D81: =IF(VLOOKUP("U1."&B81,'PIN REPORT'!$A:$G,7,0)=0,"NC",VLOOKUP("U1."&B81,'PIN REPORT'!$A:$G,7,0)) -> NC | E81: =IF(VLOOKUP("U3."&B81,'PIN REPORT'!$A:$G,7,0)=0,"NC",VLOOKUP("U3."&B81,'PIN REPORT'!$A:$G,7,0)) -> NC | F81: =IF(VLOOKUP("U5."&B81,'PIN REPORT'!$A:$G,7,0)=0,"NC",VLOOKUP("U5."&B81,'PIN REPORT'!$A:$G,7,0)) -> NC | G81: =IF(VLOOKUP("U7."&B81,'PIN REPORT'!$A:$G,7,0)=0,"NC",VLOOKUP("U7."&B81,'PIN REPORT'!$A:$G,7,0)) -> NC

Sheet POWER
E2: SITE-1 | F2: SITE-3 | G2: SITE-5 | H2: SITE-7
K3: MERGED SUPPLIES
C4: CUSTOMER PINLIST | E4: R&D-ALTANOVA ASSIGNMENT | F4: R&D-ALTANOVA ASSIGNMENT | G4: R&D-ALTANOVA ASSIGNMENT | H4: R&D-ALTANOVA ASSIGNMENT
K5: SITE-1 | N5: SITE-3 | Q5: SITE-5 | T5: SITE-7
C6: Ball Location | D6: Ball Name | K6: SUPPLY NAME | L6: CHANNELS MERGED | N6: SUPPLY NAME | O6: CHANNELS MERGED | Q6: SUPPLY NAME | R6: CHANNELS MERGED | T6: SUPPLY NAME | U6: CHANNELS MERGED
C7: M33 | D7: VCCPLL0 | E7: =VLOOKUP("U1."&C7,'PIN REPORT'!$A:$G,7,0) -> J1207_LDP5F | F7: =VLOOKUP("U3."&C7,'PIN REPORT'!$A:$G,7,0) -> J1402_LDP3F | G7: =VLOOKUP("U5."&C7,'PIN REPORT'!$A:$G,7,0) -> J1302_LDP5F | H7: =VLOOKUP("U7."&C7,'PIN REPORT'!$A:$G,7,0) -> J1103_LDP3F | K7: U1_VCC | L7: J1205_HDP1F | N7: U3_VCC | O7: J1401_HDP1F | Q7: U5_VCC | R7: J1304_HDP1F | T7: U7_VCC | U7: J1104_HDP1F
C8: L32 | D8: VCCPLL1 | E8: =VLOOKUP("U1."&C8,'PIN REPORT'!$A:$G,7,0) -> J1207_LDP5F | F8: =VLOOKUP("U3."&C8,'PIN REPORT'!$A:$G,7,0) -> J1402_LDP3F | G8: =VLOOKUP("U5."&C8,'PIN REPORT'!$A:$G,7,0) -> J1302_LDP5F | H8: =VLOOKUP("U7."&C8,'PIN REPORT'!$A:$G,7,0) -> J1103_LDP3F | L8: J1205_HDP2F | O8: J1401_HDP2F | R8: J1304_HDP2F | U8: J1104_HDP2F
C9: K34 | D9: VCCPLL2 | E9: =VLOOKUP("U1."&C9,'PIN REPORT'!$A:$G,7,0) -> J1207_LDP5F | F9: =VLOOKUP("U3."&C9,'PIN REPORT'!$A:$G,7,0) -> J1402_LDP3F | G9: =VLOOKUP("U5."&C9,'PIN REPORT'!$A:$G,7,0) -> J1302_LDP5F | H9: =VLOOKUP("U7."&C9,'PIN REPORT'!$A:$G,7,0) -> J1103_LDP3F | L9: J1206_HDP3F | O9: J1402_HDP3F | R9: J1303_HDP3F | U9: J1103_HDP3F
C10: K32 | D10: VCCPLL3 | E10: =VLOOKUP("U1."&C10,'PIN REPORT'!$A:$G,7,0) -> J1207_LDP5F | F10: =VLOOKUP("U3."&C10,'PIN REPORT'!$A:$G,7,0) -> J1402_LDP3F | G10: =VLOOKUP("U5."&C10,'PIN REPORT'!$A:$G,7,0) -> J1302_LDP5F | H10: =VLOOKUP("U7."&C10,'PIN REPORT'!$A:$G,7,0) -> J1103_LDP3F | L10: J1206_HDP4F | O10: J1402_HDP4F | R10: J1303_HDP4F | U10: J1103_HDP4F
C11: W35 | D11: VCCFHV | E11: =VLOOKUP("U1."&C11,'PIN REPORT'!$A:$G,7,0) -> J1208_LDP7F | F11: =VLOOKUP("U3."&C11,'PIN REPORT'!$A:$G,7,0) -> J1403_LDP5F | G11: =VLOOKUP("U5."&C11,'PIN REPORT'!$A:$G,7,0) -> J1301_LDP7F | H11: =VLOOKUP("U7."&C11,'PIN REPORT'!$A:$G,7,0) -> J1102_LDP5F | L11: J1207_HDP5F | O11: J1403_HDP5F | R11: J1302_HDP5F | U11: J1102_HDP5F
C12: D35 | D12: VCCTHM | E12: =VLOOKUP("U1."&C12,'PIN REPORT'!$A:$G,7,0) -> J1205_LDP2F | F12: =VLOOKUP("U3."&C12,'PIN REPORT'!$A:$G,7,0) -> J1401_LDP1F | G12: =VLOOKUP("U5."&C12,'PIN REPORT'!$A:$G,7,0) -> J1304_LDP2F | H12: =VLOOKUP("U7."&C12,'PIN REPORT'!$A:$G,7,0) -> J1103_LDP4F | L12: J1207_HDP6F | O12: J1403_HDP6F | R12: J1302_HDP6F | U12: J1102_HDP6F
C13: J29 | D13: VCCTHMDIG | E13: =VLOOKUP("U1."&C13,'PIN REPORT'!$A:$G,7,0) -> J1205_LDP2F | F13: =VLOOKUP("U3."&C13,'PIN REPORT'!$A:$G,7,0) -> J1401_LDP1F | G13: =VLOOKUP("U5."&C13,'PIN REPORT'!$A:$G,7,0) -> J1304_LDP2F | H13: =VLOOKUP("U7."&C13,'PIN REPORT'!$A:$G,7,0) -> J1103_LDP4F
C14: L29 | D14: VCCTHM_HV | E14: =VLOOKUP("U1."&C14,'PIN REPORT'!$A:$G,7,0) -> J1205_LDP1F | F14: =VLOOKUP("U3."&C14,'PIN REPORT'!$A:$G,7,0) -> J1401_LDP2F | G14: =VLOOKUP("U5."&C14,'PIN REPORT'!$A:$G,7,0) -> J1304_LDP1F | H14: =VLOOKUP("U7."&C14,'PIN REPORT'!$A:$G,7,0) -> J1104_LDP2F | K14: U1_VCCG | L14: J1208_HDP7F | N14: U3_VCCG | O14: J1404_HDP7F | Q14: U5_VCCG | R14: J1301_HDP7F | T14: U7_VCCG | U14: J1101_HDP7F
C15: U37 | D15: VCCADCA | E15: =VLOOKUP("U1."&C15,'PIN REPORT'!$A:$G,7,0) -> U1_VCCADCA | F15: =VLOOKUP("U3."&C15,'PIN REPORT'!$A:$G,7,0) -> U3_VCCADCA | G15: =VLOOKUP("U5."&C15,'PIN REPORT'!$A:$G,7,0) -> U5_VCCADCA | H15: =VLOOKUP("U7."&C15,'PIN REPORT'!$A:$G,7,0) -> U7_VCCADCA | L15: J1208_HDP8F | O15: J1404_HDP8F | R15: J1301_HDP8F | U15: J1101_HDP8F
C16: K38 | D16: VCCIDV | E16: =VLOOKUP("U1."&C16,'PIN REPORT'!$A:$G,7,0) -> J1206_LDP3F | F16: =VLOOKUP("U3."&C16,'PIN REPORT'!$A:$G,7,0) -> J1402_LDP4F | G16: =VLOOKUP("U5."&C16,'PIN REPORT'!$A:$G,7,0) -> J1303_LDP3F | H16: =VLOOKUP("U7."&C16,'PIN REPORT'!$A:$G,7,0) -> J1104_LDP1F
C17: AB8 | D17: VCCIOA | E17: =VLOOKUP("U1."&C17,'PIN REPORT'!$A:$G,7,0) -> J1208_LDP8F | F17: =VLOOKUP("U3."&C17,'PIN REPORT'!$A:$G,7,0) -> J1404_LDP7F | G17: =VLOOKUP("U5."&C17,'PIN REPORT'!$A:$G,7,0) -> J1301_LDP8F | H17: =VLOOKUP("U7."&C17,'PIN REPORT'!$A:$G,7,0) -> J1101_LDP7F | K17: U1_VCC_DPLL_TDC | L17: J1210_LDP7F | N17: U3_VCC_DPLL_TDC | O17: J1406_LDP7F | Q17: U5_VCC_DPLL_TDC | R17: J1408_LDP7F | T17: U7_VCC_DPLL_TDC | U17: J1105_LDP7F
C18: N33 | D18: VCCIDV_EHV | E18: =VLOOKUP("U1."&C18,'PIN REPORT'!$A:$G,7,0) -> J1206_LDP4F | F18: =VLOOKUP("U3."&C18,'PIN REPORT'!$A:$G,7,0) -> J1403_LDP6F | G18: =VLOOKUP("U5."&C18,'PIN REPORT'!$A:$G,7,0) -> J1303_LDP4F | H18: =VLOOKUP("U7."&C18,'PIN REPORT'!$A:$G,7,0) -> J1102_LDP6F | L18: J1210_LDP8F | O18: J1406_LDP8F | R18: J1408_LDP8F | U18: J1105_LDP8F
C19: A11 | D19: VCC | E19: =VLOOKUP("U1."&C19,'PIN REPORT'!$A:$G,7,0) -> J1205_HDP1F | F19: =VLOOKUP("U3."&C19,'PIN REPORT'!$A:$G,7,0) -> J1401_HDP1F | G19: =VLOOKUP("U5."&C19,'PIN REPORT'!$A:$G,7,0) -> J1304_HDP1F | H19: =VLOOKUP("U7."&C19,'PIN REPORT'!$A:$G,7,0) -> J1104_HDP1F
C20: A12 | D20: VCC | E20: =VLOOKUP("U1."&C20,'PIN REPORT'!$A:$G,7,0) -> J1205_HDP1F | F20: =VLOOKUP("U3."&C20,'PIN REPORT'!$A:$G,7,0) -> J1401_HDP1F | G20: =VLOOKUP("U5."&C20,'PIN REPORT'!$A:$G,7,0) -> J1304_HDP1F | H20: =VLOOKUP("U7."&C20,'PIN REPORT'!$A:$G,7,0) -> J1104_HDP1F
C21: A15 | D21: VCC | E21: =VLOOKUP("U1."&C21,'PIN REPORT'!$A:$G,7,0) -> J1205_HDP1F | F21: =VLOOKUP("U3."&C21,'PIN REPORT'!$A:$G,7,0) -> J1401_HDP1F | G21: =VLOOKUP("U5."&C21,'PIN REPORT'!$A:$G,7,0) -> J1304_HDP1F | H21: =VLOOKUP("U7."&C21,'PIN REPORT'!$A:$G,7,0) -> J1104_HDP1F
C22: A16 | D22: VCC | E22: =VLOOKUP("U1."&C22,'PIN REPORT'!$A:$G,7,0) -> J1205_HDP1F | F22: =VLOOKUP("U3."&C22,'PIN REPORT'!$A:$G,7,0) -> J1401_HDP1F | G22: =VLOOKUP("U5."&C22,'PIN REPORT'!$A:$G,7,0) -> J1304_HDP1F | H22: =VLOOKUP("U7."&C22,'PIN REPORT'!$A:$G,7,0) -> J1104_HDP1F
C23: A23 | D23: VCC | E23: =VLOOKUP("U1."&C23,'PIN REPORT'!$A:$G,7,0) -> J1205_HDP1F | F23: =VLOOKUP("U3."&C23,'PIN REPORT'!$A:$G,7,0) -> J1401_HDP1F | G23: =VLOOKUP("U5."&C23,'PIN REPORT'!$A:$G,7,0) -> J1304_HDP1F | H23: =VLOOKUP("U7."&C23,'PIN REPORT'!$A:$G,7,0) -> J1104_HDP1F
C24: A24 | D24: VCC | E24: =VLOOKUP("U1."&C24,'PIN REPORT'!$A:$G,7,0) -> J1205_HDP1F | F24: =VLOOKUP("U3."&C24,'PIN REPORT'!$A:$G,7,0) -> J1401_HDP1F | G24: =VLOOKUP("U5."&C24,'PIN REPORT'!$A:$G,7,0) -> J1304_HDP1F | H24: =VLOOKUP("U7."&C24,'PIN REPORT'!$A:$G,7,0) -> J1104_HDP1F
C25: A27 | D25: VCC | E25: =VLOOKUP("U1."&C25,'PIN REPORT'!$A:$G,7,0) -> J1205_HDP1F | F25: =VLOOKUP("U3."&C25,'PIN REPORT'!$A:$G,7,0) -> J1401_HDP1F | G25: =VLOOKUP("U5."&C25,'PIN REPORT'!$A:$G,7,0) -> J1304_HDP1F | H25: =VLOOKUP("U7."&C25,'PIN REPORT'!$A:$G,7,0) -> J1104_HDP1F
C26: A28 | D26: VCC | E26: =VLOOKUP("U1."&C26,'PIN REPORT'!$A:$G,7,0) -> J1205_HDP1F | F26: =VLOOKUP("U3."&C26,'PIN REPORT'!$A:$G,7,0) -> J1401_HDP1F | G26: =VLOOKUP("U5."&C26,'PIN REPORT'!$A:$G,7,0) -> J1304_HDP1F | H26: =VLOOKUP("U7."&C26,'PIN REPORT'!$A:$G,7,0) -> J1104_HDP1F
C27: B11 | D27: VCC | E27: =VLOOKUP("U1."&C27,'PIN REPORT'!$A:$G,7,0) -> J1205_HDP1F | F27: =VLOOKUP("U3."&C27,'PIN REPORT'!$A:$G,7,0) -> J1401_HDP1F | G27: =VLOOKUP("U5."&C27,'PIN REPORT'!$A:$G,7,0) -> J1304_HDP1F | H27: =VLOOKUP("U7."&C27,'PIN REPORT'!$A:$G,7,0) -> J1104_HDP1F
C28: B12 | D28: VCC | E28: =VLOOKUP("U1."&C28,'PIN REPORT'!$A:$G,7,0) -> J1205_HDP1F | F28: =VLOOKUP("U3."&C28,'PIN REPORT'!$A:$G,7,0) -> J1401_HDP1F | G28: =VLOOKUP("U5."&C28,'PIN REPORT'!$A:$G,7,0) -> J1304_HDP1F | H28: =VLOOKUP("U7."&C28,'PIN REPORT'!$A:$G,7,0) -> J1104_HDP1F
C29: B15 | D29: VCC | E29: =VLOOKUP("U1."&C29,'PIN REPORT'!$A:$G,7,0) -> J1205_HDP1F | F29: =VLOOKUP("U3."&C29,'PIN REPORT'!$A:$G,7,0) -> J1401_HDP1F | G29: =VLOOKUP("U5."&C29,'PIN REPORT'!$A:$G,7,0) -> J1304_HDP1F | H29: =VLOOKUP("U7."&C29,'PIN REPORT'!$A:$G,7,0) -> J1104_HDP1F
C30: B16 | D30: VCC | E30: =VLOOKUP("U1."&C30,'PIN REPORT'!$A:$G,7,0) -> J1205_HDP1F | F30: =VLOOKUP("U3."&C30,'PIN REPORT'!$A:$G,7,0) -> J1401_HDP1F | G30: =VLOOKUP("U5."&C30,'PIN REPORT'!$A:$G,7,0) -> J1304_HDP1F | H30: =VLOOKUP("U7."&C30,'PIN REPORT'!$A:$G,7,0) -> J1104_HDP1F
... C216: AC38 | D216: VCCHVIO3_HV | E216: =VLOOKUP("U1."&C216,'PIN REPORT'!$A:$G,7,0) -> J1209_LDP1F | F216: =VLOOKUP("U3."&C216,'PIN REPORT'!$A:$G,7,0) -> J1405_LDP4F | G216: =VLOOKUP("U5."&C216,'PIN REPORT'!$A:$G,7,0) -> J1407_LDP4F | H216: =VLOOKUP("U7."&C216,'PIN REPORT'!$A:$G,7,0) -> J1106_LDP3F

Sheet GROUND
D2: SITE-1 | E2: SITE-3 | F2: SITE-5 | G2: SITE-7
B4: CUSTOMER PINLIST | D4: R&D-ALTANOVA ASSIGNMENT | E4: R&D-ALTANOVA ASSIGNMENT | F4: R&D-ALTANOVA ASSIGNMENT | G4: R&D-ALTANOVA ASSIGNMENT
B6: Ball Location | C6: Ball Name
B7: F38 | C7: XSBOXANA[0] | D7: =VLOOKUP("U1."&B7,'PIN REPORT'!$A:$G,7,0) -> DGND | E7: =VLOOKUP("U3."&B7,'PIN REPORT'!$A:$G,7,0) -> DGND | F7: =VLOOKUP("U5."&B7,'PIN REPORT'!$A:$G,7,0) -> DGND | G7: =VLOOKUP("U7."&B7,'PIN REPORT'!$A:$G,7,0) -> DGND
B8: A13 | C8: VSS | D8: =VLOOKUP("U1."&B8,'PIN REPORT'!$A:$G,7,0) -> DGND | E8: =VLOOKUP("U3."&B8,'PIN REPORT'!$A:$G,7,0) -> DGND | F8: =VLOOKUP("U5."&B8,'PIN REPORT'!$A:$G,7,0) -> DGND | G8: =VLOOKUP("U7."&B8,'PIN REPORT'!$A:$G,7,0) -> DGND
B9: A14 | C9: VSS | D9: =VLOOKUP("U1."&B9,'PIN REPORT'!$A:$G,7,0) -> DGND | E9: =VLOOKUP("U3."&B9,'PIN REPORT'!$A:$G,7,0) -> DGND | F9: =VLOOKUP("U5."&B9,'PIN REPORT'!$A:$G,7,0) -> DGND | G9: =VLOOKUP("U7."&B9,'PIN REPORT'!$A:$G,7,0) -> DGND
B10: A17 | C10: VSS | D10: =VLOOKUP("U1."&B10,'PIN REPORT'!$A:$G,7,0) -> DGND | E10: =VLOOKUP("U3."&B10,'PIN REPORT'!$A:$G,7,0) -> DGND | F10: =VLOOKUP("U5."&B10,'PIN REPORT'!$A:$G,7,0) -> DGND | G10: =VLOOKUP("U7."&B10,'PIN REPORT'!$A:$G,7,0) -> DGND
B11: A18 | C11: VSS | D11: =VLOOKUP("U1."&B11,'PIN REPORT'!$A:$G,7,0) -> DGND | E11: =VLOOKUP("U3."&B11,'PIN REPORT'!$A:$G,7,0) -> DGND | F11: =VLOOKUP("U5."&B11,'PIN REPORT'!$A:$G,7,0) -> DGND | G11: =VLOOKUP("U7."&B11,'PIN REPORT'!$A:$G,7,0) -> DGND
B12: A25 | C12: VSS | D12: =VLOOKUP("U1."&B12,'PIN REPORT'!$A:$G,7,0) -> DGND | E12: =VLOOKUP("U3."&B12,'PIN REPORT'!$A:$G,7,0) -> DGND | F12: =VLOOKUP("U5."&B12,'PIN REPORT'!$A:$G,7,0) -> DGND | G12: =VLOOKUP("U7."&B12,'PIN REPORT'!$A:$G,7,0) -> DGND
B13: A26 | C13: VSS | D13: =VLOOKUP("U1."&B13,'PIN REPORT'!$A:$G,7,0) -> DGND | E13: =VLOOKUP("U3."&B13,'PIN REPORT'!$A:$G,7,0) -> DGND | F13: =VLOOKUP("U5."&B13,'PIN REPORT'!$A:$G,7,0) -> DGND | G13: =VLOOKUP("U7."&B13,'PIN REPORT'!$A:$G,7,0) -> DGND
B14: A29 | C14: VSS | D14: =VLOOKUP("U1."&B14,'PIN REPORT'!$A:$G,7,0) -> DGND | E14: =VLOOKUP("U3."&B14,'PIN REPORT'!$A:$G,7,0) -> DGND | F14: =VLOOKUP("U5."&B14,'PIN REPORT'!$A:$G,7,0) -> DGND | G14: =VLOOKUP("U7."&B14,'PIN REPORT'!$A:$G,7,0) -> DGND
B15: A35 | C15: VSS | D15: =VLOOKUP("U1."&B15,'PIN REPORT'!$A:$G,7,0) -> DGND | E15: =VLOOKUP("U3."&B15,'PIN REPORT'!$A:$G,7,0) -> DGND | F15: =VLOOKUP("U5."&B15,'PIN REPORT'!$A:$G,7,0) -> DGND | G15: =VLOOKUP("U7."&B15,'PIN REPORT'!$A:$G,7,0) -> DGND
B16: A36 | C16: VSS | D16: =VLOOKUP("U1."&B16,'PIN REPORT'!$A:$G,7,0) -> DGND | E16: =VLOOKUP("U3."&B16,'PIN REPORT'!$A:$G,7,0) -> DGND | F16: =VLOOKUP("U5."&B16,'PIN REPORT'!$A:$G,7,0) -> DGND | G16: =VLOOKUP("U7."&B16,'PIN REPORT'!$A:$G,7,0) -> DGND
B17: A38 | C17: VSS | D17: =VLOOKUP("U1."&B17,'PIN REPORT'!$A:$G,7,0) -> DGND | E17: =VLOOKUP("U3."&B17,'PIN REPORT'!$A:$G,7,0) -> DGND | F17: =VLOOKUP("U5."&B17,'PIN REPORT'!$A:$G,7,0) -> DGND | G17: =VLOOKUP("U7."&B17,'PIN REPORT'!$A:$G,7,0) -> DGND
B18: A4 | C18: VSS | D18: =VLOOKUP("U1."&B18,'PIN REPORT'!$A:$G,7,0) -> DGND | E18: =VLOOKUP("U3."&B18,'PIN REPORT'!$A:$G,7,0) -> DGND | F18: =VLOOKUP("U5."&B18,'PIN REPORT'!$A:$G,7,0) -> DGND | G18: =VLOOKUP("U7."&B18,'PIN REPORT'!$A:$G,7,0) -> DGND
... B440: P34 | C440: XPSDFITS[9] | D440: =VLOOKUP("U1."&B440,'PIN REPORT'!$A:$G,7,0) -> DGND | E440: =VLOOKUP("U3."&B440,'PIN REPORT'!$A:$G,7,0) -> DGND | F440: =VLOOKUP("U5."&B440,'PIN REPORT'!$A:$G,7,0) -> DGND | G440: =VLOOKUP("U7."&B440,'PIN REPORT'!$A:$G,7,0) -> DGND

Sheet TRIGGER
D4: Site-1 | E4: 800 MDM | F4: DPS150 | G4: LCDPS | H4: PATCH PANEL
E5: J1607_PMDTRG0 | F5: J1206_HIMTRG
E6: J1604_PMDTRG0 | F6: J1207_HVBMP3
E7: J1601_PMDTRG0 | F7: J1208_LIMTRG | G7: J1209_LIMTRG
E9: J1607_PMDTRG1 | F9: J1205_HVBMP0
E10: J1604_PMDTRG1 | F10: J1207_HVBMP4
E11: J1601_PMDTRG1 | F11: J1208_LVBMP0 | G11: J1209_LVBMP0
E13: J1607_PMDTRG2 | F13: J1205_HVBMP1
E14: J1604_PMDTRG2 | F14: J1207_HVBMP5
E15: J1601_PMDTRG2 | F15: J1208_LVBMP1 | G15: J1209_LVBMP1
E17: J1607_PMDTRG3 | F17: J1207_HVBMP2
E18: J1604_PMDTRG3 | H18: J1713.AS16
D21: Site-3 | E21: 800 MDM | F21: DPS150 | G21: LCDPS | H21: PATCH PANEL
E22: J1801_PMDTRG0 | F22: J1402_HIMTRG
E23: J1804_PMDTRG0 | F23: J1403_HVBMP3
E24: J1807_PMDTRG0 | F24: J1404_LIMTRG | G24: J1405_LIMTRG
E26: J1801_PMDTRG1 | F26: J1401_HVBMP0
E27: J1804_PMDTRG1 | F27: J1403_HVBMP4
E28: J1807_PMDTRG1 | F28: J1404_LVBMP0 | G28: J1405_LVBMP0
E30: J1801_PMDTRG2 | F30: J1401_HVBMP1
E31: J1804_PMDTRG2 | F31: J1403_HVBMP5
E32: J1807_PMDTRG2 | F32: J1404_LVBMP1 | G32: J1405_LVBMP1
E34: J1801_PMDTRG3 | F34: J1403_HVBMP2
E35: J1804_PMDTRG3 | H35: J1713.BS16
D38: Site-5 | E38: 800 MDM | F38: DPS150 | G38: LCDPS | H38: PATCH PANEL
E39: J1703_PMDTRG0 | F39: J1303_HIMTRG
E40: J1706_PMDTRG0 | F40: J1302_HVBMP3
E41: J1709_PMDTRG0 | F41: J1301_LIMTRG | G41: J1407_LIMTRG
E43: J1703_PMDTRG1 | F43: J1304_HVBMP0
E44: J1706_PMDTRG1 | F44: J1302_HVBMP4
E45: J1709_PMDTRG1 | F45: J1301_LVBMP0 | G45: J1407_LVBMP0
E47: J1703_PMDTRG2 | F47: J1304_HVBMP1
E48: J1706_PMDTRG2 | F48: J1302_HVBMP5
E49: J1709_PMDTRG2 | F49: J1301_LVBMP1 | G49: J1407_LVBMP1
E51: J1703_PMDTRG3 | F51: J1302_HVBMP2
E52: J1706_PMDTRG3 | H52: J1713.CS16
D55: Site-7 | E55: 800 MDM | F55: DPS150 | G55: LCDPS | H55: PATCH PANEL
E56: J1509_PMDTRG0 | F56: J1103_HIMTRG
E57: J1506_PMDTRG0 | F57: J1102_HVBMP3
E58: J1503_PMDTRG0 | F58: J1101_LIMTRG | G58: J1106_LIMTRG
...

Sheet UTILITY
D5: SITE-1 | E5: SITE-3 | F5: SITE-5 | G5: SITE-7
C6: UTILITY BIT AT RELAY (K20)FOR SPECIAL POWER | D6: J1212_XCW00 | E6: J1112_XCW00 | F6: J1312_XCW00 | G6: J1412_XCW00
C7: UTILITY BIT AT RELAY (K17) FOR DRIVER CIRCUIT | D7: J1212_XCW01 | E7: J1112_XCW01 | F7: J1312_XCW01 | G7: J1412_XCW01
C8: UTILITY BIT AT RELAY (K18) FOR DRIVER CIRCUIT | D8: J1212_XCW02 | E8: J1112_XCW02 | F8: J1312_XCW02 | G8: J1412_XCW02
C9: PCI_CRTL_MAIN | D9: U1_PCI_CTRL_MAIN | E9: U3_PCI_CTRL_MAIN | F9: U5_PCI_CTRL_MAIN | G9: U7_PCI_CTRL_MAIN
C10: PCI_CRTL_SEC | D10: U1_PCI_CTRL_SEC | E10: U3_PCI_CTRL_SEC | F10: U5_PCI_CTRL_SEC | G10: U7_PCI_CTRL_SEC

Sheet TCI
D2: SITE-1
D3: CUSTOMER PINLIST | F3: R&D-ALTANOVA ASSIGNMENT
D5: Ball Location | E5: Ball Name | F5: NETNAME | G5: TCI PINS
D6: J32 | E6: XRTDA | F6: ="U1_"&E6 -> U1_XRTDA | G6: =VLOOKUP("U1."&D6,'PIN REPORT'!$A:$G,7,0) -> J1313_R1TD2I+ | H6: J1313_R1TD2V+
D7: J31 | E7: XRTDB | F7: ="U1_"&E7 -> U1_XRTDB | G7: =VLOOKUP("U1."&D7,'PIN REPORT'!$A:$G,7,0) -> J1313_R1TD2I- | H7: J1313_R1TD2V-
D8: K36 | E8: XTHERMDA | F8: ="U1_"&E8 -> U1_XTHERMDA | G8: =VLOOKUP("U1."&D8,'PIN REPORT'!$A:$G,7,0) -> J1313_R1TD1I+ | H8: J1313_R1TD1V+
D9: J40 | E9: XTHERMDC | F9: ="U1_"&E9 -> U1_XTHERMDC | G9: =VLOOKUP("U1."&D9,'PIN REPORT'!$A:$G,7,0) -> J1313_R1TD1I- | H9: J1313_R1TD1V-
D11: SITE-3
D12: CUSTOMER PINLIST | F12: R&D-ALTANOVA ASSIGNMENT
D14: Ball Location | E14: Ball Name | F14: NETNAME | G14: TCI PINS
D15: J32 | E15: XRTDA | F15: ="U3_"&E15 -> U3_XRTDA | G15: =VLOOKUP("U3."&D15,'PIN REPORT'!$A:$G,7,0) -> J1413_R1TD2I+ | H15: J1413_R1TD2V+
D16: J31 | E16: XRTDB | F16: ="U3_"&E16 -> U3_XRTDB | G16: =VLOOKUP("U3."&D16,'PIN REPORT'!$A:$G,7,0) -> J1413_R1TD2I- | H16: J1413_R1TD2V-
D17: K36 | E17: XTHERMDA | F17: ="U3_"&E17 -> U3_XTHERMDA | G17: =VLOOKUP("U3."&D17,'PIN REPORT'!$A:$G,7,0) -> J1413_R1TD1I+ | H17: J1413_R1TD1V+
D18: J40 | E18: XTHERMDC | F18: ="U3_"&E18 -> U3_XTHERMDC | G18: =VLOOKUP("U3."&D18,'PIN REPORT'!$A:$G,7,0) -> J1413_R1TD1I- | H18: J1413_R1TD1V-
D21: SITE-5
D22: CUSTOMER PINLIST | F22: R&D-ALTANOVA ASSIGNMENT
D24: Ball Location | E24: Ball Name | F24: NETNAME | G24: TCI PINS
D25: J32 | E25: XRTDA | F25: ="U5_"&E25 -> U5_XRTDA | G25: =VLOOKUP("U5."&D25,'PIN REPORT'!$A:$G,7,0) -> J1313_R2TD2I+ | H25: J1313_R2TD2V+
D26: J31 | E26: XRTDB | F26: ="U5_"&E26 -> U5_XRTDB | G26: =VLOOKUP("U5."&D26,'PIN REPORT'!$A:$G,7,0) -> J1313_R2TD2I- | H26: J1313_R2TD2V-
D27: K36 | E27: XTHERMDA | F27: ="U5_"&E27 -> U5_XTHERMDA | G27: =VLOOKUP("U5."&D27,'PIN REPORT'!$A:$G,7,0) -> J1313_R2TD1I+ | H27: J1313_R2TD1V+
D28: J40 | E28: XTHERMDC | F28: ="U5_"&E28 -> U5_XTHERMDC | G28: =VLOOKUP("U5."&D28,'PIN REPORT'!$A:$G,7,0) -> J1313_R2TD1I- | H28: J1313_R2TD1V-
D31: SITE-7
D32: CUSTOMER PINLIST | F32: R&D-ALTANOVA ASSIGNMENT
D34: Ball Location | E34: Ball Name | F34: NETNAME | G34: TCI PINS
D35: J32 | E35: XRTDA | F35: ="U7_"&E35 -> U7_XRTDA | G35: =VLOOKUP("U7."&D35,'PIN REPORT'!$A:$G,7,0) -> J1413_R2TD2I+ | H35: J1413_R2TD2V+
D36: J31 | E36: XRTDB | F36: ="U7_"&E36 -> U7_XRTDB | G36: =VLOOKUP("U7."&D36,'PIN REPORT'!$A:$G,7,0) -> J1413_R2TD2I- | H36: J1413_R2TD2V-
D37: K36 | E37: XTHERMDA | F37: ="U7_"&E37 -> U7_XTHERMDA | G37: =VLOOKUP("U7."&D37,'PIN REPORT'!$A:$G,7,0) -> J1413_R2TD1I+ | H37: J1413_R2TD1V+
D38: J40 | E38: XTHERMDC | F38: ="U7_"&E38 -> U7_XTHERMDC | G38: =VLOOKUP("U7."&D38,'PIN REPORT'!$A:$G,7,0) -> J1413_R2TD1I- | H38: J1413_R2TD1V-

Sheet SENSE PINS FOR HC SUPPLIES
F12: SITE-1 | G12: SITE-3 | H12: SITE-5 | I12: SITE-7
F14: R&D-ALTANOVA ASSIGNMENT | G14: R&D-ALTANOVA ASSIGNMENT | H14: R&D-ALTANOVA ASSIGNMENT | I14: R&D-ALTANOVA ASSIGNMENT
D16: Ball Location | E16: Ball Name
D17: L11 | E17: VCC_SENSE1 | F17: =VLOOKUP("U1."&D17,'PIN REPORT'!$A:$G,7,0) -> J1205_HDP1S | G17: =VLOOKUP("U3."&D17,'PIN REPORT'!$A:$G,7,0) -> J1401_HDP1S | H17: =VLOOKUP("U5."&D17,'PIN REPORT'!$A:$G,7,0) -> J1304_HDP1S | I17: =VLOOKUP("U7."&D17,'PIN REPORT'!$A:$G,7,0) -> J1104_HDP1S
D18: L24 | E18: VCC_SENSE2 | F18: =VLOOKUP("U1."&D18,'PIN REPORT'!$A:$G,7,0) -> J1205_HDP1S | G18: =VLOOKUP("U3."&D18,'PIN REPORT'!$A:$G,7,0) -> J1401_HDP1S | H18: =VLOOKUP("U5."&D18,'PIN REPORT'!$A:$G,7,0) -> J1304_HDP1S | I18: =VLOOKUP("U7."&D18,'PIN REPORT'!$A:$G,7,0) -> J1104_HDP1S
D19: AJ19 | E19: VCCG_SENSE1 | F19: =VLOOKUP("U1."&D19,'PIN REPORT'!$A:$G,7,0) -> J1208_HDP7S | G19: =VLOOKUP("U3."&D19,'PIN REPORT'!$A:$G,7,0) -> J1404_HDP7S | H19: =VLOOKUP("U5."&D19,'PIN REPORT'!$A:$G,7,0) -> J1301_HDP7S | I19: =VLOOKUP("U7."&D19,'PIN REPORT'!$A:$G,7,0) -> J1101_HDP7S
D20: AP7 | E20: VCCG_SENSE2 | F20: =VLOOKUP("U1."&D20,'PIN REPORT'!$A:$G,7,0) -> J1208_HDP7S | G20: =VLOOKUP("U3."&D20,'PIN REPORT'!$A:$G,7,0) -> J1404_HDP7S | H20: =VLOOKUP("U5."&D20,'PIN REPORT'!$A:$G,7,0) -> J1301_HDP7S | I20: =VLOOKUP("U7."&D20,'PIN REPORT'!$A:$G,7,0) -> J1101_HDP7S

Sheet MONITOR ASSIGNEMT
C3: HVMONI/HIMONI
C5: SITE-1 | D5: SITE-3 | E5: SITE-5 | F5: SITE-7
B6: HVMONI | C6: J1205_HVMONI | D6: J1401_HVMONI | E6: J1304_HVMONI | F6: J1104_HVMONI
B7: HIMONI | C7: J1205_HIMONI | D7: J1401_HIMONI | E7: J1304_HIMONI | F7: J1104_HIMONI
B11: 800 MDM ASSIGNMENT ON PATCH PANEL (J1713)
B13: SITE-1 | D13: SITE-3 | F13: SITE-5 | H13: SITE-7
B14: PATCH PANEL PIN NUMBER | C14: 800 MDM ASSIGNMENT | D14: PATCH PANEL PIN NUMBER | E14: 800 MDM ASSIGNMENT | F14: PATCH PANEL PIN NUMBER | G14: 800 MDM ASSIGNMENT | H14: PATCH PANEL PIN NUMBER | I14: 800 MDM ASSIGNMENT
B15: J1713.AS15 | C15: J1601_PIN30 | D15: J1713.BS15 | E15: J1803_PIN94 | F15: J1713.CS15 | G15: J1709_PIN40 | H15: J1713.DS14 | I15: J1508_PIN73

Sheet PIN REPORT
B1: Design Name D:/AWAIS.KHAN_JOBS/Intel-4651/November/21-Nov/INTEL-4651-X74B SRAMCOLL-BRD-64.brd
B2: Date Fri Nov 21 17:54:30 2014
B3: Component Pin Report
B4: REFDES | C4: PIN_NUMBER | D4: COMP_DEVICE_TYPE | E4: PIN_TYPE | F4: PIN_NAME | G4: NET_NAME
A5: =B5&"."&C5 -> A1.1 | B5: A1 | C5: 1 | D5: INTEL680_STIFFENER_INTEL680_STI | E5: BI | F5: 1 | G5: CHASSIS_GND
A6: =B6&"."&C6 -> C1.1 | B6: C1 | C6: 1 | D6: 03000E-22_03000E-22_0.1UF | E6: UNSPEC | F6: 1 | G6: DGND
A7: =B7&"."&C7 -> C1.2 | B7: C1 | C7: 2 | D7: 03000E-22_03000E-22_0.1UF | E7: UNSPEC | F7: 2 | G7: N15582677
A8: =B8&"."&C8 -> C3.1 | B8: C3 | C8: 1 | D8: 03000E-22_03000E-22_0.1UF | E8: UNSPEC | F8: 1 | G8: DGND
A9: =B9&"."&C9 -> C3.2 | B9: C3 | C9: 2 | D9: 03000E-22_03000E-22_0.1UF | E9: UNSPEC | F9: 2 | G9: N15643198
A10: =B10&"."&C10 -> C5.1 | B10: C5 | C10: 1 | D10: 03000E-22_03000E-22_0.1UF | E10: UNSPEC | F10: 1 | G10: DGND
A11: =B11&"."&C11 -> C5.2 | B11: C5 | C11: 2 | D11: 03000E-22_03000E-22_0.1UF | E11: UNSPEC | F11: 2 | G11: N15643877
A12: =B12&"."&C12 -> C7.1 | B12: C7 | C12: 1 | D12: 03000E-22_03000E-22_0.1UF | E12: UNSPEC | F12: 1 | G12: DGND
A13: =B13&"."&C13 -> C7.2 | B13: C7 | C13: 2 | D13: 03000E-22_03000E-22_0.1UF | E13: UNSPEC | F13: 2 | G13: N15644566
A14: =B14&"."&C14 -> D1.A | B14: D1 | C14: A | D14: 08118A_08118A_{VALUE} | E14: UNSPEC | F14: ANODE | G14: J1113_UP5V
A15: =B15&"."&C15 -> D1.K | B15: D1 | C15: K | D15: 08118A_08118A_{VALUE} | E15: UNSPEC | F15: CATHODE | G15: N15582677
A16: =B16&"."&C16 -> D2.A | B16: D2 | C16: A | D16: 08118A_08118A_{VALUE} | E16: UNSPEC | F16: ANODE | G16: N25050915
A17: =B17&"."&C17 -> D2.K | B17: D2 | C17: K | D17: 08118A_08118A_{VALUE} | E17: UNSPEC | F17: CATHODE | G17: N15582677
A18: =B18&"."&C18 -> D3.A | B18: D3 | C18: A | D18: 08118A_08118A_{VALUE} | E18: UNSPEC | F18: ANODE | G18: J1113_UP5V
A19: =B19&"."&C19 -> D3.K | B19: D3 | C19: K | D19: 08118A_08118A_{VALUE} | E19: UNSPEC | F19: CATHODE | G19: N15643198
A20: =B20&"."&C20 -> D4.A | B20: D4 | C20: A | D20: 08118A_08118A_{VALUE} | E20: UNSPEC | F20: ANODE | G20: N25051289
A21: =B21&"."&C21 -> D4.K | B21: D4 | C21: K | D21: 08118A_08118A_{VALUE} | E21: UNSPEC | F21: CATHODE | G21: N15643198
A22: =B22&"."&C22 -> D5.A | B22: D5 | C22: A | D22: 08118A_08118A_{VALUE} | E22: UNSPEC | F22: ANODE | G22: J1113_UP5V
A23: =B23&"."&C23 -> D5.K | B23: D5 | C23: K | D23: 08118A_08118A_{VALUE} | E23: UNSPEC | F23: CATHODE | G23: N15643877
A24: =B24&"."&C24 -> D6.A | B24: D6 | C24: A | D24: 08118A_08118A_{VALUE} | E24: UNSPEC | F24: ANODE | G24: N25051156
A25: =B25&"."&C25 -> D6.K | B25: D6 | C25: K | D25: 08118A_08118A_{VALUE} | E25: UNSPEC | F25: CATHODE | G25: N15643877
... A29: =B29&"."&C29 -> D8.K | B29: D8 | C29: K | D29: 08118A_08118A_{VALUE} | E29: UNSPEC | F29: CATHODE | G29: N15644566
A30: =B30&"."&C30 -> E1.1 | B30: E1 | C30: 1 | D30: 05333A_05333A_{VALUE} | E30: UNSPEC | F30: A0 | G30: N15582641
A31: =B31&"."&C31 -> E1.2 | B31: E1 | C31: 2 | D31: 05333A_05333A_{VALUE} | E31: UNSPEC | F31: A1
A32: =B32&"."&C32 -> E1.3 | B32: E1 | C32: 3 | D32: 05333A_05333A_{VALUE} | E32: UNSPEC | F32: A2
A33: =B33&"."&C33 -> E1.4 | B33: E1 | C33: 4 | D33: 05333A_05333A_{VALUE} | E33: UNSPEC | F33: VSS | G33: DGND
A34: =B34&"."&C34 -> E1.5 | B34: E1 | C34: 5 | D34: 05333A_05333A_{VALUE} | E34: UNSPEC | F34: SDA | G34: J1212_CSDA
A35: =B35&"."&C35 -> E1.6 | B35: E1 | C35: 6 | D35: 05333A_05333A_{VALUE} | E35: UNSPEC | F35: SCL | G35: J1212_CSCL
A36: =B36&"."&C36 -> E1.7 | B36: E1 | C36: 7 | D36: 05333A_05333A_{VALUE} | E36: UNSPEC | F36: WP
A37: =B37&"."&C37 -> E1.8 | B37: E1 | C37: 8 | D37: 05333A_05333A_{VALUE} | E37: UNSPEC | F37: VCC | G37: N15582677
A38: =B38&"."&C38 -> E3.1 | B38: E3 | C38: 1 | D38: 05333A_05333A_{VALUE} | E38: UNSPEC | F38: A0 | G38: N15643330
A39: =B39&"."&C39 -> E3.2 | B39: E3 | C39: 2 | D39: 05333A_05333A_{VALUE} | E39: UNSPEC | F39: A1
A40: =B40&"."&C40 -> E3.3 | B40: E3 | C40: 3 | D40: 05333A_05333A_{VALUE} | E40: UNSPEC | F40: A2
A41: =B41&"."&C41 -> E3.4 | B41: E3 | C41: 4 | D41: 05333A_05333A_{VALUE} | E41: UNSPEC | F41: VSS | G41: DGND
A42: =B42&"."&C42 -> E3.5 | B42: E3 | C42: 5 | D42: 05333A_05333A_{VALUE} | E42: UNSPEC | F42: SDA | G42: J1112_CSDA
A43: =B43&"."&C43 -> E3.6 | B43: E3 | C43: 6 | D43: 05333A_05333A_{VALUE} | E43: UNSPEC | F43: SCL | G43: J1112_CSCL
...

Sheet NELIST REPORT
A1: Design Name D:/AWAIS.KHAN_JOBS/Intel-4651/November/OK-555/INTEL-4651-X74B SRAMCOLL-BRD-41.brd
A2: Date Wed Nov 19 15:38:49 2014
A3: Net List Report
A4: Net Name | B4: Net Pins
A5: CHASSIS_GND | B5: A1.1 | C5: RCHASSIS.2
