Workbook
Name Diff_: [1]set_validations_!$A$2:$A$801
Name gang_: [1]set_validations_!$D$2:$D$801
Name Loop_back: [2]set_validations_!$E$2:$E$801
Name Match_: [1]set_validations_!$B$2:$B$801
Name Share_: [1]set_validations_!$C$2:$C$801
Name Time_Domain: [3]set_validations_!$F$2:$F$10

Sheet History
A1: Date | B1: Revision | C1: Author | D1: Changes
A2: 44635 | B2: Rev0 | C2: Kunihiro.Matsuura | D2: First draft.
A3: 44637 | B3: Rev1 | C3: Kunihiro.Matsuura | D3: Changed TDAU TC assignment and routing. (SITE1,SITE3,Thermal TAB)

Sheet Sheet1
A1: A4 | B1: =_xlfn.XLOOKUP(A1,SITE1!$V$4:$V$1034,SITE1!$U$4:$U$1034,"") -> VSS | C1: {=_xlfn.TEXTJOIN(",",TRUE,_xlfn.UNIQUE(TRANSPOSE(_xlfn.MAP(_xlfn.XLOOKUP(A1,SITE1!$C$4:$C$1034,SITE1!$F$4:$O$1034,""),_xlfn.LAMBDA(_xlpm.x,IF(_xlpm.x<>"",TRIM(CLEAN(LEFT(_xlpm.x,FIND(".",_xlpm.x & ".")-1))),""))))))} | D1: 0.001 | E1: 1.3808 | F1: =_xlfn.LET(_xlpm.raw,_xlfn.XLOOKUP(A1,SITE1!$C$4:$C$1034,SITE1!$E$4:$E$1034),_xlpm.cleanRaw,SUBSTITUTE(SUBSTITUTE(_xlpm.raw,"_PIN","."),"PIN","."),_xlpm.mainPart,MID(_xlpm.cleanRaw,2,FIND(".",_xlpm.cleanRaw & ".")-2),_xlpm.subPart,MID(_xlpm.cleanRaw,FIND(".",_xlpm.cleanRaw & ".")+1,99),_xlpm.result,RIGHT(_xlpm.mainPart,LEN(_xlpm.mainPart)-1)& TEXT(_xlpm.subPart,"000"),IF(OR(_xlpm.raw="",_xlpm.raw="-"),"",_xlpm.result)) | G1: =_xlfn.LET(_xlpm.raw,_xlfn.XLOOKUP(A1,SITE3!$C$4:$C$1034,SITE3!$E$4:$E$1034),_xlpm.cleanRaw,SUBSTITUTE(SUBSTITUTE(_xlpm.raw,"_PIN","."),"PIN","."),_xlpm.mainPart,MID(_xlpm.cleanRaw,2,FIND(".",_xlpm.cleanRaw & ".")-2),_xlpm.subPart,MID(_xlpm.cleanRaw,FIND(".",_xlpm.cleanRaw & ".")+1,99),_xlpm.result,RIGHT(_xlpm.mainPart,LEN(_xlpm.mainPart)-1)& TEXT(_xlpm.subPart,"000"),IF(OR(_xlpm.raw="",_xlpm.raw="-"),"",_xlpm.result)) | H1: ="" | I1: ="" | J1: =A1&";"&B1&";"&C1&";"&D1&";"&E1&";"&F1&";"&G1&";"&H1&";"&I1 -> A4;VSS;;0.000999999999999445;1.3808;;;;
A2: A5 | B2: =_xlfn.XLOOKUP(A2,SITE1!$V$4:$V$1034,SITE1!$U$4:$U$1034,"") -> VSS | C2: {=_xlfn.TEXTJOIN(",",TRUE,_xlfn.UNIQUE(TRANSPOSE(_xlfn.MAP(_xlfn.XLOOKUP(A2,SITE1!$C$4:$C$1034,SITE1!$F$4:$O$1034,""),_xlfn.LAMBDA(_xlpm.x,IF(_xlpm.x<>"",TRIM(CLEAN(LEFT(_xlpm.x,FIND(".",_xlpm.x & ".")-1))),""))))))} | D2: 0.001 | E2: 1.8813 | F2: =_xlfn.LET(_xlpm.raw,_xlfn.XLOOKUP(A2,SITE1!$C$4:$C$1034,SITE1!$E$4:$E$1034),_xlpm.cleanRaw,SUBSTITUTE(SUBSTITUTE(_xlpm.raw,"_PIN","."),"PIN","."),_xlpm.mainPart,MID(_xlpm.cleanRaw,2,FIND(".",_xlpm.cleanRaw & ".")-2),_xlpm.subPart,MID(_xlpm.cleanRaw,FIND(".",_xlpm.cleanRaw & ".")+1,99),_xlpm.result,RIGHT(_xlpm.mainPart,LEN(_xlpm.mainPart)-1)& TEXT(_xlpm.subPart,"000"),IF(OR(_xlpm.raw="",_xlpm.raw="-"),"",_xlpm.result)) | G2: =_xlfn.LET(_xlpm.raw,_xlfn.XLOOKUP(A2,SITE3!$C$4:$C$1034,SITE3!$E$4:$E$1034),_xlpm.cleanRaw,SUBSTITUTE(SUBSTITUTE(_xlpm.raw,"_PIN","."),"PIN","."),_xlpm.mainPart,MID(_xlpm.cleanRaw,2,FIND(".",_xlpm.cleanRaw & ".")-2),_xlpm.subPart,MID(_xlpm.cleanRaw,FIND(".",_xlpm.cleanRaw & ".")+1,99),_xlpm.result,RIGHT(_xlpm.mainPart,LEN(_xlpm.mainPart)-1)& TEXT(_xlpm.subPart,"000"),IF(OR(_xlpm.raw="",_xlpm.raw="-"),"",_xlpm.result)) | H2: ="" | I2: ="" | J2: =A2&";"&B2&";"&C2&";"&D2&";"&E2&";"&F2&";"&G2&";"&H2&";"&I2 -> A5;VSS;;0.000999999999999445;1.88129999999999;;;;
A3: A7 | B3: =_xlfn.XLOOKUP(A3,SITE1!$V$4:$V$1034,SITE1!$U$4:$U$1034,"") -> VSS | C3: {=_xlfn.TEXTJOIN(",",TRUE,_xlfn.UNIQUE(TRANSPOSE(_xlfn.MAP(_xlfn.XLOOKUP(A3,SITE1!$C$4:$C$1034,SITE1!$F$4:$O$1034,""),_xlfn.LAMBDA(_xlpm.x,IF(_xlpm.x<>"",TRIM(CLEAN(LEFT(_xlpm.x,FIND(".",_xlpm.x & ".")-1))),""))))))} | D3: 0.001 | E3: 2.9476 | F3: =_xlfn.LET(_xlpm.raw,_xlfn.XLOOKUP(A3,SITE1!$C$4:$C$1034,SITE1!$E$4:$E$1034),_xlpm.cleanRaw,SUBSTITUTE(SUBSTITUTE(_xlpm.raw,"_PIN","."),"PIN","."),_xlpm.mainPart,MID(_xlpm.cleanRaw,2,FIND(".",_xlpm.cleanRaw & ".")-2),_xlpm.subPart,MID(_xlpm.cleanRaw,FIND(".",_xlpm.cleanRaw & ".")+1,99),_xlpm.result,RIGHT(_xlpm.mainPart,LEN(_xlpm.mainPart)-1)& TEXT(_xlpm.subPart,"000"),IF(OR(_xlpm.raw="",_xlpm.raw="-"),"",_xlpm.result)) | G3: =_xlfn.LET(_xlpm.raw,_xlfn.XLOOKUP(A3,SITE3!$C$4:$C$1034,SITE3!$E$4:$E$1034),_xlpm.cleanRaw,SUBSTITUTE(SUBSTITUTE(_xlpm.raw,"_PIN","."),"PIN","."),_xlpm.mainPart,MID(_xlpm.cleanRaw,2,FIND(".",_xlpm.cleanRaw & ".")-2),_xlpm.subPart,MID(_xlpm.cleanRaw,FIND(".",_xlpm.cleanRaw & ".")+1,99),_xlpm.result,RIGHT(_xlpm.mainPart,LEN(_xlpm.mainPart)-1)& TEXT(_xlpm.subPart,"000"),IF(OR(_xlpm.raw="",_xlpm.raw="-"),"",_xlpm.result)) | H3: ="" | I3: ="" | J3: =A3&";"&B3&";"&C3&";"&D3&";"&E3&";"&F3&";"&G3&";"&H3&";"&I3 -> A7;VSS;;0.000999999999999445;2.94759999999999;;;;
A4: A12 | B4: =_xlfn.XLOOKUP(A4,SITE1!$V$4:$V$1034,SITE1!$U$4:$U$1034,"") -> VSS | C4: {=_xlfn.TEXTJOIN(",",TRUE,_xlfn.UNIQUE(TRANSPOSE(_xlfn.MAP(_xlfn.XLOOKUP(A4,SITE1!$C$4:$C$1034,SITE1!$F$4:$O$1034,""),_xlfn.LAMBDA(_xlpm.x,IF(_xlpm.x<>"",TRIM(CLEAN(LEFT(_xlpm.x,FIND(".",_xlpm.x & ".")-1))),""))))))} | D4: 0.001 | E4: 5.1701 | F4: =_xlfn.LET(_xlpm.raw,_xlfn.XLOOKUP(A4,SITE1!$C$4:$C$1034,SITE1!$E$4:$E$1034),_xlpm.cleanRaw,SUBSTITUTE(SUBSTITUTE(_xlpm.raw,"_PIN","."),"PIN","."),_xlpm.mainPart,MID(_xlpm.cleanRaw,2,FIND(".",_xlpm.cleanRaw & ".")-2),_xlpm.subPart,MID(_xlpm.cleanRaw,FIND(".",_xlpm.cleanRaw & ".")+1,99),_xlpm.result,RIGHT(_xlpm.mainPart,LEN(_xlpm.mainPart)-1)& TEXT(_xlpm.subPart,"000"),IF(OR(_xlpm.raw="",_xlpm.raw="-"),"",_xlpm.result)) | G4: =_xlfn.LET(_xlpm.raw,_xlfn.XLOOKUP(A4,SITE3!$C$4:$C$1034,SITE3!$E$4:$E$1034),_xlpm.cleanRaw,SUBSTITUTE(SUBSTITUTE(_xlpm.raw,"_PIN","."),"PIN","."),_xlpm.mainPart,MID(_xlpm.cleanRaw,2,FIND(".",_xlpm.cleanRaw & ".")-2),_xlpm.subPart,MID(_xlpm.cleanRaw,FIND(".",_xlpm.cleanRaw & ".")+1,99),_xlpm.result,RIGHT(_xlpm.mainPart,LEN(_xlpm.mainPart)-1)& TEXT(_xlpm.subPart,"000"),IF(OR(_xlpm.raw="",_xlpm.raw="-"),"",_xlpm.result)) | H4: ="" | I4: ="" | J4: =A4&";"&B4&";"&C4&";"&D4&";"&E4&";"&F4&";"&G4&";"&H4&";"&I4 -> A12;VSS;;0.000999999999999445;5.1701;;;;
A5: A17 | B5: =_xlfn.XLOOKUP(A5,SITE1!$V$4:$V$1034,SITE1!$U$4:$U$1034,"") -> USB31_1_TXN | C5: {=_xlfn.TEXTJOIN(",",TRUE,_xlfn.UNIQUE(TRANSPOSE(_xlfn.MAP(_xlfn.XLOOKUP(A5,SITE1!$C$4:$C$1034,SITE1!$F$4:$O$1034,""),_xlfn.LAMBDA(_xlpm.x,IF(_xlpm.x<>"",TRIM(CLEAN(LEFT(_xlpm.x,FIND(".",_xlpm.x & ".")-1))),""))))))} -> CA202,LA203 | D5: 0 | E5: 7.7309 | F5: =_xlfn.LET(_xlpm.raw,_xlfn.XLOOKUP(A5,SITE1!$C$4:$C$1034,SITE1!$E$4:$E$1034),_xlpm.cleanRaw,SUBSTITUTE(SUBSTITUTE(_xlpm.raw,"_PIN","."),"PIN","."),_xlpm.mainPart,MID(_xlpm.cleanRaw,2,FIND(".",_xlpm.cleanRaw & ".")-2),_xlpm.subPart,MID(_xlpm.cleanRaw,FIND(".",_xlpm.cleanRaw & ".")+1,99),_xlpm.result,RIGHT(_xlpm.mainPart,LEN(_xlpm.mainPart)-1)& TEXT(_xlpm.subPart,"000"),IF(OR(_xlpm.raw="",_xlpm.raw="-"),"",_xlpm.result)) -> 606090 | G5: =_xlfn.LET(_xlpm.raw,_xlfn.XLOOKUP(A5,SITE3!$C$4:$C$1034,SITE3!$E$4:$E$1034),_xlpm.cleanRaw,SUBSTITUTE(SUBSTITUTE(_xlpm.raw,"_PIN","."),"PIN","."),_xlpm.mainPart,MID(_xlpm.cleanRaw,2,FIND(".",_xlpm.cleanRaw & ".")-2),_xlpm.subPart,MID(_xlpm.cleanRaw,FIND(".",_xlpm.cleanRaw & ".")+1,99),_xlpm.result,RIGHT(_xlpm.mainPart,LEN(_xlpm.mainPart)-1)& TEXT(_xlpm.subPart,"000"),IF(OR(_xlpm.raw="",_xlpm.raw="-"),"",_xlpm.result)) -> 806090 | H5: ="" | I5: ="" | J5: =A5&";"&B5&";"&C5&";"&D5&";"&E5&";"&F5&";"&G5&";"&H5&";"&I5 -> A17;USB31_1_TXN;CA202,LA203;0;7.7309;606090;806090;;
A6: A18 | B6: =_xlfn.XLOOKUP(A6,SITE1!$V$4:$V$1034,SITE1!$U$4:$U$1034,"") -> USB31_1_TXP | C6: {=_xlfn.TEXTJOIN(",",TRUE,_xlfn.UNIQUE(TRANSPOSE(_xlfn.MAP(_xlfn.XLOOKUP(A6,SITE1!$C$4:$C$1034,SITE1!$F$4:$O$1034,""),_xlfn.LAMBDA(_xlpm.x,IF(_xlpm.x<>"",TRIM(CLEAN(LEFT(_xlpm.x,FIND(".",_xlpm.x & ".")-1))),""))))))} -> CA201,LA201 | D6: 0 | E6: 8.2313 | F6: =_xlfn.LET(_xlpm.raw,_xlfn.XLOOKUP(A6,SITE1!$C$4:$C$1034,SITE1!$E$4:$E$1034),_xlpm.cleanRaw,SUBSTITUTE(SUBSTITUTE(_xlpm.raw,"_PIN","."),"PIN","."),_xlpm.mainPart,MID(_xlpm.cleanRaw,2,FIND(".",_xlpm.cleanRaw & ".")-2),_xlpm.subPart,MID(_xlpm.cleanRaw,FIND(".",_xlpm.cleanRaw & ".")+1,99),_xlpm.result,RIGHT(_xlpm.mainPart,LEN(_xlpm.mainPart)-1)& TEXT(_xlpm.subPart,"000"),IF(OR(_xlpm.raw="",_xlpm.raw="-"),"",_xlpm.result)) -> 606092 | G6: =_xlfn.LET(_xlpm.raw,_xlfn.XLOOKUP(A6,SITE3!$C$4:$C$1034,SITE3!$E$4:$E$1034),_xlpm.cleanRaw,SUBSTITUTE(SUBSTITUTE(_xlpm.raw,"_PIN","."),"PIN","."),_xlpm.mainPart,MID(_xlpm.cleanRaw,2,FIND(".",_xlpm.cleanRaw & ".")-2),_xlpm.subPart,MID(_xlpm.cleanRaw,FIND(".",_xlpm.cleanRaw & ".")+1,99),_xlpm.result,RIGHT(_xlpm.mainPart,LEN(_xlpm.mainPart)-1)& TEXT(_xlpm.subPart,"000"),IF(OR(_xlpm.raw="",_xlpm.raw="-"),"",_xlpm.result)) -> 806092 | H6: ="" | I6: ="" | J6: =A6&";"&B6&";"&C6&";"&D6&";"&E6&";"&F6&";"&G6&";"&H6&";"&I6 -> A18;USB31_1_TXP;CA201,LA201;0;8.2313;606092;806092;;
A7: A20 | B7: =_xlfn.XLOOKUP(A7,SITE1!$V$4:$V$1034,SITE1!$U$4:$U$1034,"") -> USB31_3_TXP | C7: {=_xlfn.TEXTJOIN(",",TRUE,_xlfn.UNIQUE(TRANSPOSE(_xlfn.MAP(_xlfn.XLOOKUP(A7,SITE1!$C$4:$C$1034,SITE1!$F$4:$O$1034,""),_xlfn.LAMBDA(_xlpm.x,IF(_xlpm.x<>"",TRIM(CLEAN(LEFT(_xlpm.x,FIND(".",_xlpm.x & ".")-1))),""))))))} -> CA205,LA209 | D7: 0 | E7: 9.0954 | F7: =_xlfn.LET(_xlpm.raw,_xlfn.XLOOKUP(A7,SITE1!$C$4:$C$1034,SITE1!$E$4:$E$1034),_xlpm.cleanRaw,SUBSTITUTE(SUBSTITUTE(_xlpm.raw,"_PIN","."),"PIN","."),_xlpm.mainPart,MID(_xlpm.cleanRaw,2,FIND(".",_xlpm.cleanRaw & ".")-2),_xlpm.subPart,MID(_xlpm.cleanRaw,FIND(".",_xlpm.cleanRaw & ".")+1,99),_xlpm.result,RIGHT(_xlpm.mainPart,LEN(_xlpm.mainPart)-1)& TEXT(_xlpm.subPart,"000"),IF(OR(_xlpm.raw="",_xlpm.raw="-"),"",_xlpm.result)) -> 606125 | G7: =_xlfn.LET(_xlpm.raw,_xlfn.XLOOKUP(A7,SITE3!$C$4:$C$1034,SITE3!$E$4:$E$1034),_xlpm.cleanRaw,SUBSTITUTE(SUBSTITUTE(_xlpm.raw,"_PIN","."),"PIN","."),_xlpm.mainPart,MID(_xlpm.cleanRaw,2,FIND(".",_xlpm.cleanRaw & ".")-2),_xlpm.subPart,MID(_xlpm.cleanRaw,FIND(".",_xlpm.cleanRaw & ".")+1,99),_xlpm.result,RIGHT(_xlpm.mainPart,LEN(_xlpm.mainPart)-1)& TEXT(_xlpm.subPart,"000"),IF(OR(_xlpm.raw="",_xlpm.raw="-"),"",_xlpm.result)) -> 806125 | H7: ="" | I7: ="" | J7: =A7&";"&B7&";"&C7&";"&D7&";"&E7&";"&F7&";"&G7&";"&H7&";"&I7 -> A20;USB31_3_TXP;CA205,LA209;0;9.0954;606125;806125;;
A8: A21 | B8: =_xlfn.XLOOKUP(A8,SITE1!$V$4:$V$1034,SITE1!$U$4:$U$1034,"") -> USB31_3_TXN | C8: {=_xlfn.TEXTJOIN(",",TRUE,_xlfn.UNIQUE(TRANSPOSE(_xlfn.MAP(_xlfn.XLOOKUP(A8,SITE1!$C$4:$C$1034,SITE1!$F$4:$O$1034,""),_xlfn.LAMBDA(_xlpm.x,IF(_xlpm.x<>"",TRIM(CLEAN(LEFT(_xlpm.x,FIND(".",_xlpm.x & ".")-1))),""))))))} -> CA206,LA211 | D8: 0 | E8: 9.5958 | F8: =_xlfn.LET(_xlpm.raw,_xlfn.XLOOKUP(A8,SITE1!$C$4:$C$1034,SITE1!$E$4:$E$1034),_xlpm.cleanRaw,SUBSTITUTE(SUBSTITUTE(_xlpm.raw,"_PIN","."),"PIN","."),_xlpm.mainPart,MID(_xlpm.cleanRaw,2,FIND(".",_xlpm.cleanRaw & ".")-2),_xlpm.subPart,MID(_xlpm.cleanRaw,FIND(".",_xlpm.cleanRaw & ".")+1,99),_xlpm.result,RIGHT(_xlpm.mainPart,LEN(_xlpm.mainPart)-1)& TEXT(_xlpm.subPart,"000"),IF(OR(_xlpm.raw="",_xlpm.raw="-"),"",_xlpm.result)) -> 606123 | G8: =_xlfn.LET(_xlpm.raw,_xlfn.XLOOKUP(A8,SITE3!$C$4:$C$1034,SITE3!$E$4:$E$1034),_xlpm.cleanRaw,SUBSTITUTE(SUBSTITUTE(_xlpm.raw,"_PIN","."),"PIN","."),_xlpm.mainPart,MID(_xlpm.cleanRaw,2,FIND(".",_xlpm.cleanRaw & ".")-2),_xlpm.subPart,MID(_xlpm.cleanRaw,FIND(".",_xlpm.cleanRaw & ".")+1,99),_xlpm.result,RIGHT(_xlpm.mainPart,LEN(_xlpm.mainPart)-1)& TEXT(_xlpm.subPart,"000"),IF(OR(_xlpm.raw="",_xlpm.raw="-"),"",_xlpm.result)) -> 806123 | H8: ="" | I8: ="" | J8: =A8&";"&B8&";"&C8&";"&D8&";"&E8&";"&F8&";"&G8&";"&H8&";"&I8 -> A21;USB31_3_TXN;CA206,LA211;0;9.5958;606123;806123;;
A9: A23 | B9: =_xlfn.XLOOKUP(A9,SITE1!$V$4:$V$1034,SITE1!$U$4:$U$1034,"") -> USB31_5_TXP | C9: {=_xlfn.TEXTJOIN(",",TRUE,_xlfn.UNIQUE(TRANSPOSE(_xlfn.MAP(_xlfn.XLOOKUP(A9,SITE1!$C$4:$C$1034,SITE1!$F$4:$O$1034,""),_xlfn.LAMBDA(_xlpm.x,IF(_xlpm.x<>"",TRIM(CLEAN(LEFT(_xlpm.x,FIND(".",_xlpm.x & ".")-1))),""))))))} -> CA209,LA217 | D9: 0 | E9: 10.4599 | F9: =_xlfn.LET(_xlpm.raw,_xlfn.XLOOKUP(A9,SITE1!$C$4:$C$1034,SITE1!$E$4:$E$1034),_xlpm.cleanRaw,SUBSTITUTE(SUBSTITUTE(_xlpm.raw,"_PIN","."),"PIN","."),_xlpm.mainPart,MID(_xlpm.cleanRaw,2,FIND(".",_xlpm.cleanRaw & ".")-2),_xlpm.subPart,MID(_xlpm.cleanRaw,FIND(".",_xlpm.cleanRaw & ".")+1,99),_xlpm.result,RIGHT(_xlpm.mainPart,LEN(_xlpm.mainPart)-1)& TEXT(_xlpm.subPart,"000"),IF(OR(_xlpm.raw="",_xlpm.raw="-"),"",_xlpm.result)) -> 705072 | G9: =_xlfn.LET(_xlpm.raw,_xlfn.XLOOKUP(A9,SITE3!$C$4:$C$1034,SITE3!$E$4:$E$1034),_xlpm.cleanRaw,SUBSTITUTE(SUBSTITUTE(_xlpm.raw,"_PIN","."),"PIN","."),_xlpm.mainPart,MID(_xlpm.cleanRaw,2,FIND(".",_xlpm.cleanRaw & ".")-2),_xlpm.subPart,MID(_xlpm.cleanRaw,FIND(".",_xlpm.cleanRaw & ".")+1,99),_xlpm.result,RIGHT(_xlpm.mainPart,LEN(_xlpm.mainPart)-1)& TEXT(_xlpm.subPart,"000"),IF(OR(_xlpm.raw="",_xlpm.raw="-"),"",_xlpm.result)) -> 505072 | H9: ="" | I9: ="" | J9: =A9&";"&B9&";"&C9&";"&D9&";"&E9&";"&F9&";"&G9&";"&H9&";"&I9 -> A23;USB31_5_TXP;CA209,LA217;0;10.4599;705072;505072;;
A10: A24 | B10: =_xlfn.XLOOKUP(A10,SITE1!$V$4:$V$1034,SITE1!$U$4:$U$1034,"") -> USB31_5_TXN | C10: {=_xlfn.TEXTJOIN(",",TRUE,_xlfn.UNIQUE(TRANSPOSE(_xlfn.MAP(_xlfn.XLOOKUP(A10,SITE1!$C$4:$C$1034,SITE1!$F$4:$O$1034,""),_xlfn.LAMBDA(_xlpm.x,IF(_xlpm.x<>"",TRIM(CLEAN(LEFT(_xlpm.x,FIND(".",_xlpm.x & ".")-1))),""))))))} -> CA210,LA219 | D10: 0 | E10: 10.9603 | F10: =_xlfn.LET(_xlpm.raw,_xlfn.XLOOKUP(A10,SITE1!$C$4:$C$1034,SITE1!$E$4:$E$1034),_xlpm.cleanRaw,SUBSTITUTE(SUBSTITUTE(_xlpm.raw,"_PIN","."),"PIN","."),_xlpm.mainPart,MID(_xlpm.cleanRaw,2,FIND(".",_xlpm.cleanRaw & ".")-2),_xlpm.subPart,MID(_xlpm.cleanRaw,FIND(".",_xlpm.cleanRaw & ".")+1,99),_xlpm.result,RIGHT(_xlpm.mainPart,LEN(_xlpm.mainPart)-1)& TEXT(_xlpm.subPart,"000"),IF(OR(_xlpm.raw="",_xlpm.raw="-"),"",_xlpm.result)) -> 705070 | G10: =_xlfn.LET(_xlpm.raw,_xlfn.XLOOKUP(A10,SITE3!$C$4:$C$1034,SITE3!$E$4:$E$1034),_xlpm.cleanRaw,SUBSTITUTE(SUBSTITUTE(_xlpm.raw,"_PIN","."),"PIN","."),_xlpm.mainPart,MID(_xlpm.cleanRaw,2,FIND(".",_xlpm.cleanRaw & ".")-2),_xlpm.subPart,MID(_xlpm.cleanRaw,FIND(".",_xlpm.cleanRaw & ".")+1,99),_xlpm.result,RIGHT(_xlpm.mainPart,LEN(_xlpm.mainPart)-1)& TEXT(_xlpm.subPart,"000"),IF(OR(_xlpm.raw="",_xlpm.raw="-"),"",_xlpm.result)) -> 505070 | H10: ="" | I10: ="" | J10: =A10&";"&B10&";"&C10&";"&D10&";"&E10&";"&F10&";"&G10&";"&H10&";"&I10 -> A24;USB31_5_TXN;CA210,LA219;0;10.9603;705070;505070;;
A11: A26 | B11: =_xlfn.XLOOKUP(A11,SITE1!$V$4:$V$1034,SITE1!$U$4:$U$1034,"") -> USB31_7_TXP | C11: {=_xlfn.TEXTJOIN(",",TRUE,_xlfn.UNIQUE(TRANSPOSE(_xlfn.MAP(_xlfn.XLOOKUP(A11,SITE1!$C$4:$C$1034,SITE1!$F$4:$O$1034,""),_xlfn.LAMBDA(_xlpm.x,IF(_xlpm.x<>"",TRIM(CLEAN(LEFT(_xlpm.x,FIND(".",_xlpm.x & ".")-1))),""))))))} -> CA213,LA225 | D11: 0 | E11: 11.8244 | F11: =_xlfn.LET(_xlpm.raw,_xlfn.XLOOKUP(A11,SITE1!$C$4:$C$1034,SITE1!$E$4:$E$1034),_xlpm.cleanRaw,SUBSTITUTE(SUBSTITUTE(_xlpm.raw,"_PIN","."),"PIN","."),_xlpm.mainPart,MID(_xlpm.cleanRaw,2,FIND(".",_xlpm.cleanRaw & ".")-2),_xlpm.subPart,MID(_xlpm.cleanRaw,FIND(".",_xlpm.cleanRaw & ".")+1,99),_xlpm.result,RIGHT(_xlpm.mainPart,LEN(_xlpm.mainPart)-1)& TEXT(_xlpm.subPart,"000"),IF(OR(_xlpm.raw="",_xlpm.raw="-"),"",_xlpm.result)) -> 706034 | G11: =_xlfn.LET(_xlpm.raw,_xlfn.XLOOKUP(A11,SITE3!$C$4:$C$1034,SITE3!$E$4:$E$1034),_xlpm.cleanRaw,SUBSTITUTE(SUBSTITUTE(_xlpm.raw,"_PIN","."),"PIN","."),_xlpm.mainPart,MID(_xlpm.cleanRaw,2,FIND(".",_xlpm.cleanRaw & ".")-2),_xlpm.subPart,MID(_xlpm.cleanRaw,FIND(".",_xlpm.cleanRaw & ".")+1,99),_xlpm.result,RIGHT(_xlpm.mainPart,LEN(_xlpm.mainPart)-1)& TEXT(_xlpm.subPart,"000"),IF(OR(_xlpm.raw="",_xlpm.raw="-"),"",_xlpm.result)) -> 506034 | H11: ="" | I11: ="" | J11: =A11&";"&B11&";"&C11&";"&D11&";"&E11&";"&F11&";"&G11&";"&H11&";"&I11 -> A26;USB31_7_TXP;CA213,LA225;0;11.8244;706034;506034;;
A12: A27 | B12: =_xlfn.XLOOKUP(A12,SITE1!$V$4:$V$1034,SITE1!$U$4:$U$1034,"") -> USB31_7_TXN | C12: {=_xlfn.TEXTJOIN(",",TRUE,_xlfn.UNIQUE(TRANSPOSE(_xlfn.MAP(_xlfn.XLOOKUP(A12,SITE1!$C$4:$C$1034,SITE1!$F$4:$O$1034,""),_xlfn.LAMBDA(_xlpm.x,IF(_xlpm.x<>"",TRIM(CLEAN(LEFT(_xlpm.x,FIND(".",_xlpm.x & ".")-1))),""))))))} -> CA214,LA227 | D12: 0 | E12: 12.3248 | F12: =_xlfn.LET(_xlpm.raw,_xlfn.XLOOKUP(A12,SITE1!$C$4:$C$1034,SITE1!$E$4:$E$1034),_xlpm.cleanRaw,SUBSTITUTE(SUBSTITUTE(_xlpm.raw,"_PIN","."),"PIN","."),_xlpm.mainPart,MID(_xlpm.cleanRaw,2,FIND(".",_xlpm.cleanRaw & ".")-2),_xlpm.subPart,MID(_xlpm.cleanRaw,FIND(".",_xlpm.cleanRaw & ".")+1,99),_xlpm.result,RIGHT(_xlpm.mainPart,LEN(_xlpm.mainPart)-1)& TEXT(_xlpm.subPart,"000"),IF(OR(_xlpm.raw="",_xlpm.raw="-"),"",_xlpm.result)) -> 706036 | G12: =_xlfn.LET(_xlpm.raw,_xlfn.XLOOKUP(A12,SITE3!$C$4:$C$1034,SITE3!$E$4:$E$1034),_xlpm.cleanRaw,SUBSTITUTE(SUBSTITUTE(_xlpm.raw,"_PIN","."),"PIN","."),_xlpm.mainPart,MID(_xlpm.cleanRaw,2,FIND(".",_xlpm.cleanRaw & ".")-2),_xlpm.subPart,MID(_xlpm.cleanRaw,FIND(".",_xlpm.cleanRaw & ".")+1,99),_xlpm.result,RIGHT(_xlpm.mainPart,LEN(_xlpm.mainPart)-1)& TEXT(_xlpm.subPart,"000"),IF(OR(_xlpm.raw="",_xlpm.raw="-"),"",_xlpm.result)) -> 506036 | H12: ="" | I12: ="" | J12: =A12&";"&B12&";"&C12&";"&D12&";"&E12&";"&F12&";"&G12&";"&H12&";"&I12 -> A27;USB31_7_TXN;CA214,LA227;0;12.3248;706036;506036;;
... A1025: BJ54 | B1025: =_xlfn.XLOOKUP(A1025,SITE1!$V$4:$V$1034,SITE1!$U$4:$U$1034,"") -> VCCPRTC_3P3 | C1025: {=_xlfn.TEXTJOIN(",",TRUE,_xlfn.UNIQUE(TRANSPOSE(_xlfn.MAP(_xlfn.XLOOKUP(A1025,SITE1!$C$4:$C$1034,SITE1!$F$4:$O$1034,""),_xlfn.LAMBDA(_xlpm.x,IF(_xlpm.x<>"",TRIM(CLEAN(LEFT(_xlpm.x,FIND(".",_xlpm.x & ".")-1))),""))))))} -> JA4,TPA611 | D1025: 22.379 | E1025: 25.4974 | F1025: =_xlfn.LET(_xlpm.raw,_xlfn.XLOOKUP(A1025,SITE1!$C$4:$C$1034,SITE1!$E$4:$E$1034),_xlpm.cleanRaw,SUBSTITUTE(SUBSTITUTE(_xlpm.raw,"_PIN","."),"PIN","."),_xlpm.mainPart,MID(_xlpm.cleanRaw,2,FIND(".",_xlpm.cleanRaw & ".")-2),_xlpm.subPart,MID(_xlpm.cleanRaw,FIND(".",_xlpm.cleanRaw & ".")+1,99),_xlpm.result,RIGHT(_xlpm.mainPart,LEN(_xlpm.mainPart)-1)& TEXT(_xlpm.subPart,"000"),IF(OR(_xlpm.raw="",_xlpm.raw="-"),"",_xlpm.result)) -> 706038 | G1025: =_xlfn.LET(_xlpm.raw,_xlfn.XLOOKUP(A1025,SITE3!$C$4:$C$1034,SITE3!$E$4:$E$1034),_xlpm.cleanRaw,SUBSTITUTE(SUBSTITUTE(_xlpm.raw,"_PIN","."),"PIN","."),_xlpm.mainPart,MID(_xlpm.cleanRaw,2,FIND(".",_xlpm.cleanRaw & ".")-2),_xlpm.subPart,MID(_xlpm.cleanRaw,FIND(".",_xlpm.cleanRaw & ".")+1,99),_xlpm.result,RIGHT(_xlpm.mainPart,LEN(_xlpm.mainPart)-1)& TEXT(_xlpm.subPart,"000"),IF(OR(_xlpm.raw="",_xlpm.raw="-"),"",_xlpm.result)) -> 506038 | H1025: ="" | I1025: ="" | J1025: =A1025&";"&B1025&";"&C1025&";"&D1025&";"&E1025&";"&F1025&";"&G1025&";"&H1025&";"&I1025 -> BJ54;VCCPRTC_3P3;JA4,TPA611;22.3789999999999;25.4974;706038;506038;;

Sheet SITE1
B1: ITTO-620-0190 Meteor Lake PCH X4 | C1: SITE1 | M1: 44637
B3: Function | C3: Land# | D3: Channel/Tester No | F3: Components | P3: Minor Length | Q3: Major Length | R3: Total Length | S3: Trace Layer | U3: Pin Name | V3: Pin Location | W3: X-Coord | X3: Y-Coord | Y3: Power, GND or IO (Pin Type) | Z3: Top/Bottom Pin | AA3: Interface | AB3: Channel link (CMT DM250 and DM800 only) | AC3: Channel count | AD3: Time Domain | AE3: Min Trace Length (mils) | AF3: Max Trace Length (mils) | AG3: Diff pair number | AH3: Diff phase tolerance (+/- mils) | AI3: Differential impedance (Ohm) | AJ3: Match Group | AK3: Match Group tolerance (+/- mils) | AL3: Share channel (match required) | AM3: Loop back | AN3: RCOMP Groups | AO3: Test point needed | AP3: Signal Speed (MHz) Pins | AQ3: PCB Routing Instruction
A4: 1 | B4: D1_TC_M04_DP01_TD02__CLKOUT_SRC_N_0 | C4: R10 | D4: J1609.DS6 | E4: J1609PIN102 | Q4: 222.806 | R4: =IF(AND(P4="",Q4=""),"",SUM(P4:Q4)) -> 222.806 | S4: L30_HSIO6 | T4: 1 | U4: CLKOUT_SRC_N_0 | V4: R10 | W4: 8983.5 | X4: -4897.1 | Y4: IO | Z4: Bottom | AA4: DM800 | AC4: 1 | AD4: TD02 | AG4: DP01 | AH4: 5 | AI4: 100 | AJ4: M04 | AK4: 5 | AQ4: Differential. Site-to-Site match.
A5: 2 | B5: D1_TC_M04_DP02_TD02__CLKOUT_SRC_N_1 | C5: G3 | D5: J1609.AS3 | E5: J1609PIN114 | Q5: 222.8516 | R5: =IF(AND(P5="",Q5=""),"",SUM(P5:Q5)) -> 222.8516 | S5: L9_INT1 | T5: 2 | U5: CLKOUT_SRC_N_1 | V5: G3 | W5: 12413 | X5: -8492.5 | Y5: IO | Z5: Bottom | AA5: DM800 | AC5: 1 | AD5: TD02 | AG5: DP02 | AH5: 5 | AI5: 100 | AJ5: M04 | AK5: 5 | AQ5: Differential. Site-to-Site match.
A6: 3 | B6: D1_TC_M04_DP03_TD02__CLKOUT_SRC_N_10 | C6: H5 | D6: J1609.CS1 | E6: J1609PIN109 | Q6: 222.7985 | R6: =IF(AND(P6="",Q6=""),"",SUM(P6:Q6)) -> 222.7985 | S6: L11_INT2 | T6: 3 | U6: CLKOUT_SRC_N_10 | V6: H5 | W6: 11455.4 | X6: -8192.8 | Y6: IO | Z6: Bottom | AA6: DM800 | AC6: 1 | AD6: TD02 | AG6: DP03 | AH6: 5 | AI6: 100 | AJ6: M04 | AK6: 5 | AQ6: Differential. Site-to-Site match.
A7: 4 | B7: D1_TC_M04_DP04_TD02__CLKOUT_SRC_N_11 | C7: K6 | D7: J1608.CS2 | E7: J1608PIN063 | Q7: 222.8093 | R7: =IF(AND(P7="",Q7=""),"",SUM(P7:Q7)) -> 222.8093 | S7: L13_INT3 | T7: 4 | U7: CLKOUT_SRC_N_11 | V7: K6 | W7: 10945.9 | X7: -7035.5 | Y7: IO | Z7: Bottom | AA7: DM800 | AC7: 1 | AD7: TD02 | AG7: DP04 | AH7: 5 | AI7: 100 | AJ7: M04 | AK7: 5 | AQ7: Differential. Site-to-Site match.
A8: 5 | B8: D1_TC_M04_DP05_TD02__CLKOUT_SRC_N_12 | C8: N6 | D8: J1607.AS5 | E8: J1607PIN030 | Q8: 222.809 | R8: =IF(AND(P8="",Q8=""),"",SUM(P8:Q8)) -> 222.809 | S8: L11_INT2 | T8: 5 | U8: CLKOUT_SRC_N_12 | V8: N6 | W8: 10945.9 | X8: -5854.3 | Y8: IO | Z8: Bottom | AA8: DM800 | AC8: 1 | AD8: TD02 | AG8: DP05 | AH8: 5 | AI8: 100 | AJ8: M04 | AK8: 5 | AQ8: Differential. Site-to-Site match.
A9: 6 | B9: D1_TC_M04_DP06_TD02__CLKOUT_SRC_N_13 | C9: V10 | D9: J1609.BS2 | E9: J1609PIN111 | Q9: 222.813 | R9: =IF(AND(P9="",Q9=""),"",SUM(P9:Q9)) -> 222.813 | S9: L30_HSIO6 | T9: 6 | U9: CLKOUT_SRC_N_13 | V9: V10 | W9: 8983.5 | X9: -3258.8 | Y9: IO | Z9: Bottom | AA9: DM800 | AC9: 1 | AD9: TD02 | AG9: DP06 | AH9: 5 | AI9: 100 | AJ9: M04 | AK9: 5 | AQ9: Differential. Site-to-Site match.
A10: 7 | B10: D1_TC_M04_DP07_TD02__CLKOUT_SRC_N_2 | C10: J2 | D10: J1608.DS3 | E10: J1608PIN062 | Q10: 222.7924 | R10: =IF(AND(P10="",Q10=""),"",SUM(P10:Q10)) -> 222.7924 | S10: L9_INT1 | T10: 7 | U10: CLKOUT_SRC_N_2 | V10: J2 | W10: 12786.5 | X10: -7784.1 | Y10: IO | Z10: Bottom | AA10: DM800 | AC10: 1 | AD10: TD02 | AG10: DP07 | AH10: 5 | AI10: 100 | AJ10: M04 | AK10: 5 | AQ10: Differential. Site-to-Site match.
A11: 8 | B11: D1_TC_M04_DP08_TD02__CLKOUT_SRC_N_3 | C11: K2 | D11: J1607.DS2 | E11: J1607PIN020 | Q11: 222.7906 | R11: =IF(AND(P11="",Q11=""),"",SUM(P11:Q11)) -> 222.7906 | S11: L11_INT2 | T11: 8 | U11: CLKOUT_SRC_N_3 | V11: K2 | W11: 12702.5 | X11: -7123.4 | Y11: IO | Z11: Bottom | AA11: DM800 | AC11: 1 | AD11: TD02 | AG11: DP08 | AH11: 5 | AI11: 100 | AJ11: M04 | AK11: 5 | AQ11: Differential. Site-to-Site match.
A12: 9 | B12: D1_TC_M04_DP09_TD02__CLKOUT_SRC_N_4 | C12: M3 | D12: J1608.CS4 | E12: J1608PIN059 | Q12: 222.8692 | R12: =IF(AND(P12="",Q12=""),"",SUM(P12:Q12)) -> 222.8692 | S12: L9_INT1 | T12: 9 | U12: CLKOUT_SRC_N_4 | V12: M3 | W12: 12413 | X12: -6295.4 | Y12: IO | Z12: Bottom | AA12: DM800 | AC12: 1 | AD12: TD02 | AG12: DP09 | AH12: 5 | AI12: 100 | AJ12: M04 | AK12: 5 | AQ12: Differential. Site-to-Site match.
A13: 10 | B13: D1_TC_M04_DP10_TD02__CLKOUT_SRC_N_5 | C13: M4 | D13: J1607.DS7 | E13: J1607PIN012 | Q13: 222.8261 | R13: =IF(AND(P13="",Q13=""),"",SUM(P13:Q13)) -> 222.8261 | S13: L13_INT3 | T13: 10 | U13: CLKOUT_SRC_N_5 | V13: M4 | W13: 11912.6 | X13: -6214.1 | Y13: IO | Z13: Bottom | AA13: DM800 | AC13: 1 | AD13: TD02 | AG13: DP10 | AH13: 5 | AI13: 100 | AJ13: M04 | AK13: 5 | AQ13: Differential. Site-to-Site match.
A14: 11 | B14: D1_TC_M04_DP11_TD02__CLKOUT_SRC_N_6 | C14: N3 | D14: J1608.AS3 | E14: J1608PIN070 | Q14: 222.7855 | R14: =IF(AND(P14="",Q14=""),"",SUM(P14:Q14)) -> 222.7855 | S14: L9_INT1 | T14: 11 | U14: CLKOUT_SRC_N_6 | V14: N3 | W14: 12285.7 | X14: -5587 | Y14: IO | Z14: Bottom | AA14: DM800 | AC14: 1 | AD14: TD02 | AG14: DP11 | AH14: 5 | AI14: 100 | AJ14: M04 | AK14: 5 | AQ14: Differential. Site-to-Site match.
A15: 12 | B15: D1_TC_M04_DP12_TD02__CLKOUT_SRC_N_7 | C15: R2 | D15: J1607.CS4 | E15: J1607PIN015 | Q15: 222.8106 | R15: =IF(AND(P15="",Q15=""),"",SUM(P15:Q15)) -> 222.8106 | S15: L11_INT2 | T15: 12 | U15: CLKOUT_SRC_N_7 | V15: R2 | W15: 12702.5 | X15: -4926.3 | Y15: IO | Z15: Bottom | AA15: DM800 | AC15: 1 | AD15: TD02 | AG15: DP12 | AH15: 5 | AI15: 100 | AJ15: M04 | AK15: 5 | AQ15: Differential. Site-to-Site match.
... A33: 30 | B33: D1_TC_M02_DP15_TD02__CLKOUT_XTAL_P | C33: B6 | D33: J1609.DS1 | E33: J1609PIN110 | Q33: 187.7643 | R33: =IF(AND(P33="",Q33=""),"",SUM(P33:Q33)) -> 187.7643 | S33: L9_INT1 | T33: 30 | U33: CLKOUT_XTAL_P | V33: B6 | W33: 11181.6 | X33: -10770.7 | Y33: IO | Z33: Bottom | AA33: DM800 | AC33: 1 | AD33: TD02 | AG33: DP15 | AH33: 5 | AI33: 100 | AJ33: M02 | AK33: 5 | AQ33: Differential. Site-to-Site match.
A34: 31 | B34: D1_TC_M10_DP16_L88_TD01__CNV_WR_CLKN | C34: BB15 | D34: J1602.BS5 | E34: J1602PIN073 | F34: UA121.8 | G34: UA121.18 | P34: 275.3538 | Q34: 29.741 | R34: =IF(AND(P34="",Q34=""),"",SUM(P34:Q34)) -> 305.0948 | S34: L30_HSIO6/L26_HSIO4 | T34: 31 | U34: CNV_WR_CLKN | V34: BB15 | W34: 6454.6 | X34: 8048.1 | Y34: IO | Z34: Bottom | AA34: DM800 | AC34: 1 | AD34: TD01 | AG34: DP16 | AH34: 5 | AI34: 100 | AJ34: M10 | AK34: 20 | AM34: L88 | AP34: 2.56 Gbs | AQ34: Refer to "HSIO" Tab
A35: 32 | B35: D1_TC_M10_DP16_L87_TD01__CNV_WR_CLKP | C35: BC15 | D35: J1602.BS4 | E35: J1602PIN071 | F35: UA121.2 | G35: UA121.24 | P35: 275.3518 | Q35: 29.7481 | R35: =IF(AND(P35="",Q35=""),"",SUM(P35:Q35)) -> 305.0999 | S35: L30_HSIO6/L26_HSIO4 | T35: 32 | U35: CNV_WR_CLKP | V35: BC15 | W35: 6821 | X35: 8695.8 | Y35: IO | Z35: Bottom | AA35: DM800 | AC35: 1 | AD35: TD01 | AG35: DP16 | AH35: 5 | AI35: 100 | AJ35: M10 | AK35: 20 | AM35: L87 | AP35: 2.56 Gbs | AQ35: Refer to "HSIO" Tab
A36: 33 | B36: D1_TC_M10_DP17_L90_TD01__CNV_WR_D0N | C36: AV16 | D36: J1601.BS4 | E36: J1601PIN027 | F36: UA122.8 | G36: UA122.18 | P36: 275.3158 | Q36: 29.8219 | R36: =IF(AND(P36="",Q36=""),"",SUM(P36:Q36)) -> 305.1377 | S36: L30_HSIO6/L26_HSIO4 | T36: 33 | U36: CNV_WR_D0N | V36: AV16 | W36: 5965.9 | X36: 6421.8 | Y36: IO | Z36: Bottom | AA36: DM800 | AC36: 1 | AD36: TD01 | AG36: DP17 | AH36: 5 | AI36: 100 | AJ36: M10 | AK36: 20 | AM36: L90 | AP36: Dphy 2.5G (DC CoupleD - Relays and Relay switches will be added. | AQ36: Refer to "HSIO" Tab
A37: 34 | B37: D1_TC_M10_DP17_L89_TD01__CNV_WR_D0P | C37: BA16 | D37: J1601.BS5 | E37: J1601PIN029 | F37: UA122.2 | G37: UA122.24 | P37: 275.3143 | Q37: 29.8299 | R37: =IF(AND(P37="",Q37=""),"",SUM(P37:Q37)) -> 305.1442 | S37: L30_HSIO6/L26_HSIO4 | T37: 34 | U37: CNV_WR_D0P | V37: BA16 | W37: 6045.6 | X37: 7444.7 | Y37: IO | Z37: Bottom | AA37: DM800 | AC37: 1 | AD37: TD01 | AG37: DP17 | AH37: 5 | AI37: 100 | AJ37: M10 | AK37: 20 | AM37: L89 | AP37: Dphy 2.5G (DC CoupleD - Relays and Relay switches will be added. | AQ37: Refer to "HSIO" Tab
A38: 35 | B38: D1_TC_M10_DP18_L92_TD01__CNV_WR_D1N | C38: BA14 | D38: J1601.DS6 | E38: J1601PIN014 | F38: UA123.8 | G38: UA123.18 | P38: 275.3224 | Q38: 29.6363 | R38: =IF(AND(P38="",Q38=""),"",SUM(P38:Q38)) -> 304.9587 | S38: L30_HSIO6/L22_HSIO2 | T38: 35 | U38: CNV_WR_D1N | V38: BA14 | W38: 7278.6 | X38: 7469.1 | Y38: IO | Z38: Bottom | AA38: DM800 | AC38: 1 | AD38: TD01 | AG38: DP18 | AH38: 5 | AI38: 100 | AJ38: M10 | AK38: 20 | AM38: L92 | AP38: Dphy 2.5G (DC CoupleD - Relays and Relay switches will be added. | AQ38: Refer to "HSIO" Tab
A39: 36 | B39: D1_TC_M10_DP18_L91_TD01__CNV_WR_D1P | C39: BB13 | D39: J1601.DS7 | E39: J1601PIN012 | F39: UA123.2 | G39: UA123.24 | P39: 275.3168 | Q39: 29.5909 | R39: =IF(AND(P39="",Q39=""),"",SUM(P39:Q39)) -> 304.9077 | S39: L30_HSIO6/L22_HSIO2 | T39: 36 | U39: CNV_WR_D1P | V39: BB13 | W39: 7639.2 | X39: 8086.2 | Y39: IO | Z39: Bottom | AA39: DM800 | AC39: 1 | AD39: TD01 | AG39: DP18 | AH39: 5 | AI39: 100 | AJ39: M10 | AK39: 20 | AM39: L91 | AP39: Dphy 2.5G (DC CoupleD - Relays and Relay switches will be added. | AQ39: Refer to "HSIO" Tab
A40: 37 | B40: D1_TC_M10_DP19_L88_TD01__CNV_WT_CLKN | C40: BF14 | D40: J1603.AS2 | E40: J1603PIN112 | F40: UA121.7 | G40: UA121.19 | P40: 275.4156 | Q40: 29.8394 | R40: =IF(AND(P40="",Q40=""),"",SUM(P40:Q40)) -> 305.255 | S40: L20_HSIO1/L26_HSIO4 | T40: 37 | U40: CNV_WT_CLKN | V40: BF14 | W40: 7283.5 | X40: 9908.9 | Y40: IO | Z40: Bottom | AA40: DM800 | AC40: 1 | AD40: TD01 | AG40: DP19 | AH40: 5 | AI40: 100 | AJ40: M10 | AK40: 20 | AM40: L88 | AP40: 2.56 Gbs | AQ40: Refer to "HSIO" Tab
A41: 38 | B41: D1_TC_M10_DP19_L87_TD01__CNV_WT_CLKP | C41: BG14 | D41: J1603.AS3 | E41: J1603PIN114 | F41: UA121.1 | G41: UA121.25 | P41: 275.4006 | Q41: 29.837 | R41: =IF(AND(P41="",Q41=""),"",SUM(P41:Q41)) -> 305.2376 | S41: L20_HSIO1/L26_HSIO4 | T41: 38 | U41: CNV_WT_CLKP | V41: BG14 | W41: 7123.4 | X41: 10452.4 | Y41: IO | Z41: Bottom | AA41: DM800 | AC41: 1 | AD41: TD01 | AG41: DP19 | AH41: 5 | AI41: 100 | AJ41: M10 | AK41: 20 | AM41: L87 | AP41: 2.56 Gbs | AQ41: Refer to "HSIO" Tab
A42: 39 | B42: D1_TC_M10_DP20_L90_TD01__CNV_WT_D0N | C42: BF16 | D42: J1606.CS12 | E42: J1606PIN089 | F42: UA122.7 | G42: RA121.1 | H42: UA122.19 | P42: 275.2182 | Q42: 29.9333 | R42: =IF(AND(P42="",Q42=""),"",SUM(P42:Q42)) -> 305.1515 | S42: L28_HSIO5/L26_HSIO4 | T42: 39 | U42: CNV_WT_D0N | V42: BF16 | W42: 6295.4 | X42: 10162.9 | Y42: IO | Z42: Bottom | AA42: DM800 | AC42: 1 | AD42: TD01 | AG42: DP20 | AH42: 5 | AI42: 100 | AJ42: M10 | AK42: 20 | AM42: L90 | AP42: Dphy 2.5G (DC CoupleD - Relays and Relay switches will be added. | AQ42: Refer to "HSIO" Tab
A43: 40 | B43: D1_TC_M10_DP20_L89_TD01__CNV_WT_D0P | C43: BG16 | D43: J1606.CS11 | E43: J1606PIN091 | F43: UA122.1 | G43: KA121.3 | H43: UA122.25 | P43: 275.1678 | Q43: 29.9366 | R43: =IF(AND(P43="",Q43=""),"",SUM(P43:Q43)) -> 305.1044 | S43: L28_HSIO5/L26_HSIO4 | T43: 40 | U43: CNV_WT_D0P | V43: BG16 | W43: 6265.2 | X43: 10665.3 | Y43: IO | Z43: Bottom | AA43: DM800 | AC43: 1 | AD43: TD01 | AG43: DP20 | AH43: 5 | AI43: 100 | AJ43: M10 | AK43: 20 | AM43: L89 | AP43: Dphy 2.5G (DC CoupleD - Relays and Relay switches will be added. | AQ43: Refer to "HSIO" Tab
A44: 41 | B44: D1_TC_M10_DP21_L92_TD01__CNV_WT_D1N | C44: BE15 | D44: J1605.CS9 | E44: J1605PIN051 | F44: UA123.7 | G44: RA122.1 | H44: UA123.19 | P44: 275.2152 | Q44: 29.6142 | R44: =IF(AND(P44="",Q44=""),"",SUM(P44:Q44)) -> 304.8294 | S44: L28_HSIO5/L22_HSIO2 | T44: 41 | U44: CNV_WT_D1N | V44: BE15 | W44: 6668.5 | X44: 9447.6 | Y44: IO | Z44: Bottom | AA44: DM800 | AC44: 1 | AD44: TD01 | AG44: DP21 | AH44: 5 | AI44: 100 | AJ44: M10 | AK44: 20 | AM44: L92 | AP44: Dphy 2.5G (DC CoupleD - Relays and Relay switches will be added. | AQ44: Refer to "HSIO" Tab
A45: 42 | B45: D1_TC_M10_DP21_L91_TD01__CNV_WT_D1P | C45: BF15 | D45: J1605.CS8 | E45: J1605PIN053 | F45: UA123.1 | G45: KA122.3 | H45: UA123.25 | P45: 275.1433 | Q45: 29.586 | R45: =IF(AND(P45="",Q45=""),"",SUM(P45:Q45)) -> 304.7293 | S45: L28_HSIO5/L22_HSIO2 | T45: 42 | U45: CNV_WT_D1P | V45: BF15 | W45: 6760.5 | X45: 9967.8 | Y45: IO | Z45: Bottom | AA45: DM800 | AC45: 1 | AD45: TD01 | AG45: DP21 | AH45: 5 | AI45: 100 | AJ45: M10 | AK45: 20 | AM45: L91 | AP45: Dphy 2.5G (DC CoupleD - Relays and Relay switches will be added. | AQ45: Refer to "HSIO" Tab
A46: 43 | B46: D1_TC_TD01__CPU_TRSTB | C46: AK13 | D46: J1702.AS3 | E46: J1702PIN070 | Q46: 141.2335 | R46: =IF(AND(P46="",Q46=""),"",SUM(P46:Q46)) -> 141.2335 | S46: L11_INT2 | T46: 43 | U46: CPU_TRSTB | V46: AK13 | W46: 7674.8 | X46: 2344.5 | Y46: IO | Z46: Bottom | AA46: DM800 | AC46: 1 | AD46: TD01 | AQ46: direct route to TC
A47: 44 | B47: D1_TC_TD02__CPUPWRGD | C47: AH2 | D47: J1608.DS1 | E47: J1608PIN066 | Q47: 214.0052 | R47: =IF(AND(P47="",Q47=""),"",SUM(P47:Q47)) -> 214.0052 | S47: L28_HSIO5 | T47: 44 | U47: CPUPWRGD | V47: AH2 | W47: 12786.5 | X47: 1192.8 | Y47: IO | Z47: Bottom | AA47: DM800 | AC47: 1 | AD47: TD02 | AQ47: direct route to TC
A48: 45 | B48: D1_TC_TD01__CRASHLOG_TRIG_N | C48: AB5 | D48: J1701.CS6 | E48: J1701PIN101 | Q48: 240.2006 | R48: =IF(AND(P48="",Q48=""),"",SUM(P48:Q48)) -> 240.2006 | S48: L24_HSIO3 | T48: 45 | U48: CRASHLOG_TRIG_N | V48: AB5 | W48: 11455.4 | X48: -1601.5 | Y48: IO | Z48: Bottom | AA48: DM800 | AC48: 1 | AD48: TD01 | AQ48: direct route to TC
A49: 46 | B49: D1_TC_TD01__DBG_PMODE | C49: AF2 | D49: J1606.DS8 | E49: J1606PIN098 | Q49: 133.9616 | R49: =IF(AND(P49="",Q49=""),"",SUM(P49:Q49)) -> 133.9616 | S49: L9_INT1 | T49: 46 | U49: DBG_PMODE | V49: AF2 | W49: 12702.5 | X49: 532.1 | Y49: IO | Z49: Bottom | AA49: DM800 | AC49: 1 | AD49: TD01 | AQ49: direct route to TC
A50: 47 | B50: D1_TC_TD01__DIR_ESPI_ALERTB | C50: G56 | D50: J1709.DS7 | E50: J1709PIN012 | Q50: 211.743 | R50: =IF(AND(P50="",Q50=""),"",SUM(P50:Q50)) -> 211.743 | S50: L11_INT2 | T50: 47 | U50: DIR_ESPI_ALERTB | V50: G56 | W50: -12915.4 | X50: -8462.3 | Y50: IO | Z50: Bottom | AA50: DM800 | AC50: 1 | AD50: TD01 | AQ50: direct route to TC
A51: 48 | B51: D1_TC_TD01__DIR_ESPI_CLK | C51: F55 | D51: J1703.DS1 | E51: J1703PIN022 | Q51: 140.0729 | R51: =IF(AND(P51="",Q51=""),"",SUM(P51:Q51)) -> 140.0729 | S51: L9_INT1 | T51: 48 | U51: DIR_ESPI_CLK | V51: F55 | W51: -12547 | X51: -8975.4 | Y51: IO | Z51: Bottom | AA51: DM800 | AC51: 1 | AD51: TD01 | AQ51: direct route to TC
A52: 49 | B52: D1_TC_TD01__DIR_ESPI_CSB | C52: B52 | D52: J1709.BS2 | E52: J1709PIN023 | Q52: 216.996 | R52: =IF(AND(P52="",Q52=""),"",SUM(P52:Q52)) -> 216.996 | S52: L11_INT2 | T52: 49 | U52: DIR_ESPI_CSB | V52: B52 | W52: -11181.6 | X52: -10770.7 | Y52: IO | Z52: Bottom | AA52: DM800 | AC52: 1 | AD52: TD01 | AQ52: direct route to TC
A53: 50 | B53: D1_TC_TD01__DIR_ESPI_IO_0 | C53: D54 | D53: J1709.BS3 | E53: J1709PIN025 | Q53: 218.3976 | R53: =IF(AND(P53="",Q53=""),"",SUM(P53:Q53)) -> 218.3976 | S53: L11_INT2 | T53: 50 | U53: DIR_ESPI_IO_0 | V53: D54 | W53: -11787 | X53: -9771.9 | Y53: IO | Z53: Bottom | AA53: DM800 | AC53: 1 | AD53: TD01 | AQ53: direct route to TC
A54: 51 | B54: D1_TC_TD01__DIR_ESPI_IO_1 | C54: C55 | D54: J1709.CS6 | E54: J1709PIN013 | Q54: 217.2726 | R54: =IF(AND(P54="",Q54=""),"",SUM(P54:Q54)) -> 217.2726 | S54: L11_INT2 | T54: 51 | U54: DIR_ESPI_IO_1 | V54: C55 | W54: -12527.8 | X54: -10277.2 | Y54: IO | Z54: Bottom | AA54: DM800 | AC54: 1 | AD54: TD01 | AQ54: direct route to TC
A55: 52 | B55: D1_TC_TD01__DIR_ESPI_IO_2 | C55: G54 | D55: J1706.DS1 | E55: J1706PIN022 | Q55: 161.4148 | R55: =IF(AND(P55="",Q55=""),"",SUM(P55:Q55)) -> 161.4148 | S55: L13_INT3 | T55: 52 | U55: DIR_ESPI_IO_2 | V55: G54 | W55: -11912.6 | X55: -8411.2 | Y55: IO | Z55: Bottom | AA55: DM800 | AC55: 1 | AD55: TD01 | AQ55: direct route to TC
A56: 53 | B56: D1_TC_TD01__DIR_ESPI_IO_3 | C56: F53 | D56: J1709.DS6 | E56: J1709PIN014 | Q56: 216.4731 | R56: =IF(AND(P56="",Q56=""),"",SUM(P56:Q56)) -> 216.4731 | S56: L11_INT2 | T56: 53 | U56: DIR_ESPI_IO_3 | V56: F53 | W56: -11553.9 | X56: -9009.9 | Y56: IO | Z56: Bottom | AA56: DM800 | AC56: 1 | AD56: TD01 | AQ56: direct route to TC
A57: 54 | B57: D1_TC_TD01__DIR_ESPI_RCLK | C57: C53 | D57: J1708.DS14 | E57: J1708PIN042 | Q57: 216.8539 | R57: =IF(AND(P57="",Q57=""),"",SUM(P57:Q57)) -> 216.8539 | S57: L13_INT3 | T57: 54 | U57: DIR_ESPI_RCLK | V57: C53 | W57: -11467.2 | X57: -10357.2 | Y57: IO | Z57: Bottom | AA57: DM800 | AC57: 1 | AD57: TD01 | AQ57: direct route to TC
A58: 55 | B58: D1_TC_TD01__DIR_ESPI_RESETB | C58: G55 | D58: J1709.AS8 | E58: J1709PIN036 | Q58: 235.3764 | R58: =IF(AND(P58="",Q58=""),"",SUM(P58:Q58)) -> 235.3764 | S58: L15_INT4 | T58: 55 | U58: DIR_ESPI_RESETB | V58: G55 | W58: -12413 | X58: -8492.5 | Y58: IO | Z58: Bottom | AA58: DM800 | AC58: 1 | AD58: TD01 | AQ58: direct route to TC
...

Sheet SITE3
B1: ITTO-620-0190 Meteor Lake PCH X4 | C1: SITE3 | M1: 44637
B3: Function | C3: Land# | D3: Channel/Tester No | F3: Components | P3: Minor Length | Q3: Major Length | R3: Total Length | S3: Trace Layer | U3: Pin Name | V3: Pin Location | W3: X-Coord | X3: Y-Coord | Y3: Power, GND or IO (Pin Type) | Z3: Top/Bottom Pin | AA3: Interface | AB3: Channel link (CMT DM250 and DM800 only) | AC3: Channel count | AD3: Time Domain | AE3: Min Trace Length (mils) | AF3: Max Trace Length (mils) | AG3: Diff pair number | AH3: Diff phase tolerance (+/- mils) | AI3: Differential impedance (Ohm) | AJ3: Match Group | AK3: Match Group tolerance (+/- mils) | AL3: Share channel (match required) | AM3: Loop back | AN3: RCOMP Groups | AO3: Test point needed | AP3: Signal Speed (MHz) Pins | AQ3: PCB Routing Instruction
A4: 1 | B4: D3_TC_M04_DP01_TD02__CLKOUT_SRC_N_0 | C4: R10 | D4: J1809.DS6 | E4: J1809PIN102 | Q4: 222.806 | R4: =IF(AND(P4="",Q4=""),"",SUM(P4:Q4)) -> 222.806 | S4: L30_HSIO6 | T4: 1 | U4: CLKOUT_SRC_N_0 | V4: R10 | W4: 8983.5 | X4: -4897.1 | Y4: IO | Z4: Bottom | AA4: DM800 | AC4: 1 | AD4: TD02 | AG4: DP01 | AH4: 5 | AI4: 100 | AJ4: M04 | AK4: 5 | AQ4: Differential. Site-to-Site match.
A5: 510 | B5: D3_TC_M01_DP80_L67_TD01__USB31_1_TXN | C5: A17 | D5: J1806.DS12 | E5: J1806PIN090 | F5: CC202.1 | G5: LC203.1 | H5: LC203.2 | P5: 258.0421 | Q5: 54.7704 | R5: =IF(AND(P5="",Q5=""),"",SUM(P5:Q5)) -> 312.8125 | S5: L22_HSIO2/L26_HSIO4 | T5: 510 | U5: USB31_1_TXN | V5: A17 | W5: 12413 | X5: -8492.5 | Y5: IO | Z5: Bottom | AA5: DM800 | AC5: 1 | AD5: TD02 | AG5: DP02 | AH5: 5 | AI5: 100 | AJ5: M04 | AK5: 5 | AQ5: Differential. Site-to-Site match.
A6: 3 | B6: D3_TC_M04_DP03_TD02__CLKOUT_SRC_N_10 | C6: H5 | D6: J1809.CS1 | E6: J1809PIN109 | Q6: 222.7985 | R6: =IF(AND(P6="",Q6=""),"",SUM(P6:Q6)) -> 222.7985 | S6: L11_INT2 | T6: 3 | U6: CLKOUT_SRC_N_10 | V6: H5 | W6: 11455.4 | X6: -8192.8 | Y6: IO | Z6: Bottom | AA6: DM800 | AC6: 1 | AD6: TD02 | AG6: DP03 | AH6: 5 | AI6: 100 | AJ6: M04 | AK6: 5 | AQ6: Differential. Site-to-Site match.
A7: 541 | B7: D3_TC_M01_DP88_L82_TD01__USB31_8_RXP | C7: K25 | D7: J1806.CS4 | E7: J1806PIN103 | F7: CC215.2 | G7: LC230.1 | H7: LC230.2 | P7: 258.0014 | Q7: 54.6071 | R7: =IF(AND(P7="",Q7=""),"",SUM(P7:Q7)) -> 312.6085 | S7: L20_HSIO1/L28_HSIO5 | T7: 541 | U7: USB31_8_RXP | V7: K25 | W7: 10945.9 | X7: -7035.5 | Y7: IO | Z7: Bottom | AA7: DM800 | AC7: 1 | AD7: TD02 | AG7: DP04 | AH7: 5 | AI7: 100 | AJ7: M04 | AK7: 5 | AQ7: Differential. Site-to-Site match.
A8: 5 | B8: D3_TC_M04_DP05_TD02__CLKOUT_SRC_N_12 | C8: N6 | D8: J1807.AS5 | E8: J1807PIN030 | Q8: 222.809 | R8: =IF(AND(P8="",Q8=""),"",SUM(P8:Q8)) -> 222.809 | S8: L11_INT2 | T8: 5 | U8: CLKOUT_SRC_N_12 | V8: N6 | W8: 10945.9 | X8: -5854.3 | Y8: IO | Z8: Bottom | AA8: DM800 | AC8: 1 | AD8: TD02 | AG8: DP05 | AH8: 5 | AI8: 100 | AJ8: M04 | AK8: 5 | AQ8: Differential. Site-to-Site match.
A9: 542 | B9: D3_TC_M01_DP88_L81_TD01__USB31_8_TXN | C9: C27 | D9: J1806.DS3 | E9: J1806PIN106 | F9: CC216.1 | G9: LC231.1 | H9: LC231.2 | P9: 257.99 | Q9: 54.8451 | R9: =IF(AND(P9="",Q9=""),"",SUM(P9:Q9)) -> 312.8351 | S9: L20_HSIO1/L26_HSIO4 | T9: 542 | U9: USB31_8_TXN | V9: C27 | W9: 8983.5 | X9: -3258.8 | Y9: IO | Z9: Bottom | AA9: DM800 | AC9: 1 | AD9: TD02 | AG9: DP06 | AH9: 5 | AI9: 100 | AJ9: M04 | AK9: 5 | AQ9: Differential. Site-to-Site match.
A10: 7 | B10: D3_TC_M04_DP07_TD02__CLKOUT_SRC_N_2 | C10: J2 | D10: J1808.DS3 | E10: J1808PIN062 | Q10: 222.7924 | R10: =IF(AND(P10="",Q10=""),"",SUM(P10:Q10)) -> 222.7924 | S10: L9_INT1 | T10: 7 | U10: CLKOUT_SRC_N_2 | V10: J2 | W10: 12786.5 | X10: -7784.1 | Y10: IO | Z10: Bottom | AA10: DM800 | AC10: 1 | AD10: TD02 | AG10: DP07 | AH10: 5 | AI10: 100 | AJ10: M04 | AK10: 5 | AQ10: Differential. Site-to-Site match.
A11: 429 | B11: D3_TC_M01_DP62_L17_TD01__PCIE_8_TXN | C11: BG27 | D11: J1803.DS14 | E11: J1803PIN086 | F11: CC236.1 | G11: LC271.1 | H11: LC271.2 | P11: 258.0329 | Q11: 54.4664 | R11: =IF(AND(P11="",Q11=""),"",SUM(P11:Q11)) -> 312.4993 | S11: L28_HSIO5/L20_HSIO1 | T11: 429 | U11: PCIE_8_TXN | V11: BG27 | W11: 12702.5 | X11: -7123.4 | Y11: IO | Z11: Bottom | AA11: DM800 | AC11: 1 | AD11: TD02 | AG11: DP08 | AH11: 5 | AI11: 100 | AJ11: M04 | AK11: 5 | AQ11: Differential. Site-to-Site match.
A12: 9 | B12: D3_TC_M04_DP09_TD02__CLKOUT_SRC_N_4 | C12: M3 | D12: J1808.CS4 | E12: J1808PIN059 | Q12: 222.8692 | R12: =IF(AND(P12="",Q12=""),"",SUM(P12:Q12)) -> 222.8692 | S12: L9_INT1 | T12: 9 | U12: CLKOUT_SRC_N_4 | V12: M3 | W12: 12413 | X12: -6295.4 | Y12: IO | Z12: Bottom | AA12: DM800 | AC12: 1 | AD12: TD02 | AG12: DP09 | AH12: 5 | AI12: 100 | AJ12: M04 | AK12: 5 | AQ12: Differential. Site-to-Site match.
A13: 10 | B13: D3_TC_M04_DP10_TD02__CLKOUT_SRC_N_5 | C13: M4 | D13: J1807.DS7 | E13: J1807PIN012 | Q13: 222.8261 | R13: =IF(AND(P13="",Q13=""),"",SUM(P13:Q13)) -> 222.8261 | S13: L13_INT3 | T13: 10 | U13: CLKOUT_SRC_N_5 | V13: M4 | W13: 11912.6 | X13: -6214.1 | Y13: IO | Z13: Bottom | AA13: DM800 | AC13: 1 | AD13: TD02 | AG13: DP10 | AH13: 5 | AI13: 100 | AJ13: M04 | AK13: 5 | AQ13: Differential. Site-to-Site match.
A14: 317 | B14: D3_TC_TD01__GPP_R_9_ISH_SPI_CSB_GSPI2_CS0B | C14: AW4 | D14: J1803.CS2 | E14: J1803PIN107 | Q14: 159.5425 | R14: =IF(AND(P14="",Q14=""),"",SUM(P14:Q14)) -> 159.5425 | S14: L20_HSIO1 | T14: 317 | U14: GPP_R_9_ISH_SPI_CSB_GSPI2_CS0B | V14: AW4 | W14: 12285.7 | X14: -5587 | Y14: IO | Z14: Bottom | AA14: DM800 | AC14: 1 | AD14: TD02 | AG14: DP11 | AH14: 5 | AI14: 100 | AJ14: M04 | AK14: 5 | AQ14: Differential. Site-to-Site match.
A15: 12 | B15: D3_TC_M04_DP12_TD02__CLKOUT_SRC_N_7 | C15: R2 | D15: J1807.CS4 | E15: J1807PIN015 | Q15: 222.8106 | R15: =IF(AND(P15="",Q15=""),"",SUM(P15:Q15)) -> 222.8106 | S15: L11_INT2 | T15: 12 | U15: CLKOUT_SRC_N_7 | V15: R2 | W15: 12702.5 | X15: -4926.3 | Y15: IO | Z15: Bottom | AA15: DM800 | AC15: 1 | AD15: TD02 | AG15: DP12 | AH15: 5 | AI15: 100 | AJ15: M04 | AK15: 5 | AQ15: Differential. Site-to-Site match.
A16: 486 | B16: D3_TC_M14_DP74_TD01__USB2N_5 | C16: E11 | D16: J1805.DS7 | E16: J1805PIN056 | Q16: 232.8764 | R16: =IF(AND(P16="",Q16=""),"",SUM(P16:Q16)) -> 232.8764 | S16: L24_HSIO3 | T16: 486 | U16: USB2N_5 | V16: E11 | W16: 12217.9 | X16: -4563.4 | Y16: IO | Z16: Bottom | AA16: DM800 | AC16: 1 | AD16: TD02 | AG16: DP13 | AH16: 5 | AI16: 100 | AJ16: M04 | AK16: 5 | AQ16: Differential. Site-to-Site match.
A17: 14 | B17: D3_TC_M04_DP14_TD02__CLKOUT_SRC_N_9 | C17: J7 | D17: J1808.BS2 | E17: J1808PIN067 | Q17: 222.8078 | R17: =IF(AND(P17="",Q17=""),"",SUM(P17:Q17)) -> 222.8078 | S17: L11_INT2 | T17: 14 | U17: CLKOUT_SRC_N_9 | V17: J7 | W17: 10449.6 | X17: -7741.5 | Y17: IO | Z17: Bottom | AA17: DM800 | AC17: 1 | AD17: TD02 | AG17: DP14 | AH17: 5 | AI17: 100 | AJ17: M04 | AK17: 5 | AQ17: Differential. Site-to-Site match.
A18: 15 | B18: D3_TC_M04_DP01_TD02__CLKOUT_SRC_P_0 | C18: R12 | D18: J1809.DS7 | E18: J1809PIN100 | Q18: 222.8073 | R18: =IF(AND(P18="",Q18=""),"",SUM(P18:Q18)) -> 222.8073 | S18: L30_HSIO6 | T18: 15 | U18: CLKOUT_SRC_P_0 | V18: R12 | W18: 8272.3 | X18: -4897.1 | Y18: IO | Z18: Bottom | AA18: DM800 | AC18: 1 | AD18: TD02 | AG18: DP01 | AH18: 5 | AI18: 100 | AJ18: M04 | AK18: 5 | AQ18: Differential. Site-to-Site match.
A19: 16 | B19: D3_TC_M04_DP02_TD02__CLKOUT_SRC_P_1 | C19: G2 | D19: J1809.AS2 | E19: J1809PIN112 | Q19: 222.8328 | R19: =IF(AND(P19="",Q19=""),"",SUM(P19:Q19)) -> 222.8328 | S19: L9_INT1 | T19: 16 | U19: CLKOUT_SRC_P_1 | V19: G2 | W19: 12915.4 | X19: -8462.3 | Y19: IO | Z19: Bottom | AA19: DM800 | AC19: 1 | AD19: TD02 | AG19: DP02 | AH19: 5 | AI19: 100 | AJ19: M04 | AK19: 5 | AQ19: Differential. Site-to-Site match.
A20: 17 | B20: D3_TC_M04_DP03_TD02__CLKOUT_SRC_P_10 | C20: F5 | D20: J1809.CS2 | E20: J1809PIN107 | Q20: 222.799 | R20: =IF(AND(P20="",Q20=""),"",SUM(P20:Q20)) -> 222.799 | S20: L11_INT2 | T20: 17 | U20: CLKOUT_SRC_P_10 | V20: F5 | W20: 11553.9 | X20: -9009.9 | Y20: IO | Z20: Bottom | AA20: DM800 | AC20: 1 | AD20: TD02 | AG20: DP03 | AH20: 5 | AI20: 100 | AJ20: M04 | AK20: 5 | AQ20: Differential. Site-to-Site match.
A21: 18 | B21: D3_TC_M04_DP04_TD02__CLKOUT_SRC_P_11 | C21: L7 | D21: J1808.CS1 | E21: J1808PIN065 | Q21: 222.8428 | R21: =IF(AND(P21="",Q21=""),"",SUM(P21:Q21)) -> 222.8428 | S21: L13_INT3 | T21: 18 | U21: CLKOUT_SRC_P_11 | V21: L7 | W21: 10289.3 | X21: -6694.5 | Y21: IO | Z21: Bottom | AA21: DM800 | AC21: 1 | AD21: TD02 | AG21: DP04 | AH21: 5 | AI21: 100 | AJ21: M04 | AK21: 5 | AQ21: Differential. Site-to-Site match.
A22: 19 | B22: D3_TC_M04_DP05_TD02__CLKOUT_SRC_P_12 | C22: N7 | D22: J1807.AS4 | E22: J1807PIN028 | Q22: 222.8574 | R22: =IF(AND(P22="",Q22=""),"",SUM(P22:Q22)) -> 222.8574 | S22: L11_INT2 | T22: 19 | U22: CLKOUT_SRC_P_12 | V22: N7 | W22: 10289.3 | X22: -5521.3 | Y22: IO | Z22: Bottom | AA22: DM800 | AC22: 1 | AD22: TD02 | AG22: DP05 | AH22: 5 | AI22: 100 | AJ22: M04 | AK22: 5 | AQ22: Differential. Site-to-Site match.
A23: 20 | B23: D3_TC_M04_DP06_TD02__CLKOUT_SRC_P_13 | C23: V12 | D23: J1809.BS3 | E23: J1809PIN113 | Q23: 222.8136 | R23: =IF(AND(P23="",Q23=""),"",SUM(P23:Q23)) -> 222.8136 | S23: L30_HSIO6 | T23: 20 | U23: CLKOUT_SRC_P_13 | V23: V12 | W23: 8272.3 | X23: -3258.8 | Y23: IO | Z23: Bottom | AA23: DM800 | AC23: 1 | AD23: TD02 | AG23: DP06 | AH23: 5 | AI23: 100 | AJ23: M04 | AK23: 5 | AQ23: Differential. Site-to-Site match.
... A26: 23 | B26: D3_TC_M04_DP09_TD02__CLKOUT_SRC_P_4 | C26: M2 | D26: J1808.CS3 | E26: J1808PIN061 | Q26: 222.8634 | R26: =IF(AND(P26="",Q26=""),"",SUM(P26:Q26)) -> 222.8634 | S26: L9_INT1 | T26: 23 | U26: CLKOUT_SRC_P_4 | V26: M2 | W26: 12915.4 | X26: -6265.2 | Y26: IO | Z26: Bottom | AA26: DM800 | AC26: 1 | AD26: TD02 | AG26: DP09 | AH26: 5 | AI26: 100 | AJ26: M04 | AK26: 5 | AQ26: Differential. Site-to-Site match.
A27: 97 | B27: D3_TC_DP39_TD01_TP__EXT_INJ_PHY_P_PAD | C27: F3 | D27: J1805.CS3 | E27: J1805PIN061 | F27: TPC607.1 | Q27: 209.2126 | R27: =IF(AND(P27="",Q27=""),"",SUM(P27:Q27)) -> 209.2126 | S27: L15_INT4 | T27: 97 | U27: EXT_INJ_PHY_P_PAD | V27: F3 | W27: 11455.4 | X27: -5995.7 | Y27: IO | Z27: Bottom | AA27: DM800 | AC27: 1 | AD27: TD02 | AG27: DP10 | AH27: 5 | AI27: 100 | AJ27: M04 | AK27: 5 | AQ27: Differential. Site-to-Site match.
A28: 25 | B28: D3_TC_M04_DP11_TD02__CLKOUT_SRC_P_6 | C28: N2 | D28: J1808.AS2 | E28: J1808PIN068 | Q28: 222.8328 | R28: =IF(AND(P28="",Q28=""),"",SUM(P28:Q28)) -> 222.8328 | S28: L9_INT1 | T28: 25 | U28: CLKOUT_SRC_P_6 | V28: N2 | W28: 12786.5 | X28: -5587 | Y28: IO | Z28: Bottom | AA28: DM800 | AC28: 1 | AD28: TD02 | AG28: DP11 | AH28: 5 | AI28: 100 | AJ28: M04 | AK28: 5 | AQ28: Differential. Site-to-Site match.
A29: 26 | B29: D3_TC_M04_DP12_TD02__CLKOUT_SRC_P_7 | C29: P3 | D29: J1807.CS3 | E29: J1807PIN017 | Q29: 222.8102 | R29: =IF(AND(P29="",Q29=""),"",SUM(P29:Q29)) -> 222.8102 | S29: L11_INT2 | T29: 26 | U29: CLKOUT_SRC_P_7 | V29: P3 | W29: 12159 | X29: -5080 | Y29: IO | Z29: Bottom | AA29: DM800 | AC29: 1 | AD29: TD02 | AG29: DP12 | AH29: 5 | AI29: 100 | AJ29: M04 | AK29: 5 | AQ29: Differential. Site-to-Site match.
A30: 27 | B30: D3_TC_M04_DP13_TD02__CLKOUT_SRC_P_8 | C30: T3 | D30: J1807.DS3 | E30: J1807PIN018 | Q30: 222.81 | R30: =IF(AND(P30="",Q30=""),"",SUM(P30:Q30)) -> 222.81 | S30: L9_INT1 | T30: 27 | U30: CLKOUT_SRC_P_8 | V30: T3 | W30: 12413 | X30: -4098.3 | Y30: IO | Z30: Bottom | AA30: DM800 | AC30: 1 | AD30: TD02 | AG30: DP13 | AH30: 5 | AI30: 100 | AJ30: M04 | AK30: 5 | AQ30: Differential. Site-to-Site match.
A31: 28 | B31: D3_TC_M04_DP14_TD02__CLKOUT_SRC_P_9 | C31: H6 | D31: J1808.BS3 | E31: J1808PIN069 | Q31: 222.8529 | R31: =IF(AND(P31="",Q31=""),"",SUM(P31:Q31)) -> 222.8529 | S31: L11_INT2 | T31: 28 | U31: CLKOUT_SRC_P_9 | V31: H6 | W31: 10883.1 | X31: -8100 | Y31: IO | Z31: Bottom | AA31: DM800 | AC31: 1 | AD31: TD02 | AG31: DP14 | AH31: 5 | AI31: 100 | AJ31: M04 | AK31: 5 | AQ31: Differential. Site-to-Site match.
A32: 29 | B32: D3_TC_M02_DP15_TD02__CLKOUT_XTAL_N | C32: C7 | D32: J1809.DS2 | E32: J1809PIN108 | Q32: 187.7767 | R32: =IF(AND(P32="",Q32=""),"",SUM(P32:Q32)) -> 187.7767 | S32: L9_INT1 | T32: 29 | U32: CLKOUT_XTAL_N | V32: C7 | W32: 10659.4 | X32: -10665.3 | Y32: IO | Z32: Bottom | AA32: DM800 | AC32: 1 | AD32: TD02 | AG32: DP15 | AH32: 5 | AI32: 100 | AJ32: M02 | AK32: 5 | AQ32: Differential. Site-to-Site match.
A33: 30 | B33: D3_TC_M02_DP15_TD02__CLKOUT_XTAL_P | C33: B6 | D33: J1809.DS1 | E33: J1809PIN110 | Q33: 187.7643 | R33: =IF(AND(P33="",Q33=""),"",SUM(P33:Q33)) -> 187.7643 | S33: L9_INT1 | T33: 30 | U33: CLKOUT_XTAL_P | V33: B6 | W33: 11181.6 | X33: -10770.7 | Y33: IO | Z33: Bottom | AA33: DM800 | AC33: 1 | AD33: TD02 | AG33: DP15 | AH33: 5 | AI33: 100 | AJ33: M02 | AK33: 5 | AQ33: Differential. Site-to-Site match.
A34: 31 | B34: D3_TC_M10_DP16_L88_TD01__CNV_WR_CLKN | C34: BB15 | D34: J1802.BS5 | E34: J1802PIN073 | F34: UC121.8 | G34: UC121.18 | P34: 275.3538 | Q34: 29.741 | R34: =IF(AND(P34="",Q34=""),"",SUM(P34:Q34)) -> 305.0948 | S34: L30_HSIO6/L26_HSIO4 | T34: 31 | U34: CNV_WR_CLKN | V34: BB15 | W34: 6454.6 | X34: 8048.1 | Y34: IO | Z34: Bottom | AA34: DM800 | AC34: 1 | AD34: TD01 | AG34: DP16 | AH34: 5 | AI34: 100 | AJ34: M10 | AK34: 20 | AM34: L88 | AP34: 2.56 Gbs | AQ34: Refer to "HSIO" Tab
A35: 32 | B35: D3_TC_M10_DP16_L87_TD01__CNV_WR_CLKP | C35: BC15 | D35: J1802.BS4 | E35: J1802PIN071 | F35: UC121.2 | G35: UC121.24 | P35: 275.3518 | Q35: 29.7481 | R35: =IF(AND(P35="",Q35=""),"",SUM(P35:Q35)) -> 305.0999 | S35: L30_HSIO6/L26_HSIO4 | T35: 32 | U35: CNV_WR_CLKP | V35: BC15 | W35: 6821 | X35: 8695.8 | Y35: IO | Z35: Bottom | AA35: DM800 | AC35: 1 | AD35: TD01 | AG35: DP16 | AH35: 5 | AI35: 100 | AJ35: M10 | AK35: 20 | AM35: L87 | AP35: 2.56 Gbs | AQ35: Refer to "HSIO" Tab
A36: 33 | B36: D3_TC_M10_DP17_L90_TD01__CNV_WR_D0N | C36: AV16 | D36: J1801.BS4 | E36: J1801PIN027 | F36: UC122.8 | G36: UC122.18 | P36: 275.3158 | Q36: 29.8219 | R36: =IF(AND(P36="",Q36=""),"",SUM(P36:Q36)) -> 305.1377 | S36: L30_HSIO6/L26_HSIO4 | T36: 33 | U36: CNV_WR_D0N | V36: AV16 | W36: 5965.9 | X36: 6421.8 | Y36: IO | Z36: Bottom | AA36: DM800 | AC36: 1 | AD36: TD01 | AG36: DP17 | AH36: 5 | AI36: 100 | AJ36: M10 | AK36: 20 | AM36: L90 | AP36: Dphy 2.5G (DC CoupleD - Relays and Relay switches will be added. | AQ36: Refer to "HSIO" Tab
A37: 34 | B37: D3_TC_M10_DP17_L89_TD01__CNV_WR_D0P | C37: BA16 | D37: J1801.BS5 | E37: J1801PIN029 | F37: UC122.2 | G37: UC122.24 | P37: 275.3143 | Q37: 29.8299 | R37: =IF(AND(P37="",Q37=""),"",SUM(P37:Q37)) -> 305.1442 | S37: L30_HSIO6/L26_HSIO4 | T37: 34 | U37: CNV_WR_D0P | V37: BA16 | W37: 6045.6 | X37: 7444.7 | Y37: IO | Z37: Bottom | AA37: DM800 | AC37: 1 | AD37: TD01 | AG37: DP17 | AH37: 5 | AI37: 100 | AJ37: M10 | AK37: 20 | AM37: L89 | AP37: Dphy 2.5G (DC CoupleD - Relays and Relay switches will be added. | AQ37: Refer to "HSIO" Tab
A38: 35 | B38: D3_TC_M10_DP18_L92_TD01__CNV_WR_D1N | C38: BA14 | D38: J1801.DS6 | E38: J1801PIN014 | F38: UC123.8 | G38: UC123.18 | P38: 275.3224 | Q38: 29.6363 | R38: =IF(AND(P38="",Q38=""),"",SUM(P38:Q38)) -> 304.9587 | S38: L30_HSIO6/L22_HSIO2 | T38: 35 | U38: CNV_WR_D1N | V38: BA14 | W38: 7278.6 | X38: 7469.1 | Y38: IO | Z38: Bottom | AA38: DM800 | AC38: 1 | AD38: TD01 | AG38: DP18 | AH38: 5 | AI38: 100 | AJ38: M10 | AK38: 20 | AM38: L92 | AP38: Dphy 2.5G (DC CoupleD - Relays and Relay switches will be added. | AQ38: Refer to "HSIO" Tab
A39: 36 | B39: D3_TC_M10_DP18_L91_TD01__CNV_WR_D1P | C39: BB13 | D39: J1801.DS7 | E39: J1801PIN012 | F39: UC123.2 | G39: UC123.24 | P39: 275.3168 | Q39: 29.5909 | R39: =IF(AND(P39="",Q39=""),"",SUM(P39:Q39)) -> 304.9077 | S39: L30_HSIO6/L22_HSIO2 | T39: 36 | U39: CNV_WR_D1P | V39: BB13 | W39: 7639.2 | X39: 8086.2 | Y39: IO | Z39: Bottom | AA39: DM800 | AC39: 1 | AD39: TD01 | AG39: DP18 | AH39: 5 | AI39: 100 | AJ39: M10 | AK39: 20 | AM39: L91 | AP39: Dphy 2.5G (DC CoupleD - Relays and Relay switches will be added. | AQ39: Refer to "HSIO" Tab
A40: 37 | B40: D3_TC_M10_DP19_L88_TD01__CNV_WT_CLKN | C40: BF14 | D40: J1803.AS2 | E40: J1803PIN112 | F40: UC121.7 | G40: UC121.19 | P40: 275.4156 | Q40: 29.8394 | R40: =IF(AND(P40="",Q40=""),"",SUM(P40:Q40)) -> 305.255 | S40: L20_HSIO1/L26_HSIO4 | T40: 37 | U40: CNV_WT_CLKN | V40: BF14 | W40: 7283.5 | X40: 9908.9 | Y40: IO | Z40: Bottom | AA40: DM800 | AC40: 1 | AD40: TD01 | AG40: DP19 | AH40: 5 | AI40: 100 | AJ40: M10 | AK40: 20 | AM40: L88 | AP40: 2.56 Gbs | AQ40: Refer to "HSIO" Tab
A41: 38 | B41: D3_TC_M10_DP19_L87_TD01__CNV_WT_CLKP | C41: BG14 | D41: J1803.AS3 | E41: J1803PIN114 | F41: UC121.1 | G41: UC121.25 | P41: 275.4006 | Q41: 29.837 | R41: =IF(AND(P41="",Q41=""),"",SUM(P41:Q41)) -> 305.2376 | S41: L20_HSIO1/L26_HSIO4 | T41: 38 | U41: CNV_WT_CLKP | V41: BG14 | W41: 7123.4 | X41: 10452.4 | Y41: IO | Z41: Bottom | AA41: DM800 | AC41: 1 | AD41: TD01 | AG41: DP19 | AH41: 5 | AI41: 100 | AJ41: M10 | AK41: 20 | AM41: L87 | AP41: 2.56 Gbs | AQ41: Refer to "HSIO" Tab
A42: 39 | B42: D3_TC_M10_DP20_L90_TD01__CNV_WT_D0N | C42: BF16 | D42: J1806.CS12 | E42: J1806PIN089 | F42: UC122.7 | G42: RC121.1 | H42: UC122.19 | P42: 275.2182 | Q42: 29.9333 | R42: =IF(AND(P42="",Q42=""),"",SUM(P42:Q42)) -> 305.1515 | S42: L28_HSIO5/L26_HSIO4 | T42: 39 | U42: CNV_WT_D0N | V42: BF16 | W42: 6295.4 | X42: 10162.9 | Y42: IO | Z42: Bottom | AA42: DM800 | AC42: 1 | AD42: TD01 | AG42: DP20 | AH42: 5 | AI42: 100 | AJ42: M10 | AK42: 20 | AM42: L90 | AP42: Dphy 2.5G (DC CoupleD - Relays and Relay switches will be added. | AQ42: Refer to "HSIO" Tab
A43: 40 | B43: D3_TC_M10_DP20_L89_TD01__CNV_WT_D0P | C43: BG16 | D43: J1806.CS11 | E43: J1806PIN091 | F43: UC122.1 | G43: KC121.3 | H43: UC122.25 | P43: 275.1678 | Q43: 29.9366 | R43: =IF(AND(P43="",Q43=""),"",SUM(P43:Q43)) -> 305.1044 | S43: L28_HSIO5/L26_HSIO4 | T43: 40 | U43: CNV_WT_D0P | V43: BG16 | W43: 6265.2 | X43: 10665.3 | Y43: IO | Z43: Bottom | AA43: DM800 | AC43: 1 | AD43: TD01 | AG43: DP20 | AH43: 5 | AI43: 100 | AJ43: M10 | AK43: 20 | AM43: L89 | AP43: Dphy 2.5G (DC CoupleD - Relays and Relay switches will be added. | AQ43: Refer to "HSIO" Tab
...

Sheet CNV_M10
B1: =SITE1!B1 -> ITTO-620-0190 Meteor Lake PCH X4 | K1: 44635
B2: CNV
K4: DUT to SW | M4: Loopback Diff pair | R4: Total | T4: Jconnector Diff pair
K5: max | L5: =MAX(K14:L25) -> 29.9366 | M5: max | N5: =MAX(M14:N25) -> 0.0454 | R5: max | S5: =MAX(R14:S25) -> 305.255 | T5: max | U5: =MAX(T14:U25) -> 0.1001
K6: min | L6: =MIN(K14:L25) -> 29.586 | R6: min | S6: =MIN(R14:S25) -> 304.7293
K7: Diff. | L7: =L5-L6 -> 0.3506 | R7: Diff. | S7: =S5-S6 -> 0.5257
K8: Less than | L8: =I14*2 -> 40 | M8: Less than | N8: 5 | R8: Less than | S8: =I14*2 -> 40 | T8: Less than | U8: 5
L9: =L8*0.0254 -> 1.016 | N9: =N8*0.0254 -> 0.127 | S9: =S8*0.0254 -> 1.016 | U9: =U8*0.0254 -> 0.127
L10: =IF(L7>L9,"Wrong","OK") -> OK | N10: =IF(N5>N9,"Wrong","OK") -> OK | S10: =IF(S7>S9,"Wrong","OK") -> OK | U10: =IF(U5>U9,"Wrong","OK") -> OK
K12: DUT to SW (MM) | M12: Diff pair (MM) | P12: SW to Jconnector (MM) | R12: Total (MM) | T12: Diff pair (MM)
B13: Pin Name | C13: Pin Location | D13: Min Trace Length (mils) | E13: Max Trace Length (mils) | F13: Diff pair number | G13: Diff phase tolerance (+/- mils) | H13: Match Group | I13: Match Group tolerance (+/- mils) | J13: Loop back | K13: SITE1 | L13: SITE3 | M13: SITE1 | N13: SITE3 | P13: SITE1 | Q13: SITE3 | R13: SITE1 | S13: SITE3 | T13: SITE1 | U13: SITE3
B14: CNV_WR_CLKN | C14: BB15 | F14: DP16 | G14: 5 | H14: M10 | I14: 20 | J14: L88 | K14: 29.741 | L14: 29.741 | M14: =ABS(K14-K15) -> 0.0071 | N14: =ABS(L14-L15) -> 0.0071 | P14: 275.3538 | Q14: 275.3538 | R14: =SUM(K14,P14) -> 305.0948 | S14: =SUM(L14,Q14) -> 305.0948 | T14: =ABS(R14-R15) -> 0.0051 | U14: =ABS(S14-S15) -> 0.0051
B15: CNV_WR_CLKP | C15: BC15 | F15: DP16 | G15: 5 | H15: M10 | I15: 20 | J15: L87 | K15: 29.7481 | L15: 29.7481 | P15: 275.3518 | Q15: 275.3518 | R15: =SUM(K15,P15) -> 305.0999 | S15: =SUM(L15,Q15) -> 305.0999
B16: CNV_WR_D0N | C16: AV16 | F16: DP17 | G16: 5 | H16: M10 | I16: 20 | J16: L90 | K16: 29.8219 | L16: 29.8219 | M16: =ABS(K16-K17) -> 0.008 | N16: =ABS(L16-L17) -> 0.008 | P16: 275.3158 | Q16: 275.3158 | R16: =SUM(K16,P16) -> 305.1377 | S16: =SUM(L16,Q16) -> 305.1377 | T16: =ABS(R16-R17) -> 0.0065 | U16: =ABS(S16-S17) -> 0.0065
B17: CNV_WR_D0P | C17: BA16 | F17: DP17 | G17: 5 | H17: M10 | I17: 20 | J17: L89 | K17: 29.8299 | L17: 29.8299 | P17: 275.3143 | Q17: 275.3143 | R17: =SUM(K17,P17) -> 305.1442 | S17: =SUM(L17,Q17) -> 305.1442
B18: CNV_WR_D1N | C18: BA14 | F18: DP18 | G18: 5 | H18: M10 | I18: 20 | J18: L92 | K18: 29.6363 | L18: 29.6363 | M18: =ABS(K18-K19) -> 0.0454 | N18: =ABS(L18-L19) -> 0.0454 | P18: 275.3224 | Q18: 275.3224 | R18: =SUM(K18,P18) -> 304.9587 | S18: =SUM(L18,Q18) -> 304.9587 | T18: =ABS(R18-R19) -> 0.051 | U18: =ABS(S18-S19) -> 0.051
B19: CNV_WR_D1P | C19: BB13 | F19: DP18 | G19: 5 | H19: M10 | I19: 20 | J19: L91 | K19: 29.5909 | L19: 29.5909 | P19: 275.3168 | Q19: 275.3168 | R19: =SUM(K19,P19) -> 304.9077 | S19: =SUM(L19,Q19) -> 304.9077
B20: CNV_WT_CLKN | C20: BF14 | F20: DP19 | G20: 5 | H20: M10 | I20: 20 | J20: L88 | K20: 29.8394 | L20: 29.8394 | M20: =ABS(K20-K21) -> 0.0024 | N20: =ABS(L20-L21) -> 0.0024 | P20: 275.4156 | Q20: 275.4156 | R20: =SUM(K20,P20) -> 305.255 | S20: =SUM(L20,Q20) -> 305.255 | T20: =ABS(R20-R21) -> 0.0174 | U20: =ABS(S20-S21) -> 0.0174
B21: CNV_WT_CLKP | C21: BG14 | F21: DP19 | G21: 5 | H21: M10 | I21: 20 | J21: L87 | K21: 29.837 | L21: 29.837 | P21: 275.4006 | Q21: 275.4006 | R21: =SUM(K21,P21) -> 305.2376 | S21: =SUM(L21,Q21) -> 305.2376
B22: CNV_WT_D0N | C22: BF16 | F22: DP20 | G22: 5 | H22: M10 | I22: 20 | J22: L90 | K22: 29.9333 | L22: 29.9333 | M22: =ABS(K22-K23) -> 0.0033 | N22: =ABS(L22-L23) -> 0.0033 | P22: 275.2182 | Q22: 275.2182 | R22: =SUM(K22,P22) -> 305.1515 | S22: =SUM(L22,Q22) -> 305.1515 | T22: =ABS(R22-R23) -> 0.0471 | U22: =ABS(S22-S23) -> 0.0471
B23: CNV_WT_D0P | C23: BG16 | F23: DP20 | G23: 5 | H23: M10 | I23: 20 | J23: L89 | K23: 29.9366 | L23: 29.9366 | P23: 275.1678 | Q23: 275.1678 | R23: =SUM(K23,P23) -> 305.1044 | S23: =SUM(L23,Q23) -> 305.1044
B24: CNV_WT_D1N | C24: BE15 | F24: DP21 | G24: 5 | H24: M10 | I24: 20 | J24: L92 | K24: 29.6142 | L24: 29.6142 | M24: =ABS(K24-K25) -> 0.0282 | N24: =ABS(L24-L25) -> 0.0282 | P24: 275.2152 | Q24: 275.2152 | R24: =SUM(K24,P24) -> 304.8294 | S24: =SUM(L24,Q24) -> 304.8294 | T24: =ABS(R24-R25) -> 0.1001 | U24: =ABS(S24-S25) -> 0.1001
B25: CNV_WT_D1P | C25: BF15 | F25: DP21 | G25: 5 | H25: M10 | I25: 20 | J25: L91 | K25: 29.586 | L25: 29.586 | P25: 275.1433 | Q25: 275.1433 | R25: =SUM(K25,P25) -> 304.7293 | S25: =SUM(L25,Q25) -> 304.7293

Sheet PCIE_USB31M01
B1: =SITE1!B1 -> ITTO-620-0190 Meteor Lake PCH X4 | K1: 44635
B2: PCIE,USB31
M4: Loopback | O4: Loopback Diff pair | V4: Total | X4: Jconnector Diff pair
M5: max | N5: =MAX(M14:N149) -> 110.0189 | O5: max | P5: =MAX(O14:P149) -> 0.0609 | V5: max | W5: =MAX(V14:W154) -> 312.3965 | X5: max | Y5: =MAX(X14:Y149) -> 0.0673
M6: min | N6: =MIN(M14:N129) -> 108.8937 | V6: min | W6: =MIN(V14:W154) -> 310.409
M7: Diff. | N7: =N5-N6 -> 1.1252 | V7: Diff. | W7: =W5-W6 -> 1.9875
M8: Less than | N8: =I14*2 -> 200 | O8: Less than | P8: 5 | V8: Less than | W8: =I14*2 -> 200 | X8: Less than | Y8: 5
N9: =N8*0.0254 -> 5.08 | P9: =P8*0.0254 -> 0.127 | W9: =W8*0.0254 -> 5.08 | Y9: =Y8*0.0254 -> 0.127
N10: =IF(N7>N9,"Wrong","OK") -> OK | P10: =IF(P5>P9,"Wrong","OK") -> OK | W10: =IF(W7>W9,"Wrong","OK") -> OK | Y10: =IF(Y5>Y9,"Wrong","OK") -> OK
K12: DUT to Capacitor (MM) | M12: Loopback (MM) | O12: Diff pair (MM) | R12: DUT to Inductor (MM) | T12: Inductor to Jconnector (MM) | V12: Total (MM) | X12: Diff pair (MM)
B13: Pin Name | C13: Pin Location | D13: Min Trace Length (mils) | E13: Max Trace Length (mils) | F13: Diff pair number | G13: Diff phase tolerance (+/- mils) | H13: Match Group | I13: Match Group tolerance (+/- mils) | J13: Loop back | K13: SITE1 | L13: SITE3 | M13: SITE1 | N13: SITE3 | O13: SITE1 | P13: SITE3 | R13: SITE1 | S13: SITE3 | T13: SITE1 | U13: SITE3 | V13: SITE1 | W13: SITE3 | X13: SITE1 | Y13: SITE3
B14: PCIE_1_TXN | C14: BJ17 | F14: DP40 | G14: 5 | H14: M01 | I14: 100 | J14: L11 | K14: 54.6769 | L14: 54.6769 | M14: =SUM(K14:K15) -> 110.0114 | N14: =SUM(L14:L15) -> 110.0114 | O14: =ABS(M14-M16) -> 0.0075 | P14: =ABS(N14-N16) -> 0.0075 | R14: 52.6412 | S14: 52.6412 | T14: 258.0383 | U14: 258.0383 | V14: =SUM(R14,T14) -> 310.6795 | W14: =SUM(S14,U14) -> 310.6795 | X14: =ABS(V14-V16) -> 0.0114 | Y14: =ABS(W14-W16) -> 0.0114
B15: PCIE_1_RXN | C15: BC19 | F15: DP40 | G15: 5 | H15: M01 | I15: 100 | J15: L11 | K15: 55.3345 | L15: 55.3345 | R15: 53.2988 | S15: 53.2988 | T15: 258.0479 | U15: 258.0479 | V15: =SUM(R15,T15) -> 311.3467 | W15: =SUM(S15,U15) -> 311.3467 | X15: =ABS(V15-V17) -> 0.0059 | Y15: =ABS(W15-W17) -> 0.0059
