Workbook
Name ballout: [1]Ballout!$A$1:$BT$43

Sheet Sheet1
A1: A3 | B1: =_xlfn.XLOOKUP(A1,'Pinlist(S1)'!$Q$4:$Q$1362,'Pinlist(S1)'!$R$4:$R$1362,"") -> SATA_PLLOBSP | C1: {=_xlfn.TEXTJOIN(",",TRUE,_xlfn.UNIQUE(TRANSPOSE(_xlfn.MAP(_xlfn.XLOOKUP(A1,'Pinlist(S1)'!$C$4:$C$1362,'Pinlist(S1)'!$F$4:$K$1362,""),_xlfn.LAMBDA(_xlpm.x,IF(_xlpm.x<>"",TRIM(CLEAN(LEFT(_xlpm.x,FIND(".",_xlpm.x & ".")-1))),""))))))} | D1: 0.965 | E1: 0 | F1: =_xlfn.LET(_xlpm.raw,_xlfn.XLOOKUP(A1,'Pinlist(S1)'!$C$4:$C$1362,'Pinlist(S1)'!$E$4:$E$1362,""),_xlpm.cleanRaw,SUBSTITUTE(SUBSTITUTE(_xlpm.raw,"_PIN","."),"PIN","."),_xlpm.mainPart,MID(_xlpm.cleanRaw,2,FIND(".",_xlpm.cleanRaw & ".")-2),_xlpm.subPart,MID(_xlpm.cleanRaw,FIND(".",_xlpm.cleanRaw & ".")+1,99),_xlpm.result,RIGHT(_xlpm.mainPart,LEN(_xlpm.mainPart)-1)& TEXT(_xlpm.subPart,"000"),IF(OR(_xlpm.raw="",_xlpm.raw="-"),"",_xlpm.result)) | G1: =_xlfn.LET(_xlpm.raw,_xlfn.XLOOKUP(A1,'Pinlist(S3)'!$C$4:$C$1362,'Pinlist(S3)'!$E$4:$E$1362,""),_xlpm.cleanRaw,SUBSTITUTE(SUBSTITUTE(_xlpm.raw,"_PIN","."),"PIN","."),_xlpm.mainPart,MID(_xlpm.cleanRaw,2,FIND(".",_xlpm.cleanRaw & ".")-2),_xlpm.subPart,MID(_xlpm.cleanRaw,FIND(".",_xlpm.cleanRaw & ".")+1,99),_xlpm.result,RIGHT(_xlpm.mainPart,LEN(_xlpm.mainPart)-1)& TEXT(_xlpm.subPart,"000"),IF(OR(_xlpm.raw="",_xlpm.raw="-"),"",_xlpm.result)) | H1: =_xlfn.LET(_xlpm.raw,_xlfn.XLOOKUP(A1,'Pinlist(S5)'!$C$4:$C$1362,'Pinlist(S5)'!$E$4:$E$1362,""),_xlpm.cleanRaw,SUBSTITUTE(SUBSTITUTE(_xlpm.raw,"_PIN","."),"PIN","."),_xlpm.mainPart,MID(_xlpm.cleanRaw,2,FIND(".",_xlpm.cleanRaw & ".")-2),_xlpm.subPart,MID(_xlpm.cleanRaw,FIND(".",_xlpm.cleanRaw & ".")+1,99),_xlpm.result,RIGHT(_xlpm.mainPart,LEN(_xlpm.mainPart)-1)& TEXT(_xlpm.subPart,"000"),IF(OR(_xlpm.raw="",_xlpm.raw="-"),"",_xlpm.result)) | I1: ="" | J1: =A1&";"&B1&";"&C1&";"&D1&";"&E1&";"&F1&";"&G1&";"&H1&";"&I1 -> A3;SATA_PLLOBSP;;0.965000000000003;0;;;;
A2: A4 | B2: =_xlfn.XLOOKUP(A2,'Pinlist(S1)'!$Q$4:$Q$1362,'Pinlist(S1)'!$R$4:$R$1362,"") -> XCKPLL_MON_N | C2: {=_xlfn.TEXTJOIN(",",TRUE,_xlfn.UNIQUE(TRANSPOSE(_xlfn.MAP(_xlfn.XLOOKUP(A2,'Pinlist(S1)'!$C$4:$C$1362,'Pinlist(S1)'!$F$4:$K$1362,""),_xlfn.LAMBDA(_xlpm.x,IF(_xlpm.x<>"",TRIM(CLEAN(LEFT(_xlpm.x,FIND(".",_xlpm.x & ".")-1))),""))))))} | D2: 1.615 | E2: 0 | F2: =_xlfn.LET(_xlpm.raw,_xlfn.XLOOKUP(A2,'Pinlist(S1)'!$C$4:$C$1362,'Pinlist(S1)'!$E$4:$E$1362,""),_xlpm.cleanRaw,SUBSTITUTE(SUBSTITUTE(_xlpm.raw,"_PIN","."),"PIN","."),_xlpm.mainPart,MID(_xlpm.cleanRaw,2,FIND(".",_xlpm.cleanRaw & ".")-2),_xlpm.subPart,MID(_xlpm.cleanRaw,FIND(".",_xlpm.cleanRaw & ".")+1,99),_xlpm.result,RIGHT(_xlpm.mainPart,LEN(_xlpm.mainPart)-1)& TEXT(_xlpm.subPart,"000"),IF(OR(_xlpm.raw="",_xlpm.raw="-"),"",_xlpm.result)) | G2: =_xlfn.LET(_xlpm.raw,_xlfn.XLOOKUP(A2,'Pinlist(S3)'!$C$4:$C$1362,'Pinlist(S3)'!$E$4:$E$1362,""),_xlpm.cleanRaw,SUBSTITUTE(SUBSTITUTE(_xlpm.raw,"_PIN","."),"PIN","."),_xlpm.mainPart,MID(_xlpm.cleanRaw,2,FIND(".",_xlpm.cleanRaw & ".")-2),_xlpm.subPart,MID(_xlpm.cleanRaw,FIND(".",_xlpm.cleanRaw & ".")+1,99),_xlpm.result,RIGHT(_xlpm.mainPart,LEN(_xlpm.mainPart)-1)& TEXT(_xlpm.subPart,"000"),IF(OR(_xlpm.raw="",_xlpm.raw="-"),"",_xlpm.result)) | H2: =_xlfn.LET(_xlpm.raw,_xlfn.XLOOKUP(A2,'Pinlist(S5)'!$C$4:$C$1362,'Pinlist(S5)'!$E$4:$E$1362,""),_xlpm.cleanRaw,SUBSTITUTE(SUBSTITUTE(_xlpm.raw,"_PIN","."),"PIN","."),_xlpm.mainPart,MID(_xlpm.cleanRaw,2,FIND(".",_xlpm.cleanRaw & ".")-2),_xlpm.subPart,MID(_xlpm.cleanRaw,FIND(".",_xlpm.cleanRaw & ".")+1,99),_xlpm.result,RIGHT(_xlpm.mainPart,LEN(_xlpm.mainPart)-1)& TEXT(_xlpm.subPart,"000"),IF(OR(_xlpm.raw="",_xlpm.raw="-"),"",_xlpm.result)) | I2: ="" | J2: =A2&";"&B2&";"&C2&";"&D2&";"&E2&";"&F2&";"&G2&";"&H2&";"&I2 -> A4;XCKPLL_MON_N;;1.61499999999999;0;;;;
A3: A5 | B3: =_xlfn.XLOOKUP(A3,'Pinlist(S1)'!$Q$4:$Q$1362,'Pinlist(S1)'!$R$4:$R$1362,"") -> VSS | C3: {=_xlfn.TEXTJOIN(",",TRUE,_xlfn.UNIQUE(TRANSPOSE(_xlfn.MAP(_xlfn.XLOOKUP(A3,'Pinlist(S1)'!$C$4:$C$1362,'Pinlist(S1)'!$F$4:$K$1362,""),_xlfn.LAMBDA(_xlpm.x,IF(_xlpm.x<>"",TRIM(CLEAN(LEFT(_xlpm.x,FIND(".",_xlpm.x & ".")-1))),""))))))} | D3: 2.265 | E3: 0 | F3: =_xlfn.LET(_xlpm.raw,_xlfn.XLOOKUP(A3,'Pinlist(S1)'!$C$4:$C$1362,'Pinlist(S1)'!$E$4:$E$1362,""),_xlpm.cleanRaw,SUBSTITUTE(SUBSTITUTE(_xlpm.raw,"_PIN","."),"PIN","."),_xlpm.mainPart,MID(_xlpm.cleanRaw,2,FIND(".",_xlpm.cleanRaw & ".")-2),_xlpm.subPart,MID(_xlpm.cleanRaw,FIND(".",_xlpm.cleanRaw & ".")+1,99),_xlpm.result,RIGHT(_xlpm.mainPart,LEN(_xlpm.mainPart)-1)& TEXT(_xlpm.subPart,"000"),IF(OR(_xlpm.raw="",_xlpm.raw="-"),"",_xlpm.result)) | G3: =_xlfn.LET(_xlpm.raw,_xlfn.XLOOKUP(A3,'Pinlist(S3)'!$C$4:$C$1362,'Pinlist(S3)'!$E$4:$E$1362,""),_xlpm.cleanRaw,SUBSTITUTE(SUBSTITUTE(_xlpm.raw,"_PIN","."),"PIN","."),_xlpm.mainPart,MID(_xlpm.cleanRaw,2,FIND(".",_xlpm.cleanRaw & ".")-2),_xlpm.subPart,MID(_xlpm.cleanRaw,FIND(".",_xlpm.cleanRaw & ".")+1,99),_xlpm.result,RIGHT(_xlpm.mainPart,LEN(_xlpm.mainPart)-1)& TEXT(_xlpm.subPart,"000"),IF(OR(_xlpm.raw="",_xlpm.raw="-"),"",_xlpm.result)) | H3: =_xlfn.LET(_xlpm.raw,_xlfn.XLOOKUP(A3,'Pinlist(S5)'!$C$4:$C$1362,'Pinlist(S5)'!$E$4:$E$1362,""),_xlpm.cleanRaw,SUBSTITUTE(SUBSTITUTE(_xlpm.raw,"_PIN","."),"PIN","."),_xlpm.mainPart,MID(_xlpm.cleanRaw,2,FIND(".",_xlpm.cleanRaw & ".")-2),_xlpm.subPart,MID(_xlpm.cleanRaw,FIND(".",_xlpm.cleanRaw & ".")+1,99),_xlpm.result,RIGHT(_xlpm.mainPart,LEN(_xlpm.mainPart)-1)& TEXT(_xlpm.subPart,"000"),IF(OR(_xlpm.raw="",_xlpm.raw="-"),"",_xlpm.result)) | I3: ="" | J3: =A3&";"&B3&";"&C3&";"&D3&";"&E3&";"&F3&";"&G3&";"&H3&";"&I3 -> A5;VSS;;2.265;0;;;;
A4: A6 | B4: =_xlfn.XLOOKUP(A4,'Pinlist(S1)'!$Q$4:$Q$1362,'Pinlist(S1)'!$R$4:$R$1362,"") -> GPP_E_3_CPU_GP_0 | C4: {=_xlfn.TEXTJOIN(",",TRUE,_xlfn.UNIQUE(TRANSPOSE(_xlfn.MAP(_xlfn.XLOOKUP(A4,'Pinlist(S1)'!$C$4:$C$1362,'Pinlist(S1)'!$F$4:$K$1362,""),_xlfn.LAMBDA(_xlpm.x,IF(_xlpm.x<>"",TRIM(CLEAN(LEFT(_xlpm.x,FIND(".",_xlpm.x & ".")-1))),""))))))} | D4: 2.847 | E4: 0.325 | F4: =_xlfn.LET(_xlpm.raw,_xlfn.XLOOKUP(A4,'Pinlist(S1)'!$C$4:$C$1362,'Pinlist(S1)'!$E$4:$E$1362,""),_xlpm.cleanRaw,SUBSTITUTE(SUBSTITUTE(_xlpm.raw,"_PIN","."),"PIN","."),_xlpm.mainPart,MID(_xlpm.cleanRaw,2,FIND(".",_xlpm.cleanRaw & ".")-2),_xlpm.subPart,MID(_xlpm.cleanRaw,FIND(".",_xlpm.cleanRaw & ".")+1,99),_xlpm.result,RIGHT(_xlpm.mainPart,LEN(_xlpm.mainPart)-1)& TEXT(_xlpm.subPart,"000"),IF(OR(_xlpm.raw="",_xlpm.raw="-"),"",_xlpm.result)) -> 504123 | G4: =_xlfn.LET(_xlpm.raw,_xlfn.XLOOKUP(A4,'Pinlist(S3)'!$C$4:$C$1362,'Pinlist(S3)'!$E$4:$E$1362,""),_xlpm.cleanRaw,SUBSTITUTE(SUBSTITUTE(_xlpm.raw,"_PIN","."),"PIN","."),_xlpm.mainPart,MID(_xlpm.cleanRaw,2,FIND(".",_xlpm.cleanRaw & ".")-2),_xlpm.subPart,MID(_xlpm.cleanRaw,FIND(".",_xlpm.cleanRaw & ".")+1,99),_xlpm.result,RIGHT(_xlpm.mainPart,LEN(_xlpm.mainPart)-1)& TEXT(_xlpm.subPart,"000"),IF(OR(_xlpm.raw="",_xlpm.raw="-"),"",_xlpm.result)) -> 808060 | H4: =_xlfn.LET(_xlpm.raw,_xlfn.XLOOKUP(A4,'Pinlist(S5)'!$C$4:$C$1362,'Pinlist(S5)'!$E$4:$E$1362,""),_xlpm.cleanRaw,SUBSTITUTE(SUBSTITUTE(_xlpm.raw,"_PIN","."),"PIN","."),_xlpm.mainPart,MID(_xlpm.cleanRaw,2,FIND(".",_xlpm.cleanRaw & ".")-2),_xlpm.subPart,MID(_xlpm.cleanRaw,FIND(".",_xlpm.cleanRaw & ".")+1,99),_xlpm.result,RIGHT(_xlpm.mainPart,LEN(_xlpm.mainPart)-1)& TEXT(_xlpm.subPart,"000"),IF(OR(_xlpm.raw="",_xlpm.raw="-"),"",_xlpm.result)) -> 602076 | I4: ="" | J4: =A4&";"&B4&";"&C4&";"&D4&";"&E4&";"&F4&";"&G4&";"&H4&";"&I4 -> A6;GPP_E_3_CPU_GP_0;;2.847;0.324999999999999;504123;808060;602076;
A5: A7 | B5: =_xlfn.XLOOKUP(A5,'Pinlist(S1)'!$Q$4:$Q$1362,'Pinlist(S1)'!$R$4:$R$1362,"") -> GPP_E_7_CPU_GP_1 | C5: {=_xlfn.TEXTJOIN(",",TRUE,_xlfn.UNIQUE(TRANSPOSE(_xlfn.MAP(_xlfn.XLOOKUP(A5,'Pinlist(S1)'!$C$4:$C$1362,'Pinlist(S1)'!$F$4:$K$1362,""),_xlfn.LAMBDA(_xlpm.x,IF(_xlpm.x<>"",TRIM(CLEAN(LEFT(_xlpm.x,FIND(".",_xlpm.x & ".")-1))),""))))))} | D5: 3.523 | E5: 0 | F5: =_xlfn.LET(_xlpm.raw,_xlfn.XLOOKUP(A5,'Pinlist(S1)'!$C$4:$C$1362,'Pinlist(S1)'!$E$4:$E$1362,""),_xlpm.cleanRaw,SUBSTITUTE(SUBSTITUTE(_xlpm.raw,"_PIN","."),"PIN","."),_xlpm.mainPart,MID(_xlpm.cleanRaw,2,FIND(".",_xlpm.cleanRaw & ".")-2),_xlpm.subPart,MID(_xlpm.cleanRaw,FIND(".",_xlpm.cleanRaw & ".")+1,99),_xlpm.result,RIGHT(_xlpm.mainPart,LEN(_xlpm.mainPart)-1)& TEXT(_xlpm.subPart,"000"),IF(OR(_xlpm.raw="",_xlpm.raw="-"),"",_xlpm.result)) -> 504118 | G5: =_xlfn.LET(_xlpm.raw,_xlfn.XLOOKUP(A5,'Pinlist(S3)'!$C$4:$C$1362,'Pinlist(S3)'!$E$4:$E$1362,""),_xlpm.cleanRaw,SUBSTITUTE(SUBSTITUTE(_xlpm.raw,"_PIN","."),"PIN","."),_xlpm.mainPart,MID(_xlpm.cleanRaw,2,FIND(".",_xlpm.cleanRaw & ".")-2),_xlpm.subPart,MID(_xlpm.cleanRaw,FIND(".",_xlpm.cleanRaw & ".")+1,99),_xlpm.result,RIGHT(_xlpm.mainPart,LEN(_xlpm.mainPart)-1)& TEXT(_xlpm.subPart,"000"),IF(OR(_xlpm.raw="",_xlpm.raw="-"),"",_xlpm.result)) -> 807004 | H5: =_xlfn.LET(_xlpm.raw,_xlfn.XLOOKUP(A5,'Pinlist(S5)'!$C$4:$C$1362,'Pinlist(S5)'!$E$4:$E$1362,""),_xlpm.cleanRaw,SUBSTITUTE(SUBSTITUTE(_xlpm.raw,"_PIN","."),"PIN","."),_xlpm.mainPart,MID(_xlpm.cleanRaw,2,FIND(".",_xlpm.cleanRaw & ".")-2),_xlpm.subPart,MID(_xlpm.cleanRaw,FIND(".",_xlpm.cleanRaw & ".")+1,99),_xlpm.result,RIGHT(_xlpm.mainPart,LEN(_xlpm.mainPart)-1)& TEXT(_xlpm.subPart,"000"),IF(OR(_xlpm.raw="",_xlpm.raw="-"),"",_xlpm.result)) -> 602055 | I5: ="" | J5: =A5&";"&B5&";"&C5&";"&D5&";"&E5&";"&F5&";"&G5&";"&H5&";"&I5 -> A7;GPP_E_7_CPU_GP_1;;3.52299999999999;0;504118;807004;602055;
A6: A9 | B6: =_xlfn.XLOOKUP(A6,'Pinlist(S1)'!$Q$4:$Q$1362,'Pinlist(S1)'!$R$4:$R$1362,"") -> GPP_E_9_USB2_OCB_0 | C6: {=_xlfn.TEXTJOIN(",",TRUE,_xlfn.UNIQUE(TRANSPOSE(_xlfn.MAP(_xlfn.XLOOKUP(A6,'Pinlist(S1)'!$C$4:$C$1362,'Pinlist(S1)'!$F$4:$K$1362,""),_xlfn.LAMBDA(_xlpm.x,IF(_xlpm.x<>"",TRIM(CLEAN(LEFT(_xlpm.x,FIND(".",_xlpm.x & ".")-1))),""))))))} | D6: 4.65 | E6: 0 | F6: =_xlfn.LET(_xlpm.raw,_xlfn.XLOOKUP(A6,'Pinlist(S1)'!$C$4:$C$1362,'Pinlist(S1)'!$E$4:$E$1362,""),_xlpm.cleanRaw,SUBSTITUTE(SUBSTITUTE(_xlpm.raw,"_PIN","."),"PIN","."),_xlpm.mainPart,MID(_xlpm.cleanRaw,2,FIND(".",_xlpm.cleanRaw & ".")-2),_xlpm.subPart,MID(_xlpm.cleanRaw,FIND(".",_xlpm.cleanRaw & ".")+1,99),_xlpm.result,RIGHT(_xlpm.mainPart,LEN(_xlpm.mainPart)-1)& TEXT(_xlpm.subPart,"000"),IF(OR(_xlpm.raw="",_xlpm.raw="-"),"",_xlpm.result)) -> 504125 | G6: =_xlfn.LET(_xlpm.raw,_xlfn.XLOOKUP(A6,'Pinlist(S3)'!$C$4:$C$1362,'Pinlist(S3)'!$E$4:$E$1362,""),_xlpm.cleanRaw,SUBSTITUTE(SUBSTITUTE(_xlpm.raw,"_PIN","."),"PIN","."),_xlpm.mainPart,MID(_xlpm.cleanRaw,2,FIND(".",_xlpm.cleanRaw & ".")-2),_xlpm.subPart,MID(_xlpm.cleanRaw,FIND(".",_xlpm.cleanRaw & ".")+1,99),_xlpm.result,RIGHT(_xlpm.mainPart,LEN(_xlpm.mainPart)-1)& TEXT(_xlpm.subPart,"000"),IF(OR(_xlpm.raw="",_xlpm.raw="-"),"",_xlpm.result)) -> 808055 | H6: =_xlfn.LET(_xlpm.raw,_xlfn.XLOOKUP(A6,'Pinlist(S5)'!$C$4:$C$1362,'Pinlist(S5)'!$E$4:$E$1362,""),_xlpm.cleanRaw,SUBSTITUTE(SUBSTITUTE(_xlpm.raw,"_PIN","."),"PIN","."),_xlpm.mainPart,MID(_xlpm.cleanRaw,2,FIND(".",_xlpm.cleanRaw & ".")-2),_xlpm.subPart,MID(_xlpm.cleanRaw,FIND(".",_xlpm.cleanRaw & ".")+1,99),_xlpm.result,RIGHT(_xlpm.mainPart,LEN(_xlpm.mainPart)-1)& TEXT(_xlpm.subPart,"000"),IF(OR(_xlpm.raw="",_xlpm.raw="-"),"",_xlpm.result)) -> 602063 | I6: ="" | J6: =A6&";"&B6&";"&C6&";"&D6&";"&E6&";"&F6&";"&G6&";"&H6&";"&I6 -> A9;GPP_E_9_USB2_OCB_0;;4.64999999999999;0;504125;808055;602063;
A7: A10 | B7: =_xlfn.XLOOKUP(A7,'Pinlist(S1)'!$Q$4:$Q$1362,'Pinlist(S1)'!$R$4:$R$1362,"") -> VCC24TBT_1P0 | C7: {=_xlfn.TEXTJOIN(",",TRUE,_xlfn.UNIQUE(TRANSPOSE(_xlfn.MAP(_xlfn.XLOOKUP(A7,'Pinlist(S1)'!$C$4:$C$1362,'Pinlist(S1)'!$F$4:$K$1362,""),_xlfn.LAMBDA(_xlpm.x,IF(_xlpm.x<>"",TRIM(CLEAN(LEFT(_xlpm.x,FIND(".",_xlpm.x & ".")-1))),""))))))} | D7: 5.325 | E7: 0.325 | F7: =_xlfn.LET(_xlpm.raw,_xlfn.XLOOKUP(A7,'Pinlist(S1)'!$C$4:$C$1362,'Pinlist(S1)'!$E$4:$E$1362,""),_xlpm.cleanRaw,SUBSTITUTE(SUBSTITUTE(_xlpm.raw,"_PIN","."),"PIN","."),_xlpm.mainPart,MID(_xlpm.cleanRaw,2,FIND(".",_xlpm.cleanRaw & ".")-2),_xlpm.subPart,MID(_xlpm.cleanRaw,FIND(".",_xlpm.cleanRaw & ".")+1,99),_xlpm.result,RIGHT(_xlpm.mainPart,LEN(_xlpm.mainPart)-1)& TEXT(_xlpm.subPart,"000"),IF(OR(_xlpm.raw="",_xlpm.raw="-"),"",_xlpm.result)) | G7: =_xlfn.LET(_xlpm.raw,_xlfn.XLOOKUP(A7,'Pinlist(S3)'!$C$4:$C$1362,'Pinlist(S3)'!$E$4:$E$1362,""),_xlpm.cleanRaw,SUBSTITUTE(SUBSTITUTE(_xlpm.raw,"_PIN","."),"PIN","."),_xlpm.mainPart,MID(_xlpm.cleanRaw,2,FIND(".",_xlpm.cleanRaw & ".")-2),_xlpm.subPart,MID(_xlpm.cleanRaw,FIND(".",_xlpm.cleanRaw & ".")+1,99),_xlpm.result,RIGHT(_xlpm.mainPart,LEN(_xlpm.mainPart)-1)& TEXT(_xlpm.subPart,"000"),IF(OR(_xlpm.raw="",_xlpm.raw="-"),"",_xlpm.result)) | H7: =_xlfn.LET(_xlpm.raw,_xlfn.XLOOKUP(A7,'Pinlist(S5)'!$C$4:$C$1362,'Pinlist(S5)'!$E$4:$E$1362,""),_xlpm.cleanRaw,SUBSTITUTE(SUBSTITUTE(_xlpm.raw,"_PIN","."),"PIN","."),_xlpm.mainPart,MID(_xlpm.cleanRaw,2,FIND(".",_xlpm.cleanRaw & ".")-2),_xlpm.subPart,MID(_xlpm.cleanRaw,FIND(".",_xlpm.cleanRaw & ".")+1,99),_xlpm.result,RIGHT(_xlpm.mainPart,LEN(_xlpm.mainPart)-1)& TEXT(_xlpm.subPart,"000"),IF(OR(_xlpm.raw="",_xlpm.raw="-"),"",_xlpm.result)) | I7: ="" | J7: =A7&";"&B7&";"&C7&";"&D7&";"&E7&";"&F7&";"&G7&";"&H7&";"&I7 -> A10;VCC24TBT_1P0;;5.325;0.324999999999999;;;;
A8: A11 | B8: =_xlfn.XLOOKUP(A8,'Pinlist(S1)'!$Q$4:$Q$1362,'Pinlist(S1)'!$R$4:$R$1362,"") -> SPARE_13 | C8: {=_xlfn.TEXTJOIN(",",TRUE,_xlfn.UNIQUE(TRANSPOSE(_xlfn.MAP(_xlfn.XLOOKUP(A8,'Pinlist(S1)'!$C$4:$C$1362,'Pinlist(S1)'!$F$4:$K$1362,""),_xlfn.LAMBDA(_xlpm.x,IF(_xlpm.x<>"",TRIM(CLEAN(LEFT(_xlpm.x,FIND(".",_xlpm.x & ".")-1))),""))))))} | D8: 6.001 | E8: 0 | F8: =_xlfn.LET(_xlpm.raw,_xlfn.XLOOKUP(A8,'Pinlist(S1)'!$C$4:$C$1362,'Pinlist(S1)'!$E$4:$E$1362,""),_xlpm.cleanRaw,SUBSTITUTE(SUBSTITUTE(_xlpm.raw,"_PIN","."),"PIN","."),_xlpm.mainPart,MID(_xlpm.cleanRaw,2,FIND(".",_xlpm.cleanRaw & ".")-2),_xlpm.subPart,MID(_xlpm.cleanRaw,FIND(".",_xlpm.cleanRaw & ".")+1,99),_xlpm.result,RIGHT(_xlpm.mainPart,LEN(_xlpm.mainPart)-1)& TEXT(_xlpm.subPart,"000"),IF(OR(_xlpm.raw="",_xlpm.raw="-"),"",_xlpm.result)) | G8: =_xlfn.LET(_xlpm.raw,_xlfn.XLOOKUP(A8,'Pinlist(S3)'!$C$4:$C$1362,'Pinlist(S3)'!$E$4:$E$1362,""),_xlpm.cleanRaw,SUBSTITUTE(SUBSTITUTE(_xlpm.raw,"_PIN","."),"PIN","."),_xlpm.mainPart,MID(_xlpm.cleanRaw,2,FIND(".",_xlpm.cleanRaw & ".")-2),_xlpm.subPart,MID(_xlpm.cleanRaw,FIND(".",_xlpm.cleanRaw & ".")+1,99),_xlpm.result,RIGHT(_xlpm.mainPart,LEN(_xlpm.mainPart)-1)& TEXT(_xlpm.subPart,"000"),IF(OR(_xlpm.raw="",_xlpm.raw="-"),"",_xlpm.result)) | H8: =_xlfn.LET(_xlpm.raw,_xlfn.XLOOKUP(A8,'Pinlist(S5)'!$C$4:$C$1362,'Pinlist(S5)'!$E$4:$E$1362,""),_xlpm.cleanRaw,SUBSTITUTE(SUBSTITUTE(_xlpm.raw,"_PIN","."),"PIN","."),_xlpm.mainPart,MID(_xlpm.cleanRaw,2,FIND(".",_xlpm.cleanRaw & ".")-2),_xlpm.subPart,MID(_xlpm.cleanRaw,FIND(".",_xlpm.cleanRaw & ".")+1,99),_xlpm.result,RIGHT(_xlpm.mainPart,LEN(_xlpm.mainPart)-1)& TEXT(_xlpm.subPart,"000"),IF(OR(_xlpm.raw="",_xlpm.raw="-"),"",_xlpm.result)) | I8: ="" | J8: =A8&";"&B8&";"&C8&";"&D8&";"&E8&";"&F8&";"&G8&";"&H8&";"&I8 -> A11;SPARE_13;;6.00099999999999;0;;;;
A9: A13 | B9: =_xlfn.XLOOKUP(A9,'Pinlist(S1)'!$Q$4:$Q$1362,'Pinlist(S1)'!$R$4:$R$1362,"") -> USB3_2_SSIC_1_TXP | C9: {=_xlfn.TEXTJOIN(",",TRUE,_xlfn.UNIQUE(TRANSPOSE(_xlfn.MAP(_xlfn.XLOOKUP(A9,'Pinlist(S1)'!$C$4:$C$1362,'Pinlist(S1)'!$F$4:$K$1362,""),_xlfn.LAMBDA(_xlpm.x,IF(_xlpm.x<>"",TRIM(CLEAN(LEFT(_xlpm.x,FIND(".",_xlpm.x & ".")-1))),""))))))} -> LA528,CA528,KA514 | D9: 7.128 | E9: 0 | F9: =_xlfn.LET(_xlpm.raw,_xlfn.XLOOKUP(A9,'Pinlist(S1)'!$C$4:$C$1362,'Pinlist(S1)'!$E$4:$E$1362,""),_xlpm.cleanRaw,SUBSTITUTE(SUBSTITUTE(_xlpm.raw,"_PIN","."),"PIN","."),_xlpm.mainPart,MID(_xlpm.cleanRaw,2,FIND(".",_xlpm.cleanRaw & ".")-2),_xlpm.subPart,MID(_xlpm.cleanRaw,FIND(".",_xlpm.cleanRaw & ".")+1,99),_xlpm.result,RIGHT(_xlpm.mainPart,LEN(_xlpm.mainPart)-1)& TEXT(_xlpm.subPart,"000"),IF(OR(_xlpm.raw="",_xlpm.raw="-"),"",_xlpm.result)) -> 506031 | G9: =_xlfn.LET(_xlpm.raw,_xlfn.XLOOKUP(A9,'Pinlist(S3)'!$C$4:$C$1362,'Pinlist(S3)'!$E$4:$E$1362,""),_xlpm.cleanRaw,SUBSTITUTE(SUBSTITUTE(_xlpm.raw,"_PIN","."),"PIN","."),_xlpm.mainPart,MID(_xlpm.cleanRaw,2,FIND(".",_xlpm.cleanRaw & ".")-2),_xlpm.subPart,MID(_xlpm.cleanRaw,FIND(".",_xlpm.cleanRaw & ".")+1,99),_xlpm.result,RIGHT(_xlpm.mainPart,LEN(_xlpm.mainPart)-1)& TEXT(_xlpm.subPart,"000"),IF(OR(_xlpm.raw="",_xlpm.raw="-"),"",_xlpm.result)) -> 807027 | H9: =_xlfn.LET(_xlpm.raw,_xlfn.XLOOKUP(A9,'Pinlist(S5)'!$C$4:$C$1362,'Pinlist(S5)'!$E$4:$E$1362,""),_xlpm.cleanRaw,SUBSTITUTE(SUBSTITUTE(_xlpm.raw,"_PIN","."),"PIN","."),_xlpm.mainPart,MID(_xlpm.cleanRaw,2,FIND(".",_xlpm.cleanRaw & ".")-2),_xlpm.subPart,MID(_xlpm.cleanRaw,FIND(".",_xlpm.cleanRaw & ".")+1,99),_xlpm.result,RIGHT(_xlpm.mainPart,LEN(_xlpm.mainPart)-1)& TEXT(_xlpm.subPart,"000"),IF(OR(_xlpm.raw="",_xlpm.raw="-"),"",_xlpm.result)) -> 603096 | I9: ="" | J9: =A9&";"&B9&";"&C9&";"&D9&";"&E9&";"&F9&";"&G9&";"&H9&";"&I9 -> A13;USB3_2_SSIC_1_TXP;LA528,CA528,KA514;7.128;0;506031;807027;603096;
A10: A14 | B10: =_xlfn.XLOOKUP(A10,'Pinlist(S1)'!$Q$4:$Q$1362,'Pinlist(S1)'!$R$4:$R$1362,"") -> VCC19P2_1P0 | C10: {=_xlfn.TEXTJOIN(",",TRUE,_xlfn.UNIQUE(TRANSPOSE(_xlfn.MAP(_xlfn.XLOOKUP(A10,'Pinlist(S1)'!$C$4:$C$1362,'Pinlist(S1)'!$F$4:$K$1362,""),_xlfn.LAMBDA(_xlpm.x,IF(_xlpm.x<>"",TRIM(CLEAN(LEFT(_xlpm.x,FIND(".",_xlpm.x & ".")-1))),""))))))} | D10: 7.803 | E10: 0.325 | F10: =_xlfn.LET(_xlpm.raw,_xlfn.XLOOKUP(A10,'Pinlist(S1)'!$C$4:$C$1362,'Pinlist(S1)'!$E$4:$E$1362,""),_xlpm.cleanRaw,SUBSTITUTE(SUBSTITUTE(_xlpm.raw,"_PIN","."),"PIN","."),_xlpm.mainPart,MID(_xlpm.cleanRaw,2,FIND(".",_xlpm.cleanRaw & ".")-2),_xlpm.subPart,MID(_xlpm.cleanRaw,FIND(".",_xlpm.cleanRaw & ".")+1,99),_xlpm.result,RIGHT(_xlpm.mainPart,LEN(_xlpm.mainPart)-1)& TEXT(_xlpm.subPart,"000"),IF(OR(_xlpm.raw="",_xlpm.raw="-"),"",_xlpm.result)) | G10: =_xlfn.LET(_xlpm.raw,_xlfn.XLOOKUP(A10,'Pinlist(S3)'!$C$4:$C$1362,'Pinlist(S3)'!$E$4:$E$1362,""),_xlpm.cleanRaw,SUBSTITUTE(SUBSTITUTE(_xlpm.raw,"_PIN","."),"PIN","."),_xlpm.mainPart,MID(_xlpm.cleanRaw,2,FIND(".",_xlpm.cleanRaw & ".")-2),_xlpm.subPart,MID(_xlpm.cleanRaw,FIND(".",_xlpm.cleanRaw & ".")+1,99),_xlpm.result,RIGHT(_xlpm.mainPart,LEN(_xlpm.mainPart)-1)& TEXT(_xlpm.subPart,"000"),IF(OR(_xlpm.raw="",_xlpm.raw="-"),"",_xlpm.result)) | H10: =_xlfn.LET(_xlpm.raw,_xlfn.XLOOKUP(A10,'Pinlist(S5)'!$C$4:$C$1362,'Pinlist(S5)'!$E$4:$E$1362,""),_xlpm.cleanRaw,SUBSTITUTE(SUBSTITUTE(_xlpm.raw,"_PIN","."),"PIN","."),_xlpm.mainPart,MID(_xlpm.cleanRaw,2,FIND(".",_xlpm.cleanRaw & ".")-2),_xlpm.subPart,MID(_xlpm.cleanRaw,FIND(".",_xlpm.cleanRaw & ".")+1,99),_xlpm.result,RIGHT(_xlpm.mainPart,LEN(_xlpm.mainPart)-1)& TEXT(_xlpm.subPart,"000"),IF(OR(_xlpm.raw="",_xlpm.raw="-"),"",_xlpm.result)) | I10: ="" | J10: =A10&";"&B10&";"&C10&";"&D10&";"&E10&";"&F10&";"&G10&";"&H10&";"&I10 -> A14;VCC19P2_1P0;;7.80299999999999;0.324999999999999;;;;
A11: A15 | B11: =_xlfn.XLOOKUP(A11,'Pinlist(S1)'!$Q$4:$Q$1362,'Pinlist(S1)'!$R$4:$R$1362,"") -> USB3_3_SSIC_2_TXP | C11: {=_xlfn.TEXTJOIN(",",TRUE,_xlfn.UNIQUE(TRANSPOSE(_xlfn.MAP(_xlfn.XLOOKUP(A11,'Pinlist(S1)'!$C$4:$C$1362,'Pinlist(S1)'!$F$4:$K$1362,""),_xlfn.LAMBDA(_xlpm.x,IF(_xlpm.x<>"",TRIM(CLEAN(LEFT(_xlpm.x,FIND(".",_xlpm.x & ".")-1))),""))))))} -> LA530,CA530,KA515 | D11: 8.479 | E11: 0 | F11: =_xlfn.LET(_xlpm.raw,_xlfn.XLOOKUP(A11,'Pinlist(S1)'!$C$4:$C$1362,'Pinlist(S1)'!$E$4:$E$1362,""),_xlpm.cleanRaw,SUBSTITUTE(SUBSTITUTE(_xlpm.raw,"_PIN","."),"PIN","."),_xlpm.mainPart,MID(_xlpm.cleanRaw,2,FIND(".",_xlpm.cleanRaw & ".")-2),_xlpm.subPart,MID(_xlpm.cleanRaw,FIND(".",_xlpm.cleanRaw & ".")+1,99),_xlpm.result,RIGHT(_xlpm.mainPart,LEN(_xlpm.mainPart)-1)& TEXT(_xlpm.subPart,"000"),IF(OR(_xlpm.raw="",_xlpm.raw="-"),"",_xlpm.result)) -> 504092 | G11: =_xlfn.LET(_xlpm.raw,_xlfn.XLOOKUP(A11,'Pinlist(S3)'!$C$4:$C$1362,'Pinlist(S3)'!$E$4:$E$1362,""),_xlpm.cleanRaw,SUBSTITUTE(SUBSTITUTE(_xlpm.raw,"_PIN","."),"PIN","."),_xlpm.mainPart,MID(_xlpm.cleanRaw,2,FIND(".",_xlpm.cleanRaw & ".")-2),_xlpm.subPart,MID(_xlpm.cleanRaw,FIND(".",_xlpm.cleanRaw & ".")+1,99),_xlpm.result,RIGHT(_xlpm.mainPart,LEN(_xlpm.mainPart)-1)& TEXT(_xlpm.subPart,"000"),IF(OR(_xlpm.raw="",_xlpm.raw="-"),"",_xlpm.result)) -> 807039 | H11: =_xlfn.LET(_xlpm.raw,_xlfn.XLOOKUP(A11,'Pinlist(S5)'!$C$4:$C$1362,'Pinlist(S5)'!$E$4:$E$1362,""),_xlpm.cleanRaw,SUBSTITUTE(SUBSTITUTE(_xlpm.raw,"_PIN","."),"PIN","."),_xlpm.mainPart,MID(_xlpm.cleanRaw,2,FIND(".",_xlpm.cleanRaw & ".")-2),_xlpm.subPart,MID(_xlpm.cleanRaw,FIND(".",_xlpm.cleanRaw & ".")+1,99),_xlpm.result,RIGHT(_xlpm.mainPart,LEN(_xlpm.mainPart)-1)& TEXT(_xlpm.subPart,"000"),IF(OR(_xlpm.raw="",_xlpm.raw="-"),"",_xlpm.result)) -> 603101 | I11: ="" | J11: =A11&";"&B11&";"&C11&";"&D11&";"&E11&";"&F11&";"&G11&";"&H11&";"&I11 -> A15;USB3_3_SSIC_2_TXP;LA530,CA530,KA515;8.479;0;504092;807039;603101;
A12: A17 | B12: =_xlfn.XLOOKUP(A12,'Pinlist(S1)'!$Q$4:$Q$1362,'Pinlist(S1)'!$R$4:$R$1362,"") -> PCIE_1_USB3_5_TXP | C12: {=_xlfn.TEXTJOIN(",",TRUE,_xlfn.UNIQUE(TRANSPOSE(_xlfn.MAP(_xlfn.XLOOKUP(A12,'Pinlist(S1)'!$C$4:$C$1362,'Pinlist(S1)'!$F$4:$K$1362,""),_xlfn.LAMBDA(_xlpm.x,IF(_xlpm.x<>"",TRIM(CLEAN(LEFT(_xlpm.x,FIND(".",_xlpm.x & ".")-1))),""))))))} -> LA502,CA502,KA501 | D12: 9.606 | E12: 0 | F12: =_xlfn.LET(_xlpm.raw,_xlfn.XLOOKUP(A12,'Pinlist(S1)'!$C$4:$C$1362,'Pinlist(S1)'!$E$4:$E$1362,""),_xlpm.cleanRaw,SUBSTITUTE(SUBSTITUTE(_xlpm.raw,"_PIN","."),"PIN","."),_xlpm.mainPart,MID(_xlpm.cleanRaw,2,FIND(".",_xlpm.cleanRaw & ".")-2),_xlpm.subPart,MID(_xlpm.cleanRaw,FIND(".",_xlpm.cleanRaw & ".")+1,99),_xlpm.result,RIGHT(_xlpm.mainPart,LEN(_xlpm.mainPart)-1)& TEXT(_xlpm.subPart,"000"),IF(OR(_xlpm.raw="",_xlpm.raw="-"),"",_xlpm.result)) -> 506036 | G12: =_xlfn.LET(_xlpm.raw,_xlfn.XLOOKUP(A12,'Pinlist(S3)'!$C$4:$C$1362,'Pinlist(S3)'!$E$4:$E$1362,""),_xlpm.cleanRaw,SUBSTITUTE(SUBSTITUTE(_xlpm.raw,"_PIN","."),"PIN","."),_xlpm.mainPart,MID(_xlpm.cleanRaw,2,FIND(".",_xlpm.cleanRaw & ".")-2),_xlpm.subPart,MID(_xlpm.cleanRaw,FIND(".",_xlpm.cleanRaw & ".")+1,99),_xlpm.result,RIGHT(_xlpm.mainPart,LEN(_xlpm.mainPart)-1)& TEXT(_xlpm.subPart,"000"),IF(OR(_xlpm.raw="",_xlpm.raw="-"),"",_xlpm.result)) -> 807031 | H12: =_xlfn.LET(_xlpm.raw,_xlfn.XLOOKUP(A12,'Pinlist(S5)'!$C$4:$C$1362,'Pinlist(S5)'!$E$4:$E$1362,""),_xlpm.cleanRaw,SUBSTITUTE(SUBSTITUTE(_xlpm.raw,"_PIN","."),"PIN","."),_xlpm.mainPart,MID(_xlpm.cleanRaw,2,FIND(".",_xlpm.cleanRaw & ".")-2),_xlpm.subPart,MID(_xlpm.cleanRaw,FIND(".",_xlpm.cleanRaw & ".")+1,99),_xlpm.result,RIGHT(_xlpm.mainPart,LEN(_xlpm.mainPart)-1)& TEXT(_xlpm.subPart,"000"),IF(OR(_xlpm.raw="",_xlpm.raw="-"),"",_xlpm.result)) -> 603090 | I12: ="" | J12: =A12&";"&B12&";"&C12&";"&D12&";"&E12&";"&F12&";"&G12&";"&H12&";"&I12 -> A17;PCIE_1_USB3_5_TXP;LA502,CA502,KA501;9.606;0;506036;807031;603090;
... A1358: BB70 | B1358: =_xlfn.XLOOKUP(A1358,'Pinlist(S1)'!$Q$4:$Q$1362,'Pinlist(S1)'!$R$4:$R$1362,"") -> VSS | C1358: {=_xlfn.TEXTJOIN(",",TRUE,_xlfn.UNIQUE(TRANSPOSE(_xlfn.MAP(_xlfn.XLOOKUP(A1358,'Pinlist(S1)'!$C$4:$C$1362,'Pinlist(S1)'!$F$4:$K$1362,""),_xlfn.LAMBDA(_xlpm.x,IF(_xlpm.x<>"",TRIM(CLEAN(LEFT(_xlpm.x,FIND(".",_xlpm.x & ".")-1))),""))))))} | D1358: 40.166 | E1358: 22.628 | F1358: =_xlfn.LET(_xlpm.raw,_xlfn.XLOOKUP(A1358,'Pinlist(S1)'!$C$4:$C$1362,'Pinlist(S1)'!$E$4:$E$1362,""),_xlpm.cleanRaw,SUBSTITUTE(SUBSTITUTE(_xlpm.raw,"_PIN","."),"PIN","."),_xlpm.mainPart,MID(_xlpm.cleanRaw,2,FIND(".",_xlpm.cleanRaw & ".")-2),_xlpm.subPart,MID(_xlpm.cleanRaw,FIND(".",_xlpm.cleanRaw & ".")+1,99),_xlpm.result,RIGHT(_xlpm.mainPart,LEN(_xlpm.mainPart)-1)& TEXT(_xlpm.subPart,"000"),IF(OR(_xlpm.raw="",_xlpm.raw="-"),"",_xlpm.result)) | G1358: =_xlfn.LET(_xlpm.raw,_xlfn.XLOOKUP(A1358,'Pinlist(S3)'!$C$4:$C$1362,'Pinlist(S3)'!$E$4:$E$1362,""),_xlpm.cleanRaw,SUBSTITUTE(SUBSTITUTE(_xlpm.raw,"_PIN","."),"PIN","."),_xlpm.mainPart,MID(_xlpm.cleanRaw,2,FIND(".",_xlpm.cleanRaw & ".")-2),_xlpm.subPart,MID(_xlpm.cleanRaw,FIND(".",_xlpm.cleanRaw & ".")+1,99),_xlpm.result,RIGHT(_xlpm.mainPart,LEN(_xlpm.mainPart)-1)& TEXT(_xlpm.subPart,"000"),IF(OR(_xlpm.raw="",_xlpm.raw="-"),"",_xlpm.result)) | H1358: =_xlfn.LET(_xlpm.raw,_xlfn.XLOOKUP(A1358,'Pinlist(S5)'!$C$4:$C$1362,'Pinlist(S5)'!$E$4:$E$1362,""),_xlpm.cleanRaw,SUBSTITUTE(SUBSTITUTE(_xlpm.raw,"_PIN","."),"PIN","."),_xlpm.mainPart,MID(_xlpm.cleanRaw,2,FIND(".",_xlpm.cleanRaw & ".")-2),_xlpm.subPart,MID(_xlpm.cleanRaw,FIND(".",_xlpm.cleanRaw & ".")+1,99),_xlpm.result,RIGHT(_xlpm.mainPart,LEN(_xlpm.mainPart)-1)& TEXT(_xlpm.subPart,"000"),IF(OR(_xlpm.raw="",_xlpm.raw="-"),"",_xlpm.result)) | I1358: ="" | J1358: =A1358&";"&B1358&";"&C1358&";"&D1358&";"&E1358&";"&F1358&";"&G1358&";"&H1358&";"&I1358 -> BB70;VSS;;40.166;22.628;;;;

Sheet Pinlist(S1)
B1: ITTO-620-0089 SKL ULT 2+2 X6 | O1: 41787 | R1: ULT 2+2 | S1: Avaliable | U1: 192 | V1: 64 | W1: ULX | X1: 256
S2: Used | U2: 191 | V2: 64 | X2: 256 | Z2: 0
A3: Sort | B3: Function | C3: Land# | D3: Channel/Tester No | F3: Components | L3: Minor Length | M3: Major Length | N3: Total Length | O3: Trace Layer | P3: Sort | Q3: XY | R3: PIN NAME | S3: DIE | T3: Power supply | U3: DDR TD | V3: Legacy TD | W3: NET | X3: PCH | Z3: Coment
A4: 1 | B4: D1_TC_SH60_TD01__AZA_BCLK_SSP0_SCLK__GPP_F_14_EMMC_DATA1__TC | C4: AY22 | D4: J1509.DS8 | E4: J1509.010 | F4: KA142.6 | G4: KA142.8 | L4: 6664.2638 | M4: 12255.831 | N4: 18920.094 | O4: L13_INT2_HS2/L13_INT2_HS2 | P4: 1 | Q4: AY22 | R4: AZA_BCLK_SSP0_SCLK | S4: PCH | W4: AZA_BCLK_SSP0_SCLK | X4: 1 | Z4: PCH-PCH relay with GPP_F_14
A5: 2 | B5: - | C5: BA4 | P5: 2 | Q5: BA4 | R5: AZA_PLLMON_N | S5: PCH | W5: AZA_PLLMON_N | X5: 0
A6: 3 | B6: - | C6: BB4 | P6: 3 | Q6: BB4 | R6: AZA_PLLMON_P | S6: PCH | W6: AZA_PLLMON_P | X6: 0
A7: 4 | B7: D1_TC_SH64_TD01__AZA_RSTB_SSP1_SCLK__GPP_F_16_EMMC_DATA3__TC | C7: AW22 | D7: J1509.DS6 | E7: J1509.014 | F7: KA144.6 | G7: KA144.8 | L7: 7406.2323 | M7: 9841.185 | N7: 17247.417 | O7: L15_INT3_HS3/L13_INT2_HS2 | P7: 4 | Q7: AW22 | R7: AZA_RSTB_SSP1_SCLK | S7: PCH | W7: AZA_RSTB_SSP1_SCLK | X7: 1 | Z7: PCH-PCH relay with GPP_F_16
A8: 5 | B8: D1_TC_SH56_TD01__AZA_SDI_0_SSP0_RXD__GPP_F_12_EMMC_CMD__TC | C8: BA21 | D8: J1509.BS9 | E8: J1509.037 | F8: KA140.6 | G8: KA140.8 | L8: 6046.9409 | M8: 13203.13 | N8: 19250.071 | O8: L17_INT4_HS4/L13_INT2_HS2 | P8: 5 | Q8: BA21 | R8: AZA_SDI_0_SSP0_RXD | S8: PCH | W8: AZA_SDI_0_SSP0_RXD | X8: 1 | Z8: PCH-PCH relay with GPP_F_12
A9: 6 | B9: D1_TC_SH66_TD01__AZA_SDI_1_SSP1_RXD__GPP_G_2_SD_DATA1__TC | C9: AY21 | D9: J1508.CS10 | E9: J1508.049 | F9: KA145.6 | G9: KA145.8 | L9: 4256.0079 | M9: 10361.984 | N9: 14617.992 | O9: L13_INT2_HS2/L13_INT2_HS2 | P9: 6 | Q9: AY21 | R9: AZA_SDI_1_SSP1_RXD | S9: PCH | W9: AZA_SDI_1_SSP1_RXD | X9: 1 | Z9: PCH-PCH relay with GPP_G_2
A10: 7 | B10: D1_TC_SH58_TD01__AZA_SDO_SSP0_TXD__GPP_F_13_EMMC_DATA0__TC | C10: BB22 | D10: J1509.BS8 | E10: J1509.035 | F10: KA141.6 | G10: KA141.8 | L10: 3244.5787 | M10: 15883.736 | N10: 19128.315 | O10: L17_INT4_HS4/L17_INT4_HS4 | P10: 7 | Q10: BB22 | R10: AZA_SDO_SSP0_TXD | S10: PCH | W10: AZA_SDO_SSP0_TXD | X10: 1 | Z10: PCH-PCH relay with GPP_F_13
A11: 8 | B11: D1_TC_SH62_TD01__AZA_SYNC_SSP0_SFRM__GPP_F_15_EMMC_DATA2__TC | C11: BA22 | D11: J1509.CS4 | E11: J1509.015 | F11: KA143.6 | G11: KA143.8 | L11: 6683.2913 | M11: 9135.5669 | N11: 15818.858 | O11: L15_INT3_HS3/L17_INT4_HS4 | P11: 8 | Q11: BA22 | R11: AZA_SYNC_SSP0_SFRM | S11: PCH | W11: AZA_SYNC_SSP0_SFRM | X11: 1 | Z11: PCH-PCH relay with GPP_F_15
A12: 9 | B12: D1_TC_TD03__CATERR_N | C12: D63 | D12: J1605.CS11 | E12: J1605.047 | M12: 6077.3858 | N12: 6077.3858 | O12: L19_INT5 | P12: 9 | Q12: D63 | R12: CATERR_N | S12: CPU | V12: 1 | W12: CATERR_N | X12: 0
A13: 10 | B13: D1_TC_DP117_SH29_TD01__CLKOUT_ITPXDP_N__DDR0_DDR1_CKE0__TC | C13: F43 | D13: J1508.DS14 | E13: J1508.042 | F13: TPA101.1 | G13: KA101.4 | H13: KA101.2 | L13: 4605.1496 | M13: 9920.063 | N13: 14525.213 | O13: L17_INT4_HS4/L13_INT2_HS2 | P13: 10 | Q13: F43 | R13: CLKOUT_ITPXDP_N | S13: PCH | W13: CLKOUT_ITPXDP_N | X13: 1
A14: 11 | B14: D1_TC_DP117_SH30_TD01__CLKOUT_ITPXDP_P__DDR0_DDR1_CKE1__TC | C14: E43 | D14: J1508.CS14 | E14: J1508.041 | F14: TPA102.1 | G14: KA101.6 | H14: KA101.8 | L14: 4605.1339 | M14: 9920.0906 | N14: 14525.224 | O14: L17_INT4_HS4/L13_INT2_HS2 | P14: 11 | Q14: E43 | R14: CLKOUT_ITPXDP_P | S14: PCH | W14: CLKOUT_ITPXDP_P | X14: 1
A15: 12 | B15: D1_TC_SH31_TD01__CLKOUT_SRC_N_0_5__DDR0_DDR1_CKE2__TC | C15: D42 | D15: J1505.BS6 | E15: J1505.075 | F15: TPA103.1 | G15: KA102.4 | H15: KA102.2 | L15: 6494.9252 | M15: 13778.933 | N15: 20273.858 | O15: L15_INT3_HS3/L11_INT1_HS1 | P15: 12 | Q15: D42 | R15: CLKOUT_SRC_N_0 | S15: PCH | X15: 1 | Z15: Y-conntion: N[0:5]
A16: 13 | B16: D1_TC_SH31_TD01__CLKOUT_SRC_N_0_5__DDR0_DDR1_CKE2__TC | C16: B42 | D16: J1505.BS6 | E16: J1505.075 | F16: TPA103.1 | G16: KA102.4 | H16: KA102.2 | L16: 6494.9252 | M16: 13778.933 | N16: 20273.858 | O16: L15_INT3_HS3/L11_INT1_HS1 | P16: 13 | Q16: B42 | R16: CLKOUT_SRC_N_1 | S16: PCH | W16: CLKOUT_SRC_N_1 | X16: 0 | Z16: Y-conntion: N[0:5]
A17: 14 | B17: D1_TC_SH31_TD01__CLKOUT_SRC_N_0_5__DDR0_DDR1_CKE2__TC | C17: D41 | D17: J1505.BS6 | E17: J1505.075 | F17: TPA103.1 | G17: KA102.4 | H17: KA102.2 | L17: 6494.9252 | M17: 13778.933 | N17: 20273.858 | O17: L15_INT3_HS3/L11_INT1_HS1 | P17: 14 | Q17: D41 | R17: CLKOUT_SRC_N_2 | S17: PCH | W17: CLKOUT_SRC_N_2 | X17: 0 | Z17: Y-conntion: N[0:5]
A18: 15 | B18: D1_TC_SH31_TD01__CLKOUT_SRC_N_0_5__DDR0_DDR1_CKE2__TC | C18: D40 | D18: J1505.BS6 | E18: J1505.075 | F18: TPA103.1 | G18: KA102.4 | H18: KA102.2 | L18: 6494.9252 | M18: 13778.933 | N18: 20273.858 | O18: L15_INT3_HS3/L11_INT1_HS1 | P18: 15 | Q18: D40 | R18: CLKOUT_SRC_N_3 | S18: PCH | W18: CLKOUT_SRC_N_3 | X18: 0 | Z18: Y-conntion: N[0:5]
A19: 16 | B19: D1_TC_SH31_TD01__CLKOUT_SRC_N_0_5__DDR0_DDR1_CKE2__TC | C19: B40 | D19: J1505.BS6 | E19: J1505.075 | F19: TPA103.1 | G19: KA102.4 | H19: KA102.2 | L19: 6494.9252 | M19: 13778.933 | N19: 20273.858 | O19: L15_INT3_HS3/L11_INT1_HS1 | P19: 16 | Q19: B40 | R19: CLKOUT_SRC_N_4 | S19: PCH | W19: CLKOUT_SRC_N_4 | X19: 0 | Z19: Y-conntion: N[0:5]
A20: 17 | B20: D1_TC_SH31_TD01__CLKOUT_SRC_N_0_5__DDR0_DDR1_CKE2__TC | C20: E40 | D20: J1505.BS6 | E20: J1505.075 | F20: TPA103.1 | G20: KA102.4 | H20: KA102.2 | L20: 6494.9252 | M20: 13778.933 | N20: 20273.858 | O20: L15_INT3_HS3/L11_INT1_HS1 | P20: 17 | Q20: E40 | R20: CLKOUT_SRC_N_5 | S20: PCH | W20: CLKOUT_SRC_N_5 | X20: 0 | Z20: Y-conntion: N[0:5]
A21: 18 | B21: D1_TC_SH32_TD01__CLKOUT_SRC_P_0_5__DDR0_DDR1_CKE3__TC | C21: C42 | D21: J1505.CS4 | E21: J1505.059 | F21: TPA104.1 | G21: KA102.6 | H21: KA102.8 | L21: 6494.9606 | M21: 13778.5 | N21: 20273.461 | O21: L26_INT7/L11_INT1_HS1 | P21: 18 | Q21: C42 | R21: CLKOUT_SRC_P_0 | S21: PCH | W21: CLKOUT_SRC_P_1 | X21: 1 | Z21: Y-conntion: P[0:5]
A22: 19 | B22: D1_TC_SH32_TD01__CLKOUT_SRC_P_0_5__DDR0_DDR1_CKE3__TC | C22: A42 | D22: J1505.CS4 | E22: J1505.059 | F22: TPA104.1 | G22: KA102.6 | H22: KA102.8 | L22: 6494.9606 | M22: 13778.5 | N22: 20273.461 | O22: L26_INT7/L11_INT1_HS1 | P22: 19 | Q22: A42 | R22: CLKOUT_SRC_P_1 | S22: PCH | W22: CLKOUT_SRC_P_2 | X22: 0 | Z22: Y-conntion: P[0:5]
A23: 20 | B23: D1_TC_SH32_TD01__CLKOUT_SRC_P_0_5__DDR0_DDR1_CKE3__TC | C23: C41 | D23: J1505.CS4 | E23: J1505.059 | F23: TPA104.1 | G23: KA102.6 | H23: KA102.8 | L23: 6494.9606 | M23: 13778.5 | N23: 20273.461 | O23: L26_INT7/L11_INT1_HS1 | P23: 20 | Q23: C41 | R23: CLKOUT_SRC_P_2 | S23: PCH | W23: CLKOUT_SRC_P_3 | X23: 0 | Z23: Y-conntion: P[0:5]
A24: 21 | B24: D1_TC_SH32_TD01__CLKOUT_SRC_P_0_5__DDR0_DDR1_CKE3__TC | C24: C40 | D24: J1505.CS4 | E24: J1505.059 | F24: TPA104.1 | G24: KA102.6 | H24: KA102.8 | L24: 6494.9606 | M24: 13778.5 | N24: 20273.461 | O24: L26_INT7/L11_INT1_HS1 | P24: 21 | Q24: C40 | R24: CLKOUT_SRC_P_3 | S24: PCH | W24: CLKOUT_SRC_P_4 | X24: 0 | Z24: Y-conntion: P[0:5]
A25: 22 | B25: D1_TC_SH32_TD01__CLKOUT_SRC_P_0_5__DDR0_DDR1_CKE3__TC | C25: A40 | D25: J1505.CS4 | E25: J1505.059 | F25: TPA104.1 | G25: KA102.6 | H25: KA102.8 | L25: 6494.9606 | M25: 13778.5 | N25: 20273.461 | O25: L26_INT7/L11_INT1_HS1 | P25: 22 | Q25: A40 | R25: CLKOUT_SRC_P_4 | S25: PCH | W25: CLKOUT_SRC_P_5 | X25: 0 | Z25: Y-conntion: P[0:5]
A26: 23 | B26: D1_TC_SH32_TD01__CLKOUT_SRC_P_0_5__DDR0_DDR1_CKE3__TC | C26: E38 | D26: J1505.CS4 | E26: J1505.059 | F26: TPA104.1 | G26: KA102.6 | H26: KA102.8 | L26: 6494.9606 | M26: 13778.5 | N26: 20273.461 | O26: L26_INT7/L11_INT1_HS1 | P26: 23 | Q26: E38 | R26: CLKOUT_SRC_P_5 | S26: PCH | W26: CPU_EDM[0] | X26: 0 | Z26: Y-conntion: P[0:5]
A27: 24 | B27: D1_TC_TD03__CPU_EDM0 | C27: A69 | D27: J1604.AS4 | E27: J1604.028 | M27: 5658.4567 | N27: 5658.4567 | O27: L32_INT10 | P27: 24 | Q27: A69 | R27: CPU_EDM[0] | S27: CPU | V27: 1 | W27: CPU_EDM[1] | X27: 0
A28: 25 | B28: D1_TC_TD03__CPU_EDM1 | C28: B69 | D28: J1604.CS13 | E28: J1604.003 | M28: 6900.8268 | N28: 6900.8268 | O28: L19_INT5 | P28: 25 | Q28: B69 | R28: CPU_EDM[1] | S28: CPU | V28: 1
A29: 26 | B29: - | C29: H65 | P29: 26 | Q29: H65 | R29: CPU_EOPIO_RCOMP | S29: EDRAM | U29: 0 | V29: 0 | Z29: Added from ULX but it is EDRAM
A30: 27 | B30: - | C30: BA70 | P30: 27 | Q30: BA70 | R30: CPU_EOPIO_VIEW[0] | S30: EDRAM | V30: 0 | Z30: Added from ULX but it is EDRAM
A31: 28 | B31: - | C31: BA68 | P31: 28 | Q31: BA68 | R31: CPU_EOPIO_VIEW[1] | S31: EDRAM | V31: 0 | Z31: Added from ULX but it is EDRAM
A32: 29 | B32: D1_TC_TD03__CPU_JTAG_TCK__TC | C32: B61 | D32: J1605.DS7 | E32: J1605.056 | F32: RA333.1 | G32: RA332.1 | H32: RA332.2 | L32: 9019.3701 | M32: 12176.961 | N32: 21196.331 | O32: L17_INT4_HS4/L13_INT2_HS2 | P32: 29 | Q32: B61 | R32: CPU_JTAG_TCK | S32: CPU | V32: 1 | W32: CPU_JTAG_TCK | X32: 0
A33: 30 | B33: D1_TC_TD03__CPU_JTAG_TDI__TC | C33: D60 | D33: J1605.CS10 | E33: J1605.049 | F33: RA327.1 | G33: RA326.1 | H33: RA326.2 | L33: 9038.9449 | M33: 12175.169 | N33: 21214.114 | O33: L17_INT4_HS4/L15_INT3_HS3 | P33: 30 | Q33: D60 | R33: CPU_JTAG_TDI | S33: CPU | V33: 1 | W33: CPU_JTAG_TDI | X33: 0
A34: 31 | B34: D1_TC_TD03__CPU_JTAG_TDO__TC | C34: A61 | D34: J1605.DS14 | E34: J1605.042 | F34: RA321.1 | G34: RA320.1 | H34: RA320.2 | L34: 9034.7283 | M34: 12181.917 | N34: 21216.646 | O34: L17_INT4_HS4/L15_INT3_HS3 | P34: 31 | Q34: A61 | R34: CPU_JTAG_TDO | S34: CPU | V34: 1 | W34: CPU_JTAG_TDO | X34: 0
A35: 32 | B35: D1_TC_TD03__CPU_JTAG_TMS__TC | C35: C60 | D35: J1605.CS9 | E35: J1605.051 | F35: RA330.1 | G35: RA329.1 | H35: RA329.2 | L35: 9036 | M35: 12186.823 | N35: 21222.823 | O35: L17_INT4_HS4/L15_INT3_HS3 | P35: 32 | Q35: C60 | R35: CPU_JTAG_TMS | S35: CPU | V35: 1 | W35: CPU_JTAG_TMS | X35: 0
A36: 33 | B36: D1_TC_TD03__CPU_JTAG_TRST_N__TC | C36: B59 | D36: J1605.DS13 | E36: J1605.044 | F36: RA324.1 | G36: RA323.1 | H36: RA323.2 | L36: 9037.9606 | M36: 12192.823 | N36: 21230.783 | O36: L17_INT4_HS4/L15_INT3_HS3 | P36: 33 | Q36: B59 | R36: CPU_JTAG_TRST_N | S36: CPU | V36: 1 | W36: CPU_JTAG_TRST_N | X36: 0
A37: 34 | B37: D1_TC_TD03__CPU_POPIO_VIEW0 | C37: BB2 | D37: J1605.DS4 | E37: J1605.060 | M37: 4153.5866 | N37: 4153.5866 | O37: L11_INT1_HS1 | P37: 34 | Q37: BB2 | R37: CPU_POPIO_VIEW[0] | S37: CPU | V37: 1 | W37: CPU_POPIO_VIEW[0] | X37: 0
A38: 35 | B38: D1_TC_TD03__CPU_POPIO_VIEW1 | C38: BA3 | D38: J1605.CS2 | E38: J1605.063 | M38: 4012.9882 | N38: 4012.9882 | O38: L11_INT1_HS1 | P38: 35 | Q38: BA3 | R38: CPU_POPIO_VIEW[1] | S38: CPU | V38: 1 | W38: CPU_POPIO_VIEW[1] | X38: 0
A39: 36 | B39: D1_TC_TD02__CPU_POPIRCOMP__TC | C39: AT16 | D39: J1605.AS14 | E39: J1605.084 | F39: RA136.2 | G39: RA135.1 | H39: RA135.2 | L39: 3991.9646 | M39: 1224.6496 | N39: 5216.6142 | O39: L11_INT1_HS1/L11_INT1_HS1 | P39: 36 | Q39: AT16 | R39: CPU_POPIRCOMP | S39: CPU | U39: 1 | W39: CPU_POPIRCOMP | X39: 0
A40: 37 | B40: D1_TC_TD01__CPUPWRGD | C40: A68 | D40: J1508.DS9 | E40: J1508.052 | M40: 10379.252 | N40: 10379.252 | O40: L24_INT6 | P40: 37 | Q40: A68 | R40: CPUPWRGD | S40: PCH | W40: CPUPWRGD | X40: 1
...

Sheet Pinlist(S3)
B1: ITTO-620-0089 SKL ULT 2+2 X6 | O1: 41787 | R1: ULT 2+2 | S1: Avaliable | U1: 192 | V1: 64 | W1: ULX | X1: 256
S2: Used | U2: 191 | V2: 64 | X2: 256 | Z2: 0
A3: Sort | B3: Function | C3: Land# | D3: Channel/Tester No | F3: Components | L3: Minor Length | M3: Major Length | N3: Total Length | O3: Trace Layer | P3: Sort | Q3: XY | R3: PIN NAME | S3: DIE | T3: Power supply | U3: DDR TD | V3: Legacy TD | W3: NET | X3: PCH | Z3: Coment
A4: 1 | B4: D3_TC_SH60_TD01__AZA_BCLK_SSP0_SCLK__GPP_F_14_EMMC_DATA1__TC | C4: AY22 | D4: J1805.CS13 | E4: J1805.043 | F4: KC142.6 | G4: KC142.8 | L4: 12187.945 | M4: 8574.0315 | N4: 20761.976 | O4: L13_INT2_HS2/L28_INT8 | P4: 1 | Q4: AY22 | R4: AZA_BCLK_SSP0_SCLK | S4: PCH | W4: AZA_BCLK_SSP0_SCLK | X4: 1 | Z4: PCH-PCH relay with GPP_F_14
A5: 2 | B5: - | C5: BA4 | P5: 2 | Q5: BA4 | R5: AZA_PLLMON_N | S5: PCH | W5: AZA_PLLMON_N | X5: 0
A6: 3 | B6: - | C6: BB4 | P6: 3 | Q6: BB4 | R6: AZA_PLLMON_P | S6: PCH | W6: AZA_PLLMON_P | X6: 0
A7: 4 | B7: D3_TC_SH64_TD01__AZA_RSTB_SSP1_SCLK__GPP_F_16_EMMC_DATA3__TC | C7: AW22 | D7: J1805.CS10 | E7: J1805.049 | F7: KC144.6 | G7: KC144.8 | L7: 9684.5157 | M7: 6992.0197 | N7: 16676.535 | O7: L13_INT2_HS2/L26_INT7 | P7: 4 | Q7: AW22 | R7: AZA_RSTB_SSP1_SCLK | S7: PCH | W7: AZA_RSTB_SSP1_SCLK | X7: 1 | Z7: PCH-PCH relay with GPP_F_16
A8: 5 | B8: D3_TC_SH56_TD01__AZA_SDI_0_SSP0_RXD__GPP_F_12_EMMC_CMD__TC | C8: BA21 | D8: J1805.DS13 | E8: J1805.044 | F8: KC140.6 | G8: KC140.8 | L8: 11830.772 | M8: 9658.3071 | N8: 21489.079 | O8: L15_INT3_HS3/L28_INT8 | P8: 5 | Q8: BA21 | R8: AZA_SDI_0_SSP0_RXD | S8: PCH | W8: AZA_SDI_0_SSP0_RXD | X8: 1 | Z8: PCH-PCH relay with GPP_F_12
A9: 6 | B9: D3_TC_SH66_TD01__AZA_SDI_1_SSP1_RXD__GPP_G_2_SD_DATA1__TC | C9: AY21 | D9: J1805.DS11 | E9: J1805.048 | F9: KC145.6 | G9: KC145.8 | L9: 8488.937 | M9: 7482.1772 | N9: 15971.114 | O9: L13_INT2_HS2/L26_INT7 | P9: 6 | Q9: AY21 | R9: AZA_SDI_1_SSP1_RXD | S9: PCH | W9: AZA_SDI_1_SSP1_RXD | X9: 1 | Z9: PCH-PCH relay with GPP_G_2
A10: 7 | B10: D3_TC_SH58_TD01__AZA_SDO_SSP0_TXD__GPP_F_13_EMMC_DATA0__TC | C10: BB22 | D10: J1805.DS14 | E10: J1805.042 | F10: KC141.6 | G10: KC141.8 | L10: 11800.969 | M10: 9507.374 | N10: 21308.343 | O10: L15_INT3_HS3/L28_INT8 | P10: 7 | Q10: BB22 | R10: AZA_SDO_SSP0_TXD | S10: PCH | W10: AZA_SDO_SSP0_TXD | X10: 1 | Z10: PCH-PCH relay with GPP_F_13
A11: 8 | B11: D3_TC_SH62_TD01__AZA_SYNC_SSP0_SFRM__GPP_F_15_EMMC_DATA2__TC | C11: BA22 | D11: J1804.CS9 | E11: J1804.007 | F11: KC143.6 | G11: KC143.8 | L11: 11151.827 | M11: 7568.2047 | N11: 18720.031 | O11: L13_INT2_HS2/L26_INT7 | P11: 8 | Q11: BA22 | R11: AZA_SYNC_SSP0_SFRM | S11: PCH | W11: AZA_SYNC_SSP0_SFRM | X11: 1 | Z11: PCH-PCH relay with GPP_F_15
A12: 9 | B12: D3_TC_TD03__CATERR_N | C12: D63 | D12: J1503.CS8 | E12: J1503.009 | M12: 7258.6181 | N12: 7258.6181 | O12: L19_INT5 | P12: 9 | Q12: D63 | R12: CATERR_N | S12: CPU | V12: 1 | W12: CATERR_N | X12: 0
A13: 10 | B13: D3_TC_DP117_SH29_TD01__CLKOUT_ITPXDP_N__DDR0_DDR1_CKE0__TC | C13: F43 | D13: J1804.CS14 | E13: J1804.001 | F13: TPC101.1 | G13: KC101.4 | H13: KC101.2 | L13: 7951.8071 | M13: 6888.7441 | N13: 14840.551 | O13: L19_INT5/L15_INT3_HS3 | P13: 10 | Q13: F43 | R13: CLKOUT_ITPXDP_N | S13: PCH | W13: CLKOUT_ITPXDP_N | X13: 1
A14: 11 | B14: D3_TC_DP117_SH30_TD01__CLKOUT_ITPXDP_P__DDR0_DDR1_CKE1__TC | C14: E43 | D14: J1804.CS13 | E14: J1804.003 | F14: TPC102.1 | G14: KC101.6 | H14: KC101.8 | L14: 7951.6496 | M14: 6888.6929 | N14: 14840.343 | O14: L19_INT5/L15_INT3_HS3 | P14: 11 | Q14: E43 | R14: CLKOUT_ITPXDP_P | S14: PCH | W14: CLKOUT_ITPXDP_P | X14: 1
A15: 12 | B15: D3_TC_SH31_TD01__CLKOUT_SRC_N_0_5__DDR0_DDR1_CKE2__TC | C15: D42 | D15: J1805.BS7 | E15: J1805.077 | F15: TPC103.1 | G15: KC102.4 | H15: KC102.2 | L15: 8030.4449 | M15: 7164.2677 | N15: 15194.713 | O15: L15_INT3_HS3/L11_INT1_HS1 | P15: 12 | Q15: D42 | R15: CLKOUT_SRC_N_0 | S15: PCH | X15: 1 | Z15: Y-conntion: N[0:5]
A16: 13 | B16: D3_TC_SH31_TD01__CLKOUT_SRC_N_0_5__DDR0_DDR1_CKE2__TC | C16: B42 | D16: J1805.BS7 | E16: J1805.077 | F16: TPC103.1 | G16: KC102.4 | H16: KC102.2 | L16: 8030.4449 | M16: 7164.2677 | N16: 15194.713 | O16: L15_INT3_HS3/L11_INT1_HS1 | P16: 13 | Q16: B42 | R16: CLKOUT_SRC_N_1 | S16: PCH | W16: CLKOUT_SRC_N_1 | X16: 0 | Z16: Y-conntion: N[0:5]
A17: 14 | B17: D3_TC_SH31_TD01__CLKOUT_SRC_N_0_5__DDR0_DDR1_CKE2__TC | C17: D41 | D17: J1805.BS7 | E17: J1805.077 | F17: TPC103.1 | G17: KC102.4 | H17: KC102.2 | L17: 8030.4449 | M17: 7164.2677 | N17: 15194.713 | O17: L15_INT3_HS3/L11_INT1_HS1 | P17: 14 | Q17: D41 | R17: CLKOUT_SRC_N_2 | S17: PCH | W17: CLKOUT_SRC_N_2 | X17: 0 | Z17: Y-conntion: N[0:5]
A18: 15 | B18: D3_TC_SH31_TD01__CLKOUT_SRC_N_0_5__DDR0_DDR1_CKE2__TC | C18: D40 | D18: J1805.BS7 | E18: J1805.077 | F18: TPC103.1 | G18: KC102.4 | H18: KC102.2 | L18: 8030.4449 | M18: 7164.2677 | N18: 15194.713 | O18: L15_INT3_HS3/L11_INT1_HS1 | P18: 15 | Q18: D40 | R18: CLKOUT_SRC_N_3 | S18: PCH | W18: CLKOUT_SRC_N_3 | X18: 0 | Z18: Y-conntion: N[0:5]
A19: 16 | B19: D3_TC_SH31_TD01__CLKOUT_SRC_N_0_5__DDR0_DDR1_CKE2__TC | C19: B40 | D19: J1805.BS7 | E19: J1805.077 | F19: TPC103.1 | G19: KC102.4 | H19: KC102.2 | L19: 8030.4449 | M19: 7164.2677 | N19: 15194.713 | O19: L15_INT3_HS3/L11_INT1_HS1 | P19: 16 | Q19: B40 | R19: CLKOUT_SRC_N_4 | S19: PCH | W19: CLKOUT_SRC_N_4 | X19: 0 | Z19: Y-conntion: N[0:5]
A20: 17 | B20: D3_TC_SH31_TD01__CLKOUT_SRC_N_0_5__DDR0_DDR1_CKE2__TC | C20: E40 | D20: J1805.BS7 | E20: J1805.077 | F20: TPC103.1 | G20: KC102.4 | H20: KC102.2 | L20: 8030.4449 | M20: 7164.2677 | N20: 15194.713 | O20: L15_INT3_HS3/L11_INT1_HS1 | P20: 17 | Q20: E40 | R20: CLKOUT_SRC_N_5 | S20: PCH | W20: CLKOUT_SRC_N_5 | X20: 0 | Z20: Y-conntion: N[0:5]
A21: 18 | B21: D3_TC_SH32_TD01__CLKOUT_SRC_P_0_5__DDR0_DDR1_CKE3__TC | C21: C42 | D21: J1805.BS9 | E21: J1805.081 | F21: TPC104.1 | G21: KC102.6 | H21: KC102.8 | L21: 8031.0079 | M21: 7164.5748 | N21: 15195.583 | O21: L26_INT7/L11_INT1_HS1 | P21: 18 | Q21: C42 | R21: CLKOUT_SRC_P_0 | S21: PCH | W21: CLKOUT_SRC_P_1 | X21: 1 | Z21: Y-conntion: P[0:5]
A22: 19 | B22: D3_TC_SH32_TD01__CLKOUT_SRC_P_0_5__DDR0_DDR1_CKE3__TC | C22: A42 | D22: J1805.BS9 | E22: J1805.081 | F22: TPC104.1 | G22: KC102.6 | H22: KC102.8 | L22: 8031.0079 | M22: 7164.5748 | N22: 15195.583 | O22: L26_INT7/L11_INT1_HS1 | P22: 19 | Q22: A42 | R22: CLKOUT_SRC_P_1 | S22: PCH | W22: CLKOUT_SRC_P_2 | X22: 0 | Z22: Y-conntion: P[0:5]
A23: 20 | B23: D3_TC_SH32_TD01__CLKOUT_SRC_P_0_5__DDR0_DDR1_CKE3__TC | C23: C41 | D23: J1805.BS9 | E23: J1805.081 | F23: TPC104.1 | G23: KC102.6 | H23: KC102.8 | L23: 8031.0079 | M23: 7164.5748 | N23: 15195.583 | O23: L26_INT7/L11_INT1_HS1 | P23: 20 | Q23: C41 | R23: CLKOUT_SRC_P_2 | S23: PCH | W23: CLKOUT_SRC_P_3 | X23: 0 | Z23: Y-conntion: P[0:5]
A24: 21 | B24: D3_TC_SH32_TD01__CLKOUT_SRC_P_0_5__DDR0_DDR1_CKE3__TC | C24: C40 | D24: J1805.BS9 | E24: J1805.081 | F24: TPC104.1 | G24: KC102.6 | H24: KC102.8 | L24: 8031.0079 | M24: 7164.5748 | N24: 15195.583 | O24: L26_INT7/L11_INT1_HS1 | P24: 21 | Q24: C40 | R24: CLKOUT_SRC_P_3 | S24: PCH | W24: CLKOUT_SRC_P_4 | X24: 0 | Z24: Y-conntion: P[0:5]
A25: 22 | B25: D3_TC_SH32_TD01__CLKOUT_SRC_P_0_5__DDR0_DDR1_CKE3__TC | C25: A40 | D25: J1805.BS9 | E25: J1805.081 | F25: TPC104.1 | G25: KC102.6 | H25: KC102.8 | L25: 8031.0079 | M25: 7164.5748 | N25: 15195.583 | O25: L26_INT7/L11_INT1_HS1 | P25: 22 | Q25: A40 | R25: CLKOUT_SRC_P_4 | S25: PCH | W25: CLKOUT_SRC_P_5 | X25: 0 | Z25: Y-conntion: P[0:5]
A26: 23 | B26: D3_TC_SH32_TD01__CLKOUT_SRC_P_0_5__DDR0_DDR1_CKE3__TC | C26: E38 | D26: J1805.BS9 | E26: J1805.081 | F26: TPC104.1 | G26: KC102.6 | H26: KC102.8 | L26: 8031.0079 | M26: 7164.5748 | N26: 15195.583 | O26: L26_INT7/L11_INT1_HS1 | P26: 23 | Q26: E38 | R26: CLKOUT_SRC_P_5 | S26: PCH | W26: CPU_EDM[0] | X26: 0 | Z26: Y-conntion: P[0:5]
A27: 24 | B27: D3_TC_TD03__CPU_EDM0 | C27: A69 | D27: J1503.BS8 | E27: J1503.035 | M27: 9212.7756 | N27: 9212.7756 | O27: L30_INT9 | P27: 24 | Q27: A69 | R27: CPU_EDM[0] | S27: CPU | V27: 1 | W27: CPU_EDM[1] | X27: 0
A28: 25 | B28: D3_TC_TD03__CPU_EDM1 | C28: B69 | D28: J1503.AS9 | E28: J1503.038 | M28: 8925.7953 | N28: 8925.7953 | O28: L19_INT5 | P28: 25 | Q28: B69 | R28: CPU_EDM[1] | S28: CPU | V28: 1
A29: 26 | B29: - | C29: H65 | P29: 26 | Q29: H65 | R29: CPU_EOPIO_RCOMP | S29: EDRAM | U29: 0 | V29: 0 | Z29: Added from ULX but it is EDRAM
A30: 27 | B30: - | C30: BA70 | P30: 27 | Q30: BA70 | R30: CPU_EOPIO_VIEW[0] | S30: EDRAM | V30: 0 | Z30: Added from ULX but it is EDRAM
A31: 28 | B31: - | C31: BA68 | P31: 28 | Q31: BA68 | R31: CPU_EOPIO_VIEW[1] | S31: EDRAM | V31: 0 | Z31: Added from ULX but it is EDRAM
A32: 29 | B32: D3_TC_TD03__CPU_JTAG_TCK__TC | C32: B61 | D32: J1503.DS14 | E32: J1503.002 | F32: RC333.1 | G32: RC332.1 | H32: RC332.2 | L32: 9033.3858 | M32: 12200.429 | N32: 21233.815 | O32: L15_INT3_HS3 | P32: 29 | Q32: B61 | R32: CPU_JTAG_TCK | S32: CPU | V32: 1 | W32: CPU_JTAG_TCK | X32: 0
A33: 30 | B33: D3_TC_TD03__CPU_JTAG_TDI__TC | C33: D60 | D33: J1502.CS14 | E33: J1502.041 | F33: RC327.1 | G33: RC326.1 | H33: RC326.2 | L33: 9051.9961 | M33: 12179.921 | N33: 21231.917 | O33: L30_INT9/L15_INT3_HS3 | P33: 30 | Q33: D60 | R33: CPU_JTAG_TDI | S33: CPU | V33: 1 | W33: CPU_JTAG_TDI | X33: 0
A34: 31 | B34: D3_TC_TD03__CPU_JTAG_TDO__TC | C34: A61 | D34: J1502.DS13 | E34: J1502.044 | F34: RC321.1 | G34: RC320.1 | H34: RC320.2 | L34: 9030.7205 | M34: 12182.728 | N34: 21213.449 | O34: L15_INT3_HS3 | P34: 31 | Q34: A61 | R34: CPU_JTAG_TDO | S34: CPU | V34: 1 | W34: CPU_JTAG_TDO | X34: 0
A35: 32 | B35: D3_TC_TD03__CPU_JTAG_TMS__TC | C35: C60 | D35: J1502.CS13 | E35: J1502.043 | F35: RC330.1 | G35: RC329.1 | H35: RC329.2 | L35: 9033.622 | M35: 12183.516 | N35: 21217.138 | O35: L17_INT4_HS4/L15_INT3_HS3 | P35: 32 | Q35: C60 | R35: CPU_JTAG_TMS | S35: CPU | V35: 1 | W35: CPU_JTAG_TMS | X35: 0
A36: 33 | B36: D3_TC_TD03__CPU_JTAG_TRST_N__TC | C36: B59 | D36: J1502.DS14 | E36: J1502.042 | F36: RC324.1 | G36: RC323.1 | H36: RC323.2 | L36: 9031.8819 | M36: 12197.201 | N36: 21229.083 | O36: L30_INT9/L15_INT3_HS3 | P36: 33 | Q36: B59 | R36: CPU_JTAG_TRST_N | S36: CPU | V36: 1 | W36: CPU_JTAG_TRST_N | X36: 0
A37: 34 | B37: D3_TC_TD03__CPU_POPIO_VIEW0 | C37: BB2 | D37: J1502.DS3 | E37: J1502.062 | M37: 6992.6142 | N37: 6992.6142 | O37: L11_INT1_HS1 | P37: 34 | Q37: BB2 | R37: CPU_POPIO_VIEW[0] | S37: CPU | V37: 1 | W37: CPU_POPIO_VIEW[0] | X37: 0
A38: 35 | B38: D3_TC_TD03__CPU_POPIO_VIEW1 | C38: BA3 | D38: J1502.DS4 | E38: J1502.060 | M38: 6933.6457 | N38: 6933.6457 | O38: L11_INT1_HS1 | P38: 35 | Q38: BA3 | R38: CPU_POPIO_VIEW[1] | S38: CPU | V38: 1 | W38: CPU_POPIO_VIEW[1] | X38: 0
A39: 36 | B39: D3_TC_TD02__CPU_POPIRCOMP__TC | C39: AT16 | D39: J1803.CS14 | E39: J1803.085 | F39: RC136.2 | G39: RC135.1 | H39: RC135.2 | L39: 5198.189 | M39: 1182.9961 | N39: 6381.185 | O39: L11_INT1_HS1/L19_INT5 | P39: 36 | Q39: AT16 | R39: CPU_POPIRCOMP | S39: CPU | U39: 1 | W39: CPU_POPIRCOMP | X39: 0
A40: 37 | B40: D3_TC_TD01__CPUPWRGD | C40: A68 | D40: J1804.AS9 | E40: J1804.038 | M40: 6253.4291 | N40: 6253.4291 | O40: L26_INT7 | P40: 37 | Q40: A68 | R40: CPUPWRGD | S40: PCH | W40: CPUPWRGD | X40: 1
...

Sheet Pinlist(S5)
B1: ITTO-620-0089 SKL ULT 2+2 X6 | O1: 41787 | R1: ULT 2+2 | S1: Avaliable | U1: 192 | V1: 64 | W1: ULX | X1: 256
S2: Used | U2: 191 | V2: 64 | X2: 256 | Z2: 0
A3: Sort | B3: Function | C3: Land# | D3: Channel/Tester No | F3: Components | L3: Minor Length | M3: Major Length | N3: Total Length | O3: Trace Layer | P3: Sort | Q3: XY | R3: PIN NAME | S3: DIE | T3: Power supply | U3: DDR TD | V3: Legacy TD | W3: NET | X3: PCH | Z3: Coment
A4: 1 | B4: D5_TC_SH60_TD01__AZA_BCLK_SSP0_SCLK__GPP_F_14_EMMC_DATA1__TC | C4: AY22 | D4: J1703.CS7 | E4: J1703.011 | F4: KE142.6 | G4: KE142.8 | L4: 6533.811 | M4: 8405.4055 | N4: 14939.217 | O4: L13_INT2_HS2/L13_INT2_HS2 | P4: 1 | Q4: AY22 | R4: AZA_BCLK_SSP0_SCLK | S4: PCH | W4: AZA_BCLK_SSP0_SCLK | X4: 1 | Z4: PCH-PCH relay with GPP_F_14
A5: 2 | B5: - | C5: BA4 | P5: 2 | Q5: BA4 | R5: AZA_PLLMON_N | S5: PCH | W5: AZA_PLLMON_N | X5: 0
A6: 3 | B6: - | C6: BB4 | P6: 3 | Q6: BB4 | R6: AZA_PLLMON_P | S6: PCH | W6: AZA_PLLMON_P | X6: 0
A7: 4 | B7: D5_TC_SH64_TD01__AZA_RSTB_SSP1_SCLK__GPP_F_16_EMMC_DATA3__TC | C7: AW22 | D7: J1703.DS14 | E7: J1703.002 | F7: KE144.6 | G7: KE144.8 | L7: 9519.2362 | M7: 6956.3228 | N7: 16475.559 | O7: L15_INT3_HS3/L19_INT5 | P7: 4 | Q7: AW22 | R7: AZA_RSTB_SSP1_SCLK | S7: PCH | W7: AZA_RSTB_SSP1_SCLK | X7: 1 | Z7: PCH-PCH relay with GPP_F_16
A8: 5 | B8: D5_TC_SH56_TD01__AZA_SDI_0_SSP0_RXD__GPP_F_12_EMMC_CMD__TC | C8: BA21 | D8: J1703.CS8 | E8: J1703.009 | F8: KE140.6 | G8: KE140.8 | L8: 5702.9685 | M8: 6625.9803 | N8: 12328.949 | O8: L17_INT4_HS4/L13_INT2_HS2 | P8: 5 | Q8: BA21 | R8: AZA_SDI_0_SSP0_RXD | S8: PCH | W8: AZA_SDI_0_SSP0_RXD | X8: 1 | Z8: PCH-PCH relay with GPP_F_12
A9: 6 | B9: D5_TC_SH66_TD01__AZA_SDI_1_SSP1_RXD__GPP_G_2_SD_DATA1__TC | C9: AY21 | D9: J1703.BS7 | E9: J1703.033 | F9: KE145.6 | G9: KE145.8 | L9: 8333.063 | M9: 5749.7874 | N9: 14082.85 | O9: L13_INT2_HS2/L13_INT2_HS2 | P9: 6 | Q9: AY21 | R9: AZA_SDI_1_SSP1_RXD | S9: PCH | W9: AZA_SDI_1_SSP1_RXD | X9: 1 | Z9: PCH-PCH relay with GPP_G_2
A10: 7 | B10: D5_TC_SH58_TD01__AZA_SDO_SSP0_TXD__GPP_F_13_EMMC_DATA0__TC | C10: BB22 | D10: J1702.DS2 | E10: J1702.064 | F10: KE141.6 | G10: KE141.8 | L10: 5996.0197 | M10: 3636.4291 | N10: 9632.4488 | O10: L17_INT4_HS4/L15_INT3_HS3 | P10: 7 | Q10: BB22 | R10: AZA_SDO_SSP0_TXD | S10: PCH | W10: AZA_SDO_SSP0_TXD | X10: 1 | Z10: PCH-PCH relay with GPP_F_13
A11: 8 | B11: D5_TC_SH62_TD01__AZA_SYNC_SSP0_SFRM__GPP_F_15_EMMC_DATA2__TC | C11: BA22 | D11: J1703.BS6 | E11: J1703.031 | F11: KE143.6 | G11: KE143.8 | L11: 7048.437 | M11: 6709.1969 | N11: 13757.634 | O11: L15_INT3_HS3/L13_INT2_HS2 | P11: 8 | Q11: BA22 | R11: AZA_SYNC_SSP0_SFRM | S11: PCH | W11: AZA_SYNC_SSP0_SFRM | X11: 1 | Z11: PCH-PCH relay with GPP_F_15
A12: 9 | B12: D5_TC_TD03__CATERR_N | C12: D63 | D12: J1709.DS8 | E12: J1709.010 | M12: 5425.2441 | N12: 5425.2441 | O12: L19_INT5 | P12: 9 | Q12: D63 | R12: CATERR_N | S12: CPU | V12: 1 | W12: CATERR_N | X12: 0
A13: 10 | B13: D5_TC_DP117_SH29_TD01__CLKOUT_ITPXDP_N__DDR0_DDR1_CKE0__TC | C13: F43 | D13: J1703.BS14 | E13: J1703.039 | F13: TPE101.1 | G13: KE101.4 | H13: KE101.2 | L13: 9644.7126 | M13: 2951.7362 | N13: 12596.449 | O13: L17_INT4_HS4/L19_INT5 | P13: 10 | Q13: F43 | R13: CLKOUT_ITPXDP_N | S13: PCH | W13: CLKOUT_ITPXDP_N | X13: 1
A14: 11 | B14: D5_TC_DP117_SH30_TD01__CLKOUT_ITPXDP_P__DDR0_DDR1_CKE1__TC | C14: E43 | D14: J1703.AS14 | E14: J1703.040 | F14: TPE102.1 | G14: KE101.6 | H14: KE101.8 | L14: 9644.9961 | M14: 2951.3937 | N14: 12596.39 | O14: L17_INT4_HS4/L19_INT5 | P14: 11 | Q14: E43 | R14: CLKOUT_ITPXDP_P | S14: PCH | W14: CLKOUT_ITPXDP_P | X14: 1
A15: 12 | B15: D5_TC_SH31_TD01__CLKOUT_SRC_N_0_5__DDR0_DDR1_CKE2__TC | C15: D42 | D15: J1702.AS9 | E15: J1702.082 | F15: TPE103.1 | G15: KE102.4 | H15: KE102.2 | L15: 9132.3661 | M15: 6219.3937 | N15: 15351.76 | O15: L15_INT3_HS3/L30_INT9 | P15: 12 | Q15: D42 | R15: CLKOUT_SRC_N_0 | S15: PCH | X15: 1 | Z15: Y-conntion: N[0:5]
A16: 13 | B16: D5_TC_SH31_TD01__CLKOUT_SRC_N_0_5__DDR0_DDR1_CKE2__TC | C16: B42 | D16: J1702.AS9 | E16: J1702.082 | F16: TPE103.1 | G16: KE102.4 | H16: KE102.2 | L16: 9132.3661 | M16: 6219.3937 | N16: 15351.76 | O16: L15_INT3_HS3/L30_INT9 | P16: 13 | Q16: B42 | R16: CLKOUT_SRC_N_1 | S16: PCH | W16: CLKOUT_SRC_N_1 | X16: 0 | Z16: Y-conntion: N[0:5]
A17: 14 | B17: D5_TC_SH31_TD01__CLKOUT_SRC_N_0_5__DDR0_DDR1_CKE2__TC | C17: D41 | D17: J1702.AS9 | E17: J1702.082 | F17: TPE103.1 | G17: KE102.4 | H17: KE102.2 | L17: 9132.3661 | M17: 6219.3937 | N17: 15351.76 | O17: L15_INT3_HS3/L30_INT9 | P17: 14 | Q17: D41 | R17: CLKOUT_SRC_N_2 | S17: PCH | W17: CLKOUT_SRC_N_2 | X17: 0 | Z17: Y-conntion: N[0:5]
A18: 15 | B18: D5_TC_SH31_TD01__CLKOUT_SRC_N_0_5__DDR0_DDR1_CKE2__TC | C18: D40 | D18: J1702.AS9 | E18: J1702.082 | F18: TPE103.1 | G18: KE102.4 | H18: KE102.2 | L18: 9132.3661 | M18: 6219.3937 | N18: 15351.76 | O18: L15_INT3_HS3/L30_INT9 | P18: 15 | Q18: D40 | R18: CLKOUT_SRC_N_3 | S18: PCH | W18: CLKOUT_SRC_N_3 | X18: 0 | Z18: Y-conntion: N[0:5]
A19: 16 | B19: D5_TC_SH31_TD01__CLKOUT_SRC_N_0_5__DDR0_DDR1_CKE2__TC | C19: B40 | D19: J1702.AS9 | E19: J1702.082 | F19: TPE103.1 | G19: KE102.4 | H19: KE102.2 | L19: 9132.3661 | M19: 6219.3937 | N19: 15351.76 | O19: L15_INT3_HS3/L30_INT9 | P19: 16 | Q19: B40 | R19: CLKOUT_SRC_N_4 | S19: PCH | W19: CLKOUT_SRC_N_4 | X19: 0 | Z19: Y-conntion: N[0:5]
A20: 17 | B20: D5_TC_SH31_TD01__CLKOUT_SRC_N_0_5__DDR0_DDR1_CKE2__TC | C20: E40 | D20: J1702.AS9 | E20: J1702.082 | F20: TPE103.1 | G20: KE102.4 | H20: KE102.2 | L20: 9132.3661 | M20: 6219.3937 | N20: 15351.76 | O20: L15_INT3_HS3/L30_INT9 | P20: 17 | Q20: E40 | R20: CLKOUT_SRC_N_5 | S20: PCH | W20: CLKOUT_SRC_N_5 | X20: 0 | Z20: Y-conntion: N[0:5]
A21: 18 | B21: D5_TC_SH32_TD01__CLKOUT_SRC_P_0_5__DDR0_DDR1_CKE3__TC | C21: C42 | D21: J1702.BS9 | E21: J1702.081 | F21: TPE104.1 | G21: KE102.6 | H21: KE102.8 | L21: 9133.6339 | M21: 6219.878 | N21: 15353.512 | O21: L26_INT7/L30_INT9 | P21: 18 | Q21: C42 | R21: CLKOUT_SRC_P_0 | S21: PCH | W21: CLKOUT_SRC_P_1 | X21: 1 | Z21: Y-conntion: P[0:5]
A22: 19 | B22: D5_TC_SH32_TD01__CLKOUT_SRC_P_0_5__DDR0_DDR1_CKE3__TC | C22: A42 | D22: J1702.BS9 | E22: J1702.081 | F22: TPE104.1 | G22: KE102.6 | H22: KE102.8 | L22: 9133.6339 | M22: 6219.878 | N22: 15353.512 | O22: L26_INT7/L30_INT9 | P22: 19 | Q22: A42 | R22: CLKOUT_SRC_P_1 | S22: PCH | W22: CLKOUT_SRC_P_2 | X22: 0 | Z22: Y-conntion: P[0:5]
A23: 20 | B23: D5_TC_SH32_TD01__CLKOUT_SRC_P_0_5__DDR0_DDR1_CKE3__TC | C23: C41 | D23: J1702.BS9 | E23: J1702.081 | F23: TPE104.1 | G23: KE102.6 | H23: KE102.8 | L23: 9133.6339 | M23: 6219.878 | N23: 15353.512 | O23: L26_INT7/L30_INT9 | P23: 20 | Q23: C41 | R23: CLKOUT_SRC_P_2 | S23: PCH | W23: CLKOUT_SRC_P_3 | X23: 0 | Z23: Y-conntion: P[0:5]
A24: 21 | B24: D5_TC_SH32_TD01__CLKOUT_SRC_P_0_5__DDR0_DDR1_CKE3__TC | C24: C40 | D24: J1702.BS9 | E24: J1702.081 | F24: TPE104.1 | G24: KE102.6 | H24: KE102.8 | L24: 9133.6339 | M24: 6219.878 | N24: 15353.512 | O24: L26_INT7/L30_INT9 | P24: 21 | Q24: C40 | R24: CLKOUT_SRC_P_3 | S24: PCH | W24: CLKOUT_SRC_P_4 | X24: 0 | Z24: Y-conntion: P[0:5]
A25: 22 | B25: D5_TC_SH32_TD01__CLKOUT_SRC_P_0_5__DDR0_DDR1_CKE3__TC | C25: A40 | D25: J1702.BS9 | E25: J1702.081 | F25: TPE104.1 | G25: KE102.6 | H25: KE102.8 | L25: 9133.6339 | M25: 6219.878 | N25: 15353.512 | O25: L26_INT7/L30_INT9 | P25: 22 | Q25: A40 | R25: CLKOUT_SRC_P_4 | S25: PCH | W25: CLKOUT_SRC_P_5 | X25: 0 | Z25: Y-conntion: P[0:5]
A26: 23 | B26: D5_TC_SH32_TD01__CLKOUT_SRC_P_0_5__DDR0_DDR1_CKE3__TC | C26: E38 | D26: J1702.BS9 | E26: J1702.081 | F26: TPE104.1 | G26: KE102.6 | H26: KE102.8 | L26: 9133.6339 | M26: 6219.878 | N26: 15353.512 | O26: L26_INT7/L30_INT9 | P26: 23 | Q26: E38 | R26: CLKOUT_SRC_P_5 | S26: PCH | W26: CPU_EDM[0] | X26: 0 | Z26: Y-conntion: P[0:5]
A27: 24 | B27: D5_TC_TD03__CPU_EDM0 | C27: A69 | D27: J1709.AS14 | E27: J1709.040 | M27: 6911 | N27: 6911 | O27: L32_INT10 | P27: 24 | Q27: A69 | R27: CPU_EDM[0] | S27: CPU | V27: 1 | W27: CPU_EDM[1] | X27: 0
A28: 25 | B28: D5_TC_TD03__CPU_EDM1 | C28: B69 | D28: J1709.CS7 | E28: J1709.011 | M28: 6157.7835 | N28: 6157.7835 | O28: L19_INT5 | P28: 25 | Q28: B69 | R28: CPU_EDM[1] | S28: CPU | V28: 1
A29: 26 | B29: - | C29: H65 | P29: 26 | Q29: H65 | R29: CPU_EOPIO_RCOMP | S29: EDRAM | U29: 0 | V29: 0 | Z29: Added from ULX but it is EDRAM
A30: 27 | B30: - | C30: BA70 | P30: 27 | Q30: BA70 | R30: CPU_EOPIO_VIEW[0] | S30: EDRAM | V30: 0 | Z30: Added from ULX but it is EDRAM
A31: 28 | B31: - | C31: BA68 | P31: 28 | Q31: BA68 | R31: CPU_EOPIO_VIEW[1] | S31: EDRAM | V31: 0 | Z31: Added from ULX but it is EDRAM
A32: 29 | B32: D5_TC_TD03__CPU_JTAG_TCK__TC | C32: B61 | D32: J1708.CS13 | E32: J1708.043 | F32: RE333.1 | G32: RE332.1 | H32: RE332.2 | L32: 9022.4094 | M32: 12189.854 | N32: 21212.264 | O32: L13_INT2_HS2/L11_INT1_HS1 | P32: 29 | Q32: B61 | R32: CPU_JTAG_TCK | S32: CPU | V32: 1 | W32: CPU_JTAG_TCK | X32: 0
A33: 30 | B33: D5_TC_TD03__CPU_JTAG_TDI__TC | C33: D60 | D33: J1709.DS10 | E33: J1709.006 | F33: RE327.1 | G33: RE326.1 | H33: RE326.2 | L33: 9028.0512 | M33: 12171.047 | N33: 21199.098 | O33: L30_INT9/L11_INT1_HS1 | P33: 30 | Q33: D60 | R33: CPU_JTAG_TDI | S33: CPU | V33: 1 | W33: CPU_JTAG_TDI | X33: 0
A34: 31 | B34: D5_TC_TD03__CPU_JTAG_TDO__TC | C34: A61 | D34: J1709.DS9 | E34: J1709.008 | F34: RE321.1 | G34: RE320.1 | H34: RE320.2 | L34: 9026.2008 | M34: 12187.587 | N34: 21213.787 | O34: L19_INT5/L11_INT1_HS1 | P34: 31 | Q34: A61 | R34: CPU_JTAG_TDO | S34: CPU | V34: 1 | W34: CPU_JTAG_TDO | X34: 0
A35: 32 | B35: D5_TC_TD03__CPU_JTAG_TMS__TC | C35: C60 | D35: J1709.CS13 | E35: J1709.003 | F35: RE330.1 | G35: RE329.1 | H35: RE329.2 | L35: 9048.3819 | M35: 12173.319 | N35: 21221.701 | O35: L13_INT2_HS2/L11_INT1_HS1 | P35: 32 | Q35: C60 | R35: CPU_JTAG_TMS | S35: CPU | V35: 1 | W35: CPU_JTAG_TMS | X35: 0
A36: 33 | B36: D5_TC_TD03__CPU_JTAG_TRST_N__TC | C36: B59 | D36: J1709.CS10 | E36: J1709.005 | F36: RE324.1 | G36: RE323.1 | H36: RE323.2 | L36: 8850.3346 | M36: 12383.311 | N36: 21233.646 | O36: L28_INT8/L11_INT1_HS1 | P36: 33 | Q36: B59 | R36: CPU_JTAG_TRST_N | S36: CPU | V36: 1 | W36: CPU_JTAG_TRST_N | X36: 0
A37: 34 | B37: D5_TC_TD03__CPU_POPIO_VIEW0 | C37: BB2 | D37: J1708.CS14 | E37: J1708.041 | M37: 9064.3425 | N37: 9064.3425 | O37: L15_INT3_HS3 | P37: 34 | Q37: BB2 | R37: CPU_POPIO_VIEW[0] | S37: CPU | V37: 1 | W37: CPU_POPIO_VIEW[0] | X37: 0
A38: 35 | B38: D5_TC_TD03__CPU_POPIO_VIEW1 | C38: BA3 | D38: J1708.DS14 | E38: J1708.042 | M38: 8865.7205 | N38: 8865.7205 | O38: L15_INT3_HS3 | P38: 35 | Q38: BA3 | R38: CPU_POPIO_VIEW[1] | S38: CPU | V38: 1 | W38: CPU_POPIO_VIEW[1] | X38: 0
A39: 36 | B39: D5_TC_TD02__CPU_POPIRCOMP__TC | C39: AT16 | D39: J1704.AS14 | E39: J1704.128 | F39: RE136.2 | G39: RE135.1 | H39: RE135.2 | L39: 4525.8268 | M39: 1223.5945 | N39: 5749.4213 | O39: L11_INT1_HS1/L17_INT4_HS4 | P39: 36 | Q39: AT16 | R39: CPU_POPIRCOMP | S39: CPU | U39: 1 | W39: CPU_POPIRCOMP | X39: 0
A40: 37 | B40: D5_TC_TD01__CPUPWRGD | C40: A68 | D40: J1703.AS5 | E40: J1703.030 | M40: 5149.3465 | N40: 5149.3465 | O40: L26_INT7 | P40: 37 | Q40: A68 | R40: CPUPWRGD | S40: PCH | W40: CPUPWRGD | X40: 1
...

Sheet Crosstalk
D1: ITTO-620-0089 SKL ULT 2+2 X6 | U1: 41712
P2: To avoid crosstalk on HSIO signal
Q3: preliminary pin assignment
C4: 【Module side connector】 | I4: 【PB side connector】
B5: J1 | C5: pin | D5: B列 | E5: C列 | F5: D列 | J5: #3 | Q5: Site1
D6: S | E6: S | F6: S | J6: J1603 | Q6: HSIO group | R6: Tch | U6: nearby signals | V6: Tch
C7: A14 | D7: - | E7: - | F7: - | I7: pin | J7: D | K7: C | L7: B | M7: A | P7: 1 | Q7: PCIE_1_USB3_5_RXN_TXN | R7: J1506PIN038 | S7: HSIO1 | T7: 1 | U7: USB2_VBUSSENSE | V7: J1506PIN023 | W7: Near1
C8: A13 | D8: PIN98 | E8: PIN96 | F8: PIN97 | J8: S | K8: S | L8: S | M8: S | P8: 2 | Q8: PCIE_1_USB3_5_RXP_TXP | R8: J1506PIN036 | S8: HSIO1 | T8: 2 | U8: THRMTRIPB | V8: J1504PIN107 | W8: Near2
C9: A12 | D9: PIN94 | E9: PIN99 | F9: PIN95 | I9: 1 | J9: PIN110 | K9: PIN109 | L9: NC | M9: RIVET | P9: 3 | Q9: PCIE_2_UFS_0A_USB3_6_RXN_TXN | R9: J1504PIN097 | S9: HSIO2 | T9: 3 | U9: PECI | V9: J1504PIN108 | W9: Near2
C10: A11 | D10: PIN101 | E10: PIN93 | F10: PIN100 | I10: 2 | J10: PIN108 | K10: PIN107 | L10: PIN111 | M10: PIN112 | P10: 4 | Q10: PCIE_2_UFS_0A_USB3_6_RXP_TXP | R10: J1504PIN095 | S10: HSIO2 | T10: 4 | U10: RSMRSTB | V10: J1504PIN086 | W10: Near2
C11: A10 | D11: PIN91 | E11: PIN102 | F11: PIN92 | I11: 3 | J11: PIN106 | K11: PIN105 | L11: PIN113 | M11: PIN114 | P11: 5 | Q11: PCIE_3_UFS_0B_LAN_0A_RXN_TXN | R11: J1506PIN037 | S11: HSIO1 | T11: 5 | U11: PCH_PWROK | V11: J1504PIN105 | W11: Near2
C12: A9 | D12: PIN104 | E12: PIN90 | F12: PIN103 | I12: 4 | J12: PIN104 | K12: PIN103 | L12: PIN115 | M12: PIN116 | P12: 6 | Q12: PCIE_3_UFS_0B_LAN_0A_RXP_TXP | R12: J1506PIN035 | S12: HSIO1 | T12: 6 | U12: SYS_PWROK | V12: J1504PIN089 | W12: Near2
C13: A8 | D13: PIN88 | E13: PIN105 | F13: PIN89 | I13: 5 | J13: RIVET | K13: NC | L13: PIN117 | M13: PIN118 | P13: 7 | Q13: PCIE_4_LAN_0B_RXN_TXN | R13: J1506PIN032 | S13: HSIO1 | T13: 7 | U13: DSW_PWROK | V13: J1504PIN087 | W13: Near2
